<?xml version="1.0" ?>
<!-- =================================================================================== -->
<!-- |    This document was autogenerated by xacro from pal.urdf.xacro                 | -->
<!-- |    EDITING THIS FILE BY HAND IS NOT RECOMMENDED                                 | -->
<!-- =================================================================================== -->
<robot name="anubis">

  <link name="base_footprint"/>

  <joint name="base_joint" type="fixed">
    <parent link="base_footprint"/>
    <child link="base_link"/>
    <origin xyz="0.0 0.0 0.00" rpy="0 0 0"/>
  </joint>

  <link name="base_link">
    <visual>
      <origin xyz="0 0 0" rpy="0 0 0"/>
      <geometry>
        <mesh filename="package://anubis/meshes/anubis_base.stl"/>
      </geometry>
      <material name="">
        <color rgba="0.75294 0.75294 0.75294 1"/>
      </material>    </visual>
  </link>

  <joint name="back_joint" type="fixed">
    <parent link="base_footprint"/>
    <child link="back_link"/>
    <origin xyz="0.0 0.0 0.00" rpy="0 0 0"/>
  </joint>

  <link name="back_link">
    <visual>
      <origin xyz="-0.50 0 0.11" rpy="0 0 -1.57"/>
      <geometry>
        <mesh filename="package://anubis/meshes/anubis_master.stl"/>
      </geometry>
      <material name="">
        <color rgba="0.5 0.5 0.5 1"/>
      </material>    </visual>
  </link>

<!--- ARM1, RIGHT SLAVE-->
   <joint name="arm1_base_joint" type="fixed">
    <parent link="base_link"/>
    <child link="arm1_base_link"/>
    <origin xyz="0 0 0" rpy="0 0 0"/>
    <!-- <origin xyz="-0.095 0  0.579" rpy="0 0 0"/> -->
    <!-- <origin xyz="-0.095 -0.135470  0.623356" rpy="0.174533 0 0"/> -->
  </joint>

  <link name="arm1_base_link">
    <visual>
      <origin rpy="0 0 0" xyz="0 0 0"/>
      <geometry>
        <mesh filename="package://anubis/meshes/arm_base_link.stl"/>
      </geometry>
      <material name="">
        <color rgba="0.75294 0.75294 0.75294 1"/>
      </material>
    </visual>
  </link>
  <joint name="arm1_base_link_joint" type="revolute">
    <parent link="arm1_base_link"/>
    <child link="link11"/>
    <origin xyz="-0.095 -0.135470  0.82335578" rpy="0.174533 0 0"/>
    <axis xyz="0 0 1"/>
    <limit effort="39" lower="-2.41" upper="2.41" velocity="1.3963"/>
  </joint>
  <link name="link11">
    <visual>
      <origin rpy="0 0 0" xyz="0 0 0"/>
      <geometry>
        <mesh filename="package://anubis/meshes/link1.stl"/>
      </geometry>
      <material name="">
        <color rgba="0.75294 0.75294 0.75294 1"/>
      </material>
    </visual>
  </link>
  <joint name="link11_joint" type="revolute">
    <parent link="link11"/>
    <child link="link12"/>
    <origin rpy="0 0 0" xyz="0 0 0.062"/>
    <axis xyz="0 1 0"/>
    <limit effort="39" lower="-2.41" upper="2.41" velocity="1.3963"/>
  </joint>
  <link name="link12">
    <visual>
      <origin rpy="0 0 0" xyz="0 0 -0.062"/>
      <geometry>
        <mesh filename="package://anubis/meshes/link2.stl"/>
      </geometry>
      <material name="">
        <color rgba="0.75294 0.75294 0.75294 1"/>
      </material>
    </visual>  "arm1_base_link_joint",
  "link11_joint",
  "link12_joint",
  "link13_joint",
  "link14_joint",
  "link15_joint",

  </link>
  <joint name="link12_joint" type="revolute">
    <parent link="link12"/>
    <child link="link13"/>
    <origin rpy="0 0 0" xyz="0 0 0.3"/>
    <axis xyz="0 1 0"/>
    <limit effort="39" lower="-2.41" upper="2.41" velocity="1.3963"/>
  </joint>
  <link name="link13">
    <visual>
      <origin rpy="0 0 0" xyz="0 0 -0.362"/>
      <geometry>
        <mesh filename="package://anubis/meshes/link3.stl"/>
      </geometry>
      <material name="">
        <color rgba="0.75294 0.75294 0.75294 1"/>
      </material>
    </visual>
  </link>
  <joint name="link13_joint" type="revolute">
    <parent link="link13"/>
    <child link="link14"/>
    <origin rpy="0 0 0" xyz="0 0 0.32"/>
    <axis xyz="0 1 0"/>
    <limit effort="39" lower="-2.41" upper="2.41" velocity="1.3963"/>
  </joint>
  <link name="link14">
    <visual>
      <origin rpy="0 0 0" xyz="0 0 -0.662"/>
      <geometry>
        <mesh filename="package://anubis/meshes/link4.stl"/>
      </geometry>
      <material name="">
        <color rgba="0.75294 0.75294 0.75294 1"/>
      </material>
    </visual>
  </link>
  <joint name="link14_joint" type="revolute">
    <parent link="link14"/>
    <child link="link15"/>
    <origin rpy="0 0 0" xyz="0 0 0.04"/>
    <axis xyz="-1 0 0"/>
    <limit effort="39" lower="-2.41" upper="2.41" velocity="1.3963"/>
  </joint>
  <link name="link15">
    <visual>
      <origin rpy="0 0 0" xyz="0 0 -0.702"/>
      <geometry>
        <mesh filename="package://anubis/meshes/link5.stl"/>
      </geometry>
      <material name="">
        <color rgba="0.75294 0.75294 0.75294 1"/>
      </material>
    </visual>
  </link>
  <joint name="link15_joint" type="revolute">
    <parent link="link15"/>
    <child link="ee_link1"/>
    <origin rpy="0 0 -1.57" xyz="0 0 0.027"/>
    <axis xyz="0 0 1"/>
    <limit effort="39" lower="-2.41" upper="2.41" velocity="1.3963"/>
  </joint>
  <link name="ee_link1" >
  </link>

  <!--- gripper1-->
  <joint name="gripper_base_joint" type="fixed">
    <parent link="ee_link1"/>
    <child link="gripper_base_link"/>
    <origin rpy="0 0 0" xyz="0 0 0"/>
        <color rgba="0.75294 0.0 0.0 1"/>
  </joint>
  <link name="gripper_base_link" >
    <visual>
      <origin rpy="0 0 0" xyz="0.0 0 0"/>
      <geometry>
        <mesh filename="package://anubis/meshes/gripper/gripper_base_link.stl"/>
      </geometry>
      <material name="">
        <color rgba="0.75294 0.75294 0.75294 1"/>
      </material>
    </visual>
  </link>

  <joint name="gripper1_joint" type="prismatic">
    <parent link="gripper_base_link"/>
    <child link="gripper1L"/>
    <origin rpy="0 0 0" xyz="0 0 0"/>
    <axis xyz="-1 0 0"/>
    <limit velocity="4.8" effort="1" lower="0" upper="0.04" />
  </joint>
  <link name="gripper1L" >
    <visual>
      <origin rpy="0 0 0" xyz="0 0 0"/>
      <geometry>
        <mesh filename="package://anubis/meshes/gripper/fingerL.stl"/>
      </geometry>
      <material name="">
        <color rgba="0.75294 0.0 0.0 1"/>
      </material>
    </visual>
  </link>

  <joint name="gripper1R_joint" type="prismatic">
    <parent link="gripper_base_link"/>
    <child link="gripper1R"/>
    <origin rpy="0 0 0" xyz="0 0 0"/>
    <axis xyz="1 0 0"/>
    <limit velocity="4.8" effort="1" lower="0" upper="0.04" />
    <mimic joint="gripper1_joint" multiplier="1" offset="0" />
  </joint>
  <link name="gripper1R" >
    <visual>
      <origin rpy="0 0 0" xyz="0 0 0"/>
      <geometry>
        <mesh filename="package://anubis/meshes/gripper/fingerR.stl"/>
      </geometry>
      <material name="">
        <color rgba="0.75294 0.0 0.0 1"/>
      </material>
    </visual>
  </link>


<!--- ARM2, LEFT SLAVE-->
   <joint name="arm2_base_joint" type="fixed">
    <parent link="base_link"/>
    <child link="arm2_base_link"/>
    <!-- <origin xyz="-0.095 0.135470  0.623356" rpy="0.174533 0 3.141592"/> -->
    <!-- <origin xyz="-0.095 0.135470  0.623356" rpy="-0.174533 0 0"/> -->
  </joint>


  <link name="arm2_base_link">
    <visual>
    <origin rpy="0 0 3.14159" xyz="-0.19 0 0"/>
      <geometry>
        <mesh filename="package://anubis/meshes/arm_base_link.stl"/>
      </geometry>
      <material name="">
        <color rgba="0.75294 0.75294 0.75294 1"/>
      </material>
    </visual>
  </link>
  <joint name="arm2_base_link_joint" type="revolute">
    <parent link="arm2_base_link"/>
    <child link="link21"/>
    <origin xyz="-0.095 0.135470  0.82335578" rpy="0.174533 0 3.14159"/>
    <axis xyz="0 0 1"/>
    <limit effort="39" lower="-2.41" upper="2.41" velocity="1.3963"/>
  </joint>
  <link name="link21">
    <visual>
      <origin rpy="0 0 0" xyz="0 0 0"/>
      <geometry>
        <mesh filename="package://anubis/meshes/link1.stl"/>
      </geometry>
      <material name="">
        <color rgba="0.75294 0.75294 0.75294 1"/>
      </material>
    </visual>
  </link>
  <joint name="link21_joint" type="revolute">
    <parent link="link21"/>
    <child link="link22"/>
    <origin rpy="0 0 0" xyz="0 0 0.062"/>
    <axis xyz="0 -1 0"/>
    <limit effort="39" lower="-2.41" upper="2.41" velocity="1.3963"/>
  </joint>
  <link name="link22">
    <visual>
      <origin rpy="0 0 0" xyz="0 0 -0.062"/>
      <geometry>
        <mesh filename="package://anubis/meshes/link2.stl"/>
      </geometry>
      <material name="">
        <color rgba="0.75294 0.75294 0.75294 1"/>
      </material>
    </visual>
  </link>
  <joint name="link22_joint" type="revolute">
    <parent link="link22"/>
    <child link="link23"/>
    <origin rpy="0 0 0" xyz="0 0 0.3"/>
    <axis xyz="0 -1 0"/>
    <limit effort="39" lower="-2.41" upper="2.41" velocity="1.3963"/>
  </joint>
  <link name="link23">
    <visual>
      <origin rpy="0 0 0" xyz="0 0 -0.362"/>
      <geometry>
        <mesh filename="package://anubis/meshes/link3.stl"/>
      </geometry>
      <material name="">
        <color rgba="0.75294 0.75294 0.75294 1"/>
      </material>
    </visual>
  </link>
  <joint name="link23_joint" type="revolute">
    <parent link="link23"/>
    <child link="link24"/>
    <origin rpy="0 0 3.14159" xyz="0 0 0.32"/>
    <axis xyz="0 1 0"/>
    <limit effort="39" lower="-2.41" upper="2.41" velocity="1.3963"/>
  </joint>
  <link name="link24">
    <visual>
      <origin rpy="0 0 0" xyz="0 0 -0.662"/>
      <geometry>
        <mesh filename="package://anubis/meshes/link4.stl"/>
      </geometry>
      <material name="">
        <color rgba="0.75294 0.75294 0.75294 1"/>
      </material>
    </visual>
  </link>
  <joint name="link24_joint" type="revolute">
    <parent link="link24"/>
    <child link="link25"/>
    <origin rpy="0 0 0" xyz="0 0 0.04"/>
    <axis xyz="-1 0 0"/>
    <limit effort="39" lower="-2.41" upper="2.41" velocity="1.3963"/>
  </joint>
  <link name="link25">
    <visual>
      <origin rpy="0 0 0" xyz="0 0 -0.702"/>
      <geometry>
        <mesh filename="package://anubis/meshes/link5.stl"/>
      </geometry>
      <material name="">
        <color rgba="0.75294 0.75294 0.75294 1"/>
      </material>
    </visual>
  </link>
  <joint name="link25_joint" type="revolute">
    <parent link="link25"/>
    <child link="ee_link2"/>
    <origin rpy="0 0 -1.57" xyz="0 0 0.027"/>
    <axis xyz="0 0 1"/>
    <limit effort="39" lower="-2.41" upper="2.41" velocity="1.3963"/>
  </joint>
  <link name="ee_link2" >
  </link>

    <!--- gripper2-->
  <joint name="gripper2_base_joint" type="fixed">
    <parent link="ee_link2"/>
    <child link="gripper2_base_link"/>
    <origin rpy="0 0 0" xyz="0 0 0"/>
        <color rgba="0.75294 0.0 0.0 1"/>
  </joint>
  <link name="gripper2_base_link" >
    <visual>
      <origin rpy="0 0 0" xyz="0.0 0 0"/>
      <geometry>
        <mesh filename="package://anubis/meshes/gripper/gripper_base_link.stl"/>
      </geometry>
      <material name="">
        <color rgba="0.75294 0.75294 0.75294 1"/>
      </material>
    </visual>
  </link>

  <joint name="gripper2_joint" type="prismatic">
    <parent link="gripper2_base_link"/>
    <child link="gripper2L"/>
    <origin rpy="0 0 0" xyz="0 0 0"/>
    <axis xyz="-1 0 0"/>
    <limit velocity="4.8" effort="1" lower="0" upper="0.04" />
  </joint>
  <link name="gripper2L" >
    <visual>
      <origin rpy="0 0 0" xyz="0 0 0"/>
      <geometry>
        <mesh filename="package://anubis/meshes/gripper/fingerL.stl"/>
      </geometry>
      <material name="">
        <color rgba="0.75294 0.0 0.0 1"/>
      </material>
    </visual>
  </link>

  <joint name="gripper2R_joint" type="prismatic">
    <parent link="gripper2_base_link"/>
    <child link="gripper2R"/>
    <origin rpy="0 0 0" xyz="0 0 0"/>
    <axis xyz="1 0 0"/>
    <limit velocity="4.8" effort="1" lower="0" upper="0.04" />
    <mimic joint="gripper2_joint" multiplier="1" offset="0" />
  </joint>
  <link name="gripper2R" >
    <visual>
      <origin rpy="0 0 0" xyz="0 0 0"/>
      <geometry>
        <mesh filename="package://anubis/meshes/gripper/fingerR.stl"/>
      </geometry>
      <material name="">
        <color rgba="0.75294 0.0 0.0 1"/>
      </material>
    </visual>
  </link>

<!--- ARM3, RIGHT MASTER-->
   <joint name="arm3_base_joint" type="fixed">
    <parent link="base_link"/>
    <child link="arm3_base_link"/>
    <origin xyz="-0.7 -0.40 0.95" rpy="0 0 0"/>
  </joint>

  <link name="arm3_base_link">
    <visual>
      <origin rpy="0 0 0" xyz="0 0 0"/>
      <geometry>
        <mesh filename="package://anubis/meshes/master_arm_base_link.stl"/>
      </geometry>
      <material name="">
        <color rgba="0.75294 0.75294 0.75294 1"/>
      </material>
    </visual>
  </link>
  <joint name="arm3_base_link_joint" type="revolute">
    <parent link="arm3_base_link"/>
    <child link="link31"/>
    <origin rpy="0 0 0" xyz="0 0 0"/>
    <axis xyz="0 0 1"/>
    <limit effort="39" lower="-2.41" upper="2.41" velocity="1.3963"/>
  </joint>
  <link name="link31">
    <visual>
      <origin rpy="0 0 0" xyz="0 0 0"/>
      <geometry>
        <mesh filename="package://anubis/meshes/link1.stl"/>
      </geometry>
      <material name="">
        <color rgba="0.75294 0.75294 0.75294 1"/>
      </material>
    </visual>
  </link>
  <joint name="link31_joint" type="revolute">
    <parent link="link31"/>
    <child link="link32"/>
    <origin rpy="0 0 0" xyz="0 0 0.062"/>
    <axis xyz="0 1 0"/>
    <limit effort="39" lower="-2.41" upper="2.41" velocity="1.3963"/>
  </joint>
  <link name="link32">
    <visual>
      <origin rpy="0 0 0" xyz="0 0 -0.062"/>
      <geometry>
        <mesh filename="package://anubis/meshes/link2.stl"/>
      </geometry>
      <material name="">
        <color rgba="0.75294 0.75294 0.75294 1"/>
      </material>
    </visual>  "arm1_base_link_joint",
  "link11_joint",
  "link12_joint",
  "link13_joint",
  "link14_joint",
  "link15_joint",

  </link>
  <joint name="link32_joint" type="revolute">
    <parent link="link32"/>
    <child link="link33"/>
    <origin rpy="0 0 0" xyz="0 0 0.3"/>
    <axis xyz="0 1 0"/>
    <limit effort="39" lower="-2.41" upper="2.41" velocity="1.3963"/>
  </joint>
  <link name="link33">
    <visual>
      <origin rpy="0 0 0" xyz="0 0 -0.362"/>
      <geometry>
        <mesh filename="package://anubis/meshes/link3.stl"/>
      </geometry>
      <material name="">
        <color rgba="0.75294 0.75294 0.75294 1"/>
      </material>
    </visual>
  </link>
  <joint name="link33_joint" type="revolute">
    <parent link="link33"/>
    <child link="link34"/>
    <origin rpy="0 0 0" xyz="0 0 0.3"/>
    <axis xyz="0 1 0"/>
    <limit effort="39" lower="-2.41" upper="2.41" velocity="1.3963"/>
  </joint>
  <link name="link34">
    <visual>
      <origin rpy="0 0 0" xyz="0 0 -0.662"/>
      <geometry>
        <mesh filename="package://anubis/meshes/link4.stl"/>
      </geometry>
      <material name="">
        <color rgba="0.75294 0.75294 0.75294 1"/>
      </material>
    </visual>
  </link>

  <joint name="link34_joint" type="revolute">
    <parent link="link34"/>
    <child link="link35"/>
    <origin rpy="0 0 0" xyz="0 0 0.04"/>
    <axis xyz="-1 0 0"/>
    <limit effort="39" lower="-2.41" upper="2.41" velocity="1.3963"/>
  </joint>
    <link name="link35">
    <visual>
      <origin rpy="0 0 0" xyz="0 0 -0.702"/>
      <geometry>
        <mesh filename="package://anubis/meshes/link5.stl"/>
      </geometry>
      <material name="">
        <color rgba="0.75294 0.75294 0.75294 1"/>
      </material>
    </visual>
  </link>
  <joint name="link35_joint" type="revolute">
    <parent link="link35"/>
    <child link="ee_link3"/>
    <origin rpy="0 0 -1.57" xyz="0 0 0.027"/>
    <axis xyz="0 0 1"/>
    <limit effort="39" lower="-2.41" upper="2.41" velocity="1.3963"/>
  </joint>
  <link name="ee_link3" >
  </link>

    <!--- gripper3-->
  <joint name="gripper3_joint" type="prismatic">
    <parent link="ee_link3"/>
    <child link="gripper3L"/>
    <origin rpy="0 0 0" xyz="0 0 0"/>
    <axis xyz="-1 0 0"/>
    <limit velocity="4.8" effort="1" lower="0" upper="0.04" />
  </joint>
  <link name="gripper3L" >
    <visual>
      <origin rpy="0 0 0" xyz="-0.005 0 0.04"/>
      <geometry>
        <box size="0.01 0.01 0.08"/>
      </geometry>
      <material name="">
        <color rgba="0.75294 0.0 0.0 1"/>
      </material>
    </visual>
  </link>

  <joint name="gripper3R_joint" type="prismatic">
    <parent link="ee_link3"/>
    <child link="gripper3R"/>
    <origin rpy="0 0 0" xyz="0 0 0"/>
    <axis xyz="1 0 0"/>
    <limit velocity="4.8" effort="1" lower="0" upper="0.04" />
    <mimic joint="gripper3_joint" multiplier="1" offset="0" />
  </joint>
  <link name="gripper3R" >
    <visual>
      <origin rpy="0 0 0" xyz="0.005 0 0.04"/>
      <geometry>
        <box size="0.01 0.01 0.08"/>
      </geometry>
      <material name="">
        <color rgba="0.75294 0.0 0.0 1"/>
      </material>
    </visual>
  </link>

<!--- ARM4, LEFT MASTER-->
   <joint name="arm4_base_joint" type="fixed">
    <parent link="base_link"/>
    <child link="arm4_base_link"/>
    <origin xyz="-0.7 0.40 0.95" rpy="0 0 0"/>
  </joint>

  <link name="arm4_base_link">
    <visual>
      <origin rpy="0 0 3.14159" xyz="0 0 0"/>
      <geometry>
        <mesh filename="package://anubis/meshes/master_arm_base_link.stl"/>
      </geometry>
      <material name="">
        <color rgba="0.75294 0.75294 0.75294 1"/>
      </material>
    </visual>
  </link>
  <joint name="arm4_base_link_joint" type="revolute">
    <parent link="arm4_base_link"/>
    <child link="link41"/>
    <origin rpy="0 0 3.14159" xyz="0 0 0"/>
    <axis xyz="0 0 1"/>
    <limit effort="39" lower="-2.41" upper="2.41" velocity="1.3963"/>
  </joint>
  <link name="link41">
    <visual>
      <origin rpy="0 0 0" xyz="0 0 0"/>
      <geometry>
        <mesh filename="package://anubis/meshes/link1.stl"/>
      </geometry>
      <material name="">
        <color rgba="0.75294 0.75294 0.75294 1"/>
      </material>
    </visual>
  </link>
  <joint name="link41_joint" type="revolute">
    <parent link="link41"/>
    <child link="link42"/>
    <origin rpy="0 0 0" xyz="0 0 0.062"/>
    <axis xyz="0 -1 0"/>
    <limit effort="39" lower="-2.41" upper="2.41" velocity="1.3963"/>
  </joint>
  <link name="link42">
    <visual>
      <origin rpy="0 0 0" xyz="0 0 -0.062"/>
      <geometry>
        <mesh filename="package://anubis/meshes/link2.stl"/>
      </geometry>
      <material name="">
        <color rgba="0.75294 0.75294 0.75294 1"/>
      </material>
    </visual>
  </link>
  <joint name="link42_joint" type="revolute">
    <parent link="link42"/>
    <child link="link43"/>
    <origin rpy="0 0 0" xyz="0 0 0.3"/>
    <axis xyz="0 -1 0"/>
    <limit effort="39" lower="-2.41" upper="2.41" velocity="1.3963"/>
  </joint>
  <link name="link43">
    <visual>
      <origin rpy="0 0 0" xyz="0 0 -0.362"/>
      <geometry>
        <mesh filename="package://anubis/meshes/link3.stl"/>
      </geometry>
      <material name="">
        <color rgba="0.75294 0.75294 0.75294 1"/>
      </material>
    </visual>
  </link>
  <joint name="link43_joint" type="revolute">
    <parent link="link43"/>
    <child link="link44"/>
    <origin rpy="0 0 3.14159" xyz="0 0 0.3"/>
    <axis xyz="0 1 0"/>
    <limit effort="39" lower="-2.41" upper="2.41" velocity="1.3963"/>
  </joint>
  <link name="link44">
    <visual>
      <origin rpy="0 0 0" xyz="0 0 -0.662"/>
      <geometry>
        <mesh filename="package://anubis/meshes/link4.stl"/>
      </geometry>
      <material name="">
        <color rgba="0.75294 0.75294 0.75294 1"/>
      </material>
    </visual>
  </link>
  <joint name="link44_joint" type="revolute">
    <parent link="link44"/>
    <child link="link45"/>
    <origin rpy="0 0 0" xyz="0 0 0.04"/>
    <axis xyz="-1 0 0"/>
    <limit effort="39" lower="-2.41" upper="2.41" velocity="1.3963"/>
  </joint>
  <link name="link45">
    <visual>
      <origin rpy="0 0 0" xyz="0 0 -0.702"/>
      <geometry>
        <mesh filename="package://anubis/meshes/link5.stl"/>
      </geometry>
      <material name="">
        <color rgba="0.75294 0.75294 0.75294 1"/>
      </material>
    </visual>
  </link>
  <joint name="link45_joint" type="revolute">
    <parent link="link45"/>
    <child link="ee_link4"/>
    <origin rpy="0 0 -1.57" xyz="0 0 0.027"/>
    <axis xyz="0 0 1"/>
    <limit effort="39" lower="-2.41" upper="2.41" velocity="1.3963"/>
  </joint>
  <link name="ee_link4" >
  </link>

    <!--- gripper4-->
  <joint name="gripper4_joint" type="prismatic">
    <parent link="ee_link4"/>
    <child link="gripper4L"/>
    <origin rpy="0 0 0" xyz="0 0 0"/>
    <axis xyz="-1 0 0"/>
    <limit velocity="4.8" effort="1" lower="0" upper="0.04" />
  </joint>
  <link name="gripper4L" >
    <visual>
      <origin rpy="0 0 0" xyz="-0.005 0 0.04"/>
      <geometry>
        <box size="0.01 0.01 0.08"/>
      </geometry>
      <material name="">
        <color rgba="0.75294 0.0 0.0 1"/>
      </material>
    </visual>
  </link>

  <joint name="gripper4R_joint" type="prismatic">
    <parent link="ee_link4"/>
    <child link="gripper4R"/>
    <origin rpy="0 0 0" xyz="0 0 0"/>
    <axis xyz="1 0 0"/>
    <limit velocity="4.8" effort="1" lower="0" upper="0.04" />
    <mimic joint="gripper4_joint" multiplier="1" offset="0" />
  </joint>
  <link name="gripper4R" >
    <visual>
      <origin rpy="0 0 0" xyz="0.005 0 0.04"/>
      <geometry>
        <box size="0.01 0.01 0.08"/>
      </geometry>
      <material name="">
        <color rgba="0.75294 0.0 0.0 1"/>
      </material>
    </visual>
  </link>

</robot>
