<?xml version="1.0" ?>
<!-- =================================================================================== -->
<!-- |    This document was autogenerated by xacro from pal.urdf.xacro                 | -->
<!-- |    EDITING THIS FILE BY HAND IS NOT RECOMMENDED                                 | -->
<!-- =================================================================================== -->
<robot name="anubis">
  
  <link name="base_link">
  	<inertial>
  		<!-- Inertial frame at link origin -->
		<origin xyz="0 0 0" rpy="0 0 0"/>
		<!-- Mass of the base -->
  		<mass value="132.3898489950015"/>
  		<!-- Moments of inertia about the link frame axes -->
      <inertia ixx="0.185196122711036"
            ixy="4.30144213829512E-08"
            ixz="5.81037523686401E-08"
            iyy="0.364893736238929"
            iyz="-0.000386720198091934"
            izz="0.223868521722778"/>
	</inertial>
    <visual>
      <origin xyz="0 0 0" rpy="0 0 0"/>
      <geometry>
        <mesh filename="package://anubis/meshes/anubis_base.stl"/>
      </geometry>
      <material name="">
        <color rgba="0.75294 0.75294 0.75294 1"/>
      </material>    
    </visual>
    <collision>
      <origin xyz="0 0 0" rpy="0 0 0"/>
      <geometry>
        <mesh filename="package://anubis/meshes/anubis_base.stl"/>
      </geometry>
    </collision>
  </link>
<!--- ARM1, RIGHT SLAVE-->
   <joint name="arm1_base_joint" type="fixed">
    <parent link="base_link"/>
    <child link="arm1_base_link"/>
    <origin xyz="0 0 0" rpy="0 0 0"/>
    <!-- <origin xyz="-0.095 0  0.579" rpy="0 0 0"/> -->
    <!-- <origin xyz="-0.095 -0.135470  0.623356" rpy="0.174533 0 0"/> -->
  </joint>

  <link name="arm1_base_link">
    <visual>
      <origin rpy="0 0 0" xyz="0 0 0"/>
      <geometry>
        <mesh filename="package://anubis/meshes/arm_base_link.stl"/>
      </geometry>
      <material name="">
        <color rgba="0.75294 0.75294 0.75294 1"/>
      </material>
    </visual>
    <collision>
      <origin rpy="0 0 0" xyz="0 0 0"/>
      <geometry>
        <mesh filename="package://anubis/meshes/arm_base_link.stl"/>
      </geometry>
    </collision>
  </link>

  <joint name="arm1_base_link_joint" type="revolute">
    <parent link="arm1_base_link"/>
    <child link="link11"/>
    <origin xyz="-0.095 -0.135470  0.82335578" rpy="0.174533 0 0"/>
    <axis xyz="0 0 1"/>
    <limit effort="39" lower="-2.41" upper="2.41" velocity="1.3963"/>
  </joint>
  <link name="link11">
    <inertial>
            <origin xyz="0 0 0" rpy="0 0 0" />
            <mass value="0.0608351104988555" />
            <inertia ixx="0.00008" ixy="0.00000" ixz="0.00001" iyy="0.00003" iyz="0.00000" izz="0.00007" />
    </inertial>
    <visual>
      <origin rpy="0 0 0" xyz="0 0 0"/>
      <geometry>
        <mesh filename="package://anubis/meshes/link1.stl"/>
      </geometry>
      <material name="">
        <color rgba="0.75294 0.75294 0.75294 1"/>
      </material>
    </visual>
    <collision>
      <origin rpy="0 0 0" xyz="0 0 0"/>
      <geometry>
         <mesh filename="package://anubis/meshes/link1.stl"/>
      </geometry>
    </collision>
  </link>

  <joint name="link11_joint" type="revolute">
    <parent link="link11"/>
    <child link="link12"/>
    <origin rpy="0 0 0" xyz="0 0 0.062"/>
    <axis xyz="0 1 0"/>
    <limit effort="39" lower="-2.41" upper="2.41" velocity="1.3963"/>
  </joint>
  <link name="link12">
        <inertial>
            <origin xyz="0 0 0" rpy="0 0 0" />
            <mass value="1.0733279014126" />
            <inertia ixx="0.00008" ixy="0.00000" ixz="0.00001" iyy="0.00003" iyz="0.00000" izz="0.00007" />
    </inertial>
    <visual>
      <origin rpy="0 0 0" xyz="0 0 -0.062"/>
      <geometry>
        <mesh filename="package://anubis/meshes/link2.stl"/>
      </geometry>
      <material name="">
        <color rgba="0.75294 0.75294 0.75294 1"/>
      </material>
    </visual>  
    <collision>
      <origin rpy="0 0 0" xyz="0 0 -0.062"/>
      <geometry>
        <mesh filename="package://anubis/meshes/link2.stl"/>
      </geometry>
    </collision>
  </link>
  <joint name="link12_joint" type="revolute">
    <parent link="link12"/>
    <child link="link13"/>
    <origin rpy="0 0 0" xyz="0 0 0.3"/>
    <axis xyz="0 1 0"/>
    <limit effort="39" lower="-2.41" upper="2.41" velocity="1.3963"/>
  </joint>
  <link name="link13">
    <inertial>
            <origin xyz="0 0 0" rpy="0 0 0" />
            <mass value="0.499404738025019" />
            <inertia ixx="0.00008" ixy="0.00000" ixz="0.00001" iyy="0.00003" iyz="0.00000" izz="0.00007" />
    </inertial>
    <visual>
      <origin rpy="0 0 0" xyz="0 0 -0.362"/>
      <geometry>
        <mesh filename="package://anubis/meshes/link3.stl"/>
      </geometry>
      <material name="">
        <color rgba="0.75294 0.75294 0.75294 1"/>
      </material>
    </visual>
    <collision>
      <origin rpy="0 0 0" xyz="0 0 -0.362"/>
      <geometry>
        <mesh filename="package://anubis/meshes/link3.stl"/>
      </geometry>
    </collision>
  </link>

  <joint name="link13_joint" type="revolute">
    <parent link="link13"/>
    <child link="link14"/>
    <origin rpy="0 0 0" xyz="0 0 0.32"/>
    <axis xyz="0 1 0"/>
    <limit effort="39" lower="-2.41" upper="2.41" velocity="1.3963"/>
  </joint>

  <link name="link14">
    <inertial>
            <origin xyz="0 0 0" rpy="0 0 0" />
            <mass value="0.0809712553169999" />
            <inertia ixx="0.00008" ixy="0.00000" ixz="0.00001" iyy="0.00003" iyz="0.00000" izz="0.00007" />
    </inertial>
    <visual>
      <origin rpy="0 0 0" xyz="0 0 -0.662"/>
      <geometry>
        <mesh filename="package://anubis/meshes/link4.stl"/>
      </geometry>
      <material name="">
        <color rgba="0.75294 0.75294 0.75294 1"/>
      </material>
    </visual>
    <collision>
      <origin rpy="0 0 0" xyz="0 0 -0.662"/>
      <geometry>
        <mesh filename="package://anubis/meshes/link4.stl"/>
      </geometry>
    </collision>
  </link>
  
  <joint name="link14_joint" type="revolute">
    <parent link="link14"/>
    <child link="link15"/>
    <origin rpy="0 0 0" xyz="0 0 0.04"/>
    <axis xyz="-1 0 0"/>
    <limit effort="39" lower="-2.41" upper="2.41" velocity="1.3963"/>
  </joint>

  <link name="link15">
    <inertial>
            <origin xyz="0 0 0" rpy="0 0 0" />
            <mass value="0.602357399313257" />
            <inertia ixx="0.00008" ixy="0.00000" ixz="0.00001" iyy="0.00003" iyz="0.00000" izz="0.00007" />
    </inertial>
    <visual>
      <origin rpy="0 0 0" xyz="0 0 -0.702"/>
      <geometry>
        <mesh filename="package://anubis/meshes/link5.stl"/>
      </geometry>
      <material name="">
        <color rgba="0.75294 0.75294 0.75294 1"/>
      </material>
    </visual>
     <collision>
       <origin rpy="0 0 0" xyz="0 0 -0.702"/>
       <geometry>
         <mesh filename="package://anubis/meshes/link5.stl"/>
       </geometry>
     </collision>
  </link>
  
  <joint name="link15_joint" type="revolute">
    <parent link="link15"/>
    <child link="ee_link1"/>
    <origin rpy="0 0 -1.57" xyz="0 0 0.027"/>
    <axis xyz="0 0 1"/>
    <limit effort="39" lower="-2.41" upper="2.41" velocity="1.3963"/>
  </joint>
  
  <link name="ee_link1" >
        <inertial>
            <origin xyz="0 0 0" rpy="0 0 0" />
            <mass value="0.0062357399313257" />
            <inertia ixx="0.00008" ixy="0.00000" ixz="0.00001" iyy="0.00003" iyz="0.00000" izz="0.00007" />
    </inertial>
  </link>

  <!--- gripper1-->
  <joint name="gripper_base_joint" type="fixed">
    <parent link="ee_link1"/>
    <child link="gripper_base_link"/>
    <origin rpy="0 0 0" xyz="0 0 0"/>
        <color rgba="0.75294 0.0 0.0 1"/>
  </joint>
  
  <link name="gripper_base_link" >
    <inertial>
            <origin xyz="0 0 0" rpy="0 0 0" />
            <mass value="0.62357399313257" />
            <inertia ixx="0.00008" ixy="0.00000" ixz="0.00001" iyy="0.00003" iyz="0.00000" izz="0.00007" />
    </inertial>
    <visual>
      <origin rpy="0 0 0" xyz="0.0 0 0"/>
      <geometry>
        <mesh filename="package://anubis/meshes/gripper/gripper_base_link.stl"/>
      </geometry>
      <material name="">
        <color rgba="0.75294 0.75294 0.75294 1"/>
      </material>
    </visual>
    <collision>
      <origin rpy="0 0 0" xyz="0.0 0 0"/>
      <geometry>
        <mesh filename="package://anubis/meshes/gripper/gripper_base_link.stl"/>
      </geometry>
    </collision>
  </link>

  <joint name="gripper1_joint" type="prismatic">
    <parent link="gripper_base_link"/>
    <child link="gripper1L"/>
    <origin rpy="0 0 0" xyz="0 0 0"/>
    <axis xyz="-1 0 0"/>
    <limit velocity="4.8" effort="1" lower="0" upper="0.04" />
  </joint>
  
  <link name="gripper1L" >
	<inertial>
  		<!-- Inertial frame at link origin -->
		<origin xyz="0 0 0" rpy="0 0 0"/>
		<!-- Mass of the gripper -->
  		<mass value="0.925"/>
  		<!-- Moments of inertia about the link frame axes -->
  		<inertia 
    			ixx="0.000347" ixy="0.0"    ixz="0.0"
			iyy="0.000561" iyz="0.0"
			izz="0.000771"/>
	</inertial>
    <visual>
      <origin rpy="0 0 0" xyz="0 0 0"/>
      <geometry>
        <mesh filename="package://anubis/meshes/gripper/fingerL.stl"/>
      </geometry>
      <material name="">
        <color rgba="0.75294 0.0 0.0 1"/>
      </material>
    </visual>
    <collision>
      <origin rpy="0 0 0" xyz="0 0 0"/>
      <geometry>
        <mesh filename="package://anubis/meshes/gripper/fingerL.stl"/>
</geometry>
  <contact_coefficients mu="0.5"  kp="5000.0"  kd="10.0" />
    </collision>
  </link>

  <joint name="gripper1R_joint" type="prismatic">
    <parent link="gripper_base_link"/>
    <child link="gripper1R"/>
    <origin rpy="0 0 0" xyz="0 0 0"/>
    <axis xyz="1 0 0"/>
    <limit velocity="4.8" effort="1" lower="0" upper="0.04" />
    <mimic joint="gripper1_joint" multiplier="1" offset="0" />
  </joint>

  <link name="gripper1R" >
	<inertial>
                <!-- Inertial frame at link origin -->
                <origin xyz="0 0 0" rpy="0 0 0"/>
                <!-- Mass of the gripper -->
                <mass value="0.925"/>
                <!-- Moments of inertia about the link frame axes -->
                <inertia 
                        ixx="0.000347" ixy="0.0"    ixz="0.0"
                        iyy="0.000561" iyz="0.0"
                        izz="0.000771"/>
	</inertial>
	  <visual>
      <origin rpy="0 0 0" xyz="0 0 0"/>
      <geometry>
        <mesh filename="package://anubis/meshes/gripper/fingerR.stl"/>
      </geometry>
      <material name="">
        <color rgba="0.75294 0.0 0.0 1"/>
      </material>
    </visual>
    <collision>
      <origin rpy="0 0 0" xyz="0 0 0"/>
      <geometry>
        <mesh filename="package://anubis/meshes/gripper/fingerR.stl"/>
</geometry>
<contact_coefficients mu="0.5"  kp="5000.0"  kd="10.0" />
    </collision>
  </link>


<!--- ARM2, LEFT SLAVE-->
  <joint name="arm2_base_joint" type="fixed">
    <parent link="base_link"/>
    <child link="arm2_base_link"/>
    <!-- <origin xyz="-0.095 0.135470  0.623356" rpy="0.174533 0 3.141592"/> -->
    <!-- <origin xyz="-0.095 0.135470  0.623356" rpy="-0.174533 0 0"/> -->
  </joint>


  <link name="arm2_base_link">
    <visual>
      <origin rpy="0 0 3.14159" xyz="-0.19 0 0"/>
      <geometry>
        <mesh filename="package://anubis/meshes/arm_base_link.stl"/>
      </geometry>
      <material name="">
      <color rgba="0.75294 0.75294 0.75294 1"/>
    </material>
    </visual>
    <collision> 
      <origin rpy="0 0 3.14159" xyz="-0.19 0 0"/>
      <geometry>
        <mesh filename="package://anubis/meshes/arm_base_link.stl"/>
      </geometry>
    </collision>
  </link>
  
  <joint name="arm2_base_link_joint" type="revolute">
    <parent link="arm2_base_link"/>
    <child link="link21"/>
    <origin xyz="-0.095 0.135470  0.82335578" rpy="0.174533 0 3.14159"/>
    <axis xyz="0 0 1"/>
    <limit effort="39" lower="-2.41" upper="2.41" velocity="1.3963"/>
  </joint>
  
  <link name="link21">
    <inertial>
            <origin xyz="0 0 0" rpy="0 0 0" />
            <mass value="0.0608351104988555" />
            <inertia ixx="0.00008" ixy="0.00000" ixz="0.00001" iyy="0.00003" iyz="0.00000" izz="0.00007" />
    </inertial>
    <visual>
      <origin rpy="0 0 0" xyz="0 0 0"/>
      <geometry>
        <mesh filename="package://anubis/meshes/link1.stl"/>
      </geometry>
      <material name="">
        <color rgba="0.75294 0.75294 0.75294 1"/>
      </material>
    </visual>
    <collision> 
      <origin rpy="0 0 0" xyz="0 0 0"/>
      <geometry>
        <mesh filename="package://anubis/meshes/link1.stl"/>
      </geometry>
    </collision>
  </link>

  <joint name="link21_joint" type="revolute">
    <parent link="link21"/>
    <child link="link22"/>
    <origin rpy="0 0 0" xyz="0 0 0.062"/>
    <axis xyz="0 -1 0"/>
    <limit effort="39" lower="-2.41" upper="2.41" velocity="1.3963"/>
  </joint>
  
  <link name="link22">
      <inertial>
            <origin xyz="0 0 0" rpy="0 0 0" />
            <mass value="1.0733279014126" />
            <inertia ixx="0.00008" ixy="0.00000" ixz="0.00001" iyy="0.00003" iyz="0.00000" izz="0.00007" />
    </inertial>
    <visual>
      <origin rpy="0 0 0" xyz="0 0 -0.062"/>
      <geometry>
        <mesh filename="package://anubis/meshes/link2.stl"/>
      </geometry>
      <material name="">
        <color rgba="0.75294 0.75294 0.75294 1"/>
      </material>
    </visual>
    <collision> 
      <origin rpy="0 0 0" xyz="0 0 -0.062"/>
      <geometry>
        <mesh filename="package://anubis/meshes/link2.stl"/>
      </geometry>
    </collision>
  </link>
  
  <joint name="link22_joint" type="revolute">
    <parent link="link22"/>
    <child link="link23"/>
    <origin rpy="0 0 0" xyz="0 0 0.3"/>
    <axis xyz="0 -1 0"/>
    <limit effort="39" lower="-2.41" upper="2.41" velocity="1.3963"/>
  </joint>

  <link name="link23">
    <inertial>
            <origin xyz="0 0 0" rpy="0 0 0" />
            <mass value="0.499404738025019" />
            <inertia ixx="0.00008" ixy="0.00000" ixz="0.00001" iyy="0.00003" iyz="0.00000" izz="0.00007" />
    </inertial>
    <visual>
      <origin rpy="0 0 0" xyz="0 0 -0.362"/>
      <geometry>
        <mesh filename="package://anubis/meshes/link3.stl"/>
      </geometry>
      <material name="">
        <color rgba="0.75294 0.75294 0.75294 1"/>
      </material>
    </visual>
    <collision> 
      <origin rpy="0 0 0" xyz="0 0 -0.362"/>
      <geometry>
        <mesh filename="package://anubis/meshes/link3.stl"/>
      </geometry>
    </collision>
  </link>

  <joint name="link23_joint" type="revolute">
    <parent link="link23"/>
    <child link="link24"/>
    <origin rpy="0 0 3.14159" xyz="0 0 0.32"/>
    <axis xyz="0 1 0"/>
    <limit effort="39" lower="-2.41" upper="2.41" velocity="1.3963"/>
  </joint>
  
  <link name="link24">
    <inertial>
            <origin xyz="0 0 0" rpy="0 0 0" />
            <mass value="0.0809712553169999" />
            <inertia ixx="0.00008" ixy="0.00000" ixz="0.00001" iyy="0.00003" iyz="0.00000" izz="0.00007" />
    </inertial>
    <visual>
      <origin rpy="0 0 0" xyz="0 0 -0.662"/>
      <geometry>
        <mesh filename="package://anubis/meshes/link4.stl"/>
      </geometry>
      <material name="">
        <color rgba="0.75294 0.75294 0.75294 1"/>
      </material>
    </visual>
    <collision> 
      <origin rpy="0 0 0" xyz="0 0 -0.662"/>
      <geometry>
        <mesh filename="package://anubis/meshes/link4.stl"/>
      </geometry>
    </collision>
  </link>
  <joint name="link24_joint" type="revolute">
    <parent link="link24"/>
    <child link="link25"/>
    <origin rpy="0 0 0" xyz="0 0 0.04"/>
    <axis xyz="-1 0 0"/>
    <limit effort="39" lower="-2.41" upper="2.41" velocity="1.3963"/>
  </joint>
  <link name="link25">
    <inertial>
            <origin xyz="0 0 0" rpy="0 0 0" />
            <mass value="0.602357399313257" />
            <inertia ixx="0.00008" ixy="0.00000" ixz="0.00001" iyy="0.00003" iyz="0.00000" izz="0.00007" />
    </inertial>
    <visual>
      <origin rpy="0 0 0" xyz="0 0 -0.702"/>
      <geometry>
        <mesh filename="package://anubis/meshes/link5.stl"/>
      </geometry>
      <material name="">
        <color rgba="0.75294 0.75294 0.75294 1"/>
      </material>
    </visual>
    <collision>
      <origin rpy="0 0 0" xyz="0 0 -0.702"/>
       <geometry>
         <mesh filename="package://anubis/meshes/link5.stl"/>
       </geometry>
    </collision>
  </link>

  <joint name="link25_joint" type="revolute">
    <parent link="link25"/>
    <child link="ee_link2"/>
    <origin rpy="0 0 -1.57" xyz="0 0 0.027"/>
    <axis xyz="0 0 1"/>
    <limit effort="39" lower="-2.41" upper="2.41" velocity="1.3963"/>
  </joint>
  <link name="ee_link2" >
      <inertial>
            <origin xyz="0 0 0" rpy="0 0 0" />
            <mass value="0.0062357399313257" />
            <inertia ixx="0.00008" ixy="0.00000" ixz="0.00001" iyy="0.00003" iyz="0.00000" izz="0.00007" />
    </inertial>
  </link>

    <!--- gripper2-->
  <joint name="gripper2_base_joint" type="fixed">
    <parent link="ee_link2"/>
    <child link="gripper2_base_link"/>
    <origin rpy="0 0 0" xyz="0 0 0"/>
        <color rgba="0.75294 0.0 0.0 1"/>
  </joint>
  <link name="gripper2_base_link" >
    <inertial>
            <origin xyz="0 0 0" rpy="0 0 0" />
            <mass value="0.62357399313257" />
            <inertia ixx="0.00008" ixy="0.00000" ixz="0.00001" iyy="0.00003" iyz="0.00000" izz="0.00007" />
    </inertial>
    <visual>
      <origin rpy="0 0 0" xyz="0.0 0 0"/>
      <geometry>
        <mesh filename="package://anubis/meshes/gripper/gripper_base_link.stl"/>
      </geometry>
      <material name="">
        <color rgba="0.75294 0.75294 0.75294 1"/>
      </material>
    </visual>
    <collision> 
      <origin rpy="0 0 0" xyz="0.0 0 0"/>
      <geometry>
        <mesh filename="package://anubis/meshes/gripper/gripper_base_link.stl"/>
      </geometry>
    </collision>
  </link>

  <joint name="gripper2_joint" type="prismatic">
    <parent link="gripper2_base_link"/>
    <child link="gripper2L"/>
    <origin rpy="0 0 0" xyz="0 0 0"/>
    <axis xyz="-1 0 0"/>
    <limit velocity="4.8" effort="1" lower="0" upper="0.04" />
  </joint>
  <link name="gripper2L" >
        <inertial>
                <!-- Inertial frame at link origin -->
                <origin xyz="0 0 0" rpy="0 0 0"/>
                <!-- Mass of the gripper -->
                <mass value="0.925"/>
                <!-- Moments of inertia about the link frame axes -->
                <inertia 
                        ixx="0.000347" ixy="0.0"    ixz="0.0"
                        iyy="0.000561" iyz="0.0"
                        izz="0.000771"/>
        </inertial>      
	  <visual>
      <origin rpy="0 0 0" xyz="0 0 0"/>
      <geometry>
        <mesh filename="package://anubis/meshes/gripper/fingerL.stl"/>
      </geometry>
      <material name="">
        <color rgba="0.75294 0.0 0.0 1"/>
      </material>
    </visual>
    <collision>
      <origin rpy="0 0 0" xyz="0 0 0"/>
      <geometry>
        <mesh filename="package://anubis/meshes/gripper/fingerL.stl"/>
</geometry>
<contact_coefficients mu="0.5"  kp="5000.0"  kd="10.0" />
    </collision>
  </link>

  <joint name="gripper2R_joint" type="prismatic">
    <parent link="gripper2_base_link"/>
    <child link="gripper2R"/>
    <origin rpy="0 0 0" xyz="0 0 0"/>
    <axis xyz="1 0 0"/>
    <limit velocity="4.8" effort="1" lower="0" upper="0.04" />
    <mimic joint="gripper2_joint" multiplier="1" offset="0" />
  </joint>
  <link name="gripper2R" >
	          <inertial>
                <!-- Inertial frame at link origin -->
                <origin xyz="0 0 0" rpy="0 0 0"/>
                <!-- Mass of the gripper -->
                <mass value="0.925"/>
                <!-- Moments of inertia about the link frame axes -->
                <inertia 
                        ixx="0.000347" ixy="0.0"    ixz="0.0"
                        iyy="0.000561" iyz="0.0"
                        izz="0.000771"/>
        </inertial>
	  <visual>
      <origin rpy="0 0 0" xyz="0 0 0"/>
      <geometry>
        <mesh filename="package://anubis/meshes/gripper/fingerR.stl"/>
      </geometry>
      <material name="">
        <color rgba="0.75294 0.0 0.0 1"/>
      </material>
    </visual>
    <collision> 
      <origin rpy="0 0 0" xyz="0 0 0"/>
      <geometry>
        <mesh filename="package://anubis/meshes/gripper/fingerR.stl"/>
      </geometry>
<contact_coefficients mu="0.5"  kp="5000.0"  kd="10.0" />
    </collision>
  </link>
</robot>
