<?xml version="1.0" ?>
<!-- =================================================================================== -->
<!-- |    This document was autogenerated by xacro from victor.urdf.xacro              | -->
<!-- |    EDITING THIS FILE BY HAND IS NOT RECOMMENDED                                 | -->
<!-- =================================================================================== -->
<robot name="victor">
  <material name="Black">
    <color rgba="0.0 0.0 0.0 1.0"/>
  </material>
  <material name="Blue">
    <color rgba="0.0 0.0 0.8 1.0"/>
  </material>
  <material name="Green">
    <color rgba="0.0 0.8 0.0 1.0"/>
  </material>
  <material name="Grey">
    <color rgba="0.4 0.4 0.4 1.0"/>
  </material>
  <material name="Orange">
    <color rgba="1.0 0.4235294117647059 0.0392156862745098 1.0"/>
  </material>
  <material name="Brown">
    <color rgba="0.8705882352941177 0.8117647058823529 0.7647058823529411 1.0"/>
  </material>
  <material name="Red">
    <color rgba="0.8 0.0 0.0 1.0"/>
  </material>
  <material name="White">
    <color rgba="1.0 1.0 1.0 1.0"/>
  </material>
  <material name="LightGrey">
    <color rgba="0.7 0.7 0.7 1"/>
  </material>
  <material name="DarkGray">
    <color rgba="0.2 0.2 0.2 1"/>
  </material>
  <material name="DarkDarkGray">
    <color rgba="0.1 0.1 0.1 1"/>
  </material>
  <link name="victor_root"/>
  <joint name="victor_dummy_root_joint" type="fixed">
    <parent link="victor_root"/>
    <child link="victor_pedestal"/>
    <origin rpy="0 0 0" xyz="0 0 0"/>
    <axis xyz="0 0 1"/>
  </joint>
  <link name="victor_pedestal">
    <visual>
      <origin rpy="0 0 0" xyz="0 0 0.9245"/>
      <geometry>
        <mesh filename="meshes/baxter_pedestal/pedestal_visual.stl"/>
      </geometry>
      <material name="DarkGray"/>
    </visual>
    <collision>
      <origin rpy="0 0 0" xyz="0 0 0.9245"/>
      <geometry>
        <mesh filename="meshes/baxter_pedestal/pedestal_collision.stl"/>
      </geometry>
      <material name="DarkGray"/>
    </collision>
    <inertial>
      <origin rpy="0 0 0" xyz="0 0 0"/>
      <mass value="60.86397744"/>
      <inertia ixx="5.0635929" ixy="0.00103417" ixz="0.80199628" iyy="6.08689388" iyz="0.00105311" izz="4.96191932"/>
    </inertial>
  </link>
  <joint name="victor_base_plate_mount_joint" type="fixed">
    <parent link="victor_pedestal"/>
    <child link="victor_base_plate_mount"/>
    <origin rpy="0 0 0" xyz="0 0 0.863"/>
    <axis xyz="0 0 1"/>
  </joint>
  <link name="victor_base_plate_mount"/>
  <joint name="victor_base_plate_joint" type="fixed">
    <parent link="victor_base_plate_mount"/>
    <child link="victor_base_plate"/>
    <origin rpy="0 0 0" xyz="0 0 0"/>
    <axis xyz="0 0 1"/>
  </joint>
  <link name="victor_base_plate">
    <visual>
      <origin rpy="0 0 0" xyz="0 0 0"/>
      <geometry>
        <mesh filename="meshes/torso/torso_visual.stl"/>
      </geometry>
      <material name="LightGrey"/>
    </visual>
    <collision>
      <origin rpy="0 0 0" xyz="0 0 0.2"/>
      <geometry>
        <!--<mesh filename="meshes/torso_visual_model.stl"/>-->
        <cylinder length="0.7" radius="0.2"/>
      </geometry>
      <material name="LightGrey"/>
    </collision>
  </link>
  <joint name="victor_left_arm_mount_joint" type="fixed">
    <parent link="victor_base_plate"/>
    <child link="victor_left_arm_mount"/>
    <origin rpy="-1.5707963268 0 -0.785398163397448" xyz="-0.02 0.1384885 0.385"/>
    <axis xyz="0 0 1"/>
  </joint>
  <link name="victor_left_arm_mount">
    <collision>
      <origin rpy="0 0 0" xyz="0 0 -0.013"/>
      <geometry>
        <!--<mesh filename="meshes/torso_visual_model.stl"/>-->
        <box size="0.31 0.31 0.032"/>
      </geometry>
      <material name="LightGrey"/>
    </collision>
  </link>
  <joint name="victor_right_arm_mount_joint" type="fixed">
    <parent link="victor_base_plate"/>
    <child link="victor_right_arm_mount"/>
    <origin rpy="1.5707963268 0 0.785398163397448" xyz="-0.02 -0.1384885 0.385"/>
    <axis xyz="0 0 1"/>
  </joint>
  <link name="victor_right_arm_mount">
    <collision>
      <origin rpy="0 0 0" xyz="0 0 -0.013"/>
      <geometry>
        <!--<mesh filename="meshes/torso_visual_model.stl"/>-->
        <box size="0.31 0.31 0.032"/>
      </geometry>
      <material name="LightGrey"/>
    </collision>
  </link>
  <!--joint between {parent} and link_0-->
  <joint name="victor_left_arm_mount_victor_left_arm_joint" type="fixed">
    <origin rpy="0 0 0" xyz="0 0 0"/>
    <parent link="victor_left_arm_mount"/>
    <child link="victor_left_arm_link_0"/>
  </joint>
  <link name="victor_left_arm_link_0">
    <inertial>
      <origin rpy="0 0 0" xyz="-0.1 0 0.07"/>
      <mass value="5"/>
      <inertia ixx="0.05" ixy="0" ixz="0" iyy="0.06" iyz="0" izz="0.03"/>
    </inertial>
    <visual>
      <origin rpy="0 0 0" xyz="0 0 0"/>
      <geometry>
        <mesh filename="meshes/iiwa7/visual/link_0.stl"/>
      </geometry>
      <material name="Grey"/>
    </visual>
    <collision>
      <origin rpy="0 0 0" xyz="0 0 0"/>
      <geometry>
        <mesh filename="meshes/iiwa7/collision/link_0.stl"/>
      </geometry>
      <material name="Grey"/>
    </collision>
    <self_collision_checking>
      <origin rpy="0 0 0" xyz="0 0 0"/>
      <geometry>
        <capsule length="0.25" radius="0.15"/>
      </geometry>
    </self_collision_checking>
  </link>
  <!-- joint between link_0 and link_1 -->
  <joint name="victor_left_arm_joint_1" type="revolute">
    <parent link="victor_left_arm_link_0"/>
    <child link="victor_left_arm_link_1"/>
    <origin rpy="0 0 0" xyz="0 0 0.15"/>
    <axis xyz="0 0 1"/>
    <limit effort="300" lower="-2.9670597283903604" upper="2.9670597283903604" velocity="1.7453292519943295"/>
    <dynamics damping="0.5"/>
  </joint>
  <link name="victor_left_arm_link_1">
    <inertial>
      <origin rpy="0 0 0" xyz="0 -0.03 0.12"/>
      <mass value="3.4525"/>
      <inertia ixx="0.02183" ixy="0" ixz="0" iyy="0.007703" iyz="-0.003887" izz="0.02083"/>
    </inertial>
    <visual>
      <origin rpy="0 0 0" xyz="0 0 0.0075"/>
      <geometry>
        <mesh filename="meshes/iiwa7/visual/link_1.stl"/>
      </geometry>
      <material name="Orange"/>
    </visual>
    <collision>
      <origin rpy="0 0 0" xyz="0 0 0.0075"/>
      <geometry>
        <mesh filename="meshes/iiwa7/collision/link_1.stl"/>
      </geometry>
      <material name="Orange"/>
    </collision>
  </link>
  <joint name="victor_left_arm_joint_2" type="revolute">
    <parent link="victor_left_arm_link_1"/>
    <child link="victor_left_arm_link_2"/>
    <origin rpy="1.5707963267948966   0 3.141592653589793" xyz="0 0 0.19"/>
    <axis xyz="0 0 1"/>
    <limit effort="300" lower="-2.0943951023931953" upper="2.0943951023931953" velocity="1.7453292519943295"/>
    <dynamics damping="0.5"/>
  </joint>
  <link name="victor_left_arm_link_2">
    <inertial>
      <origin rpy="0 0 0" xyz="0.0003 0.059 0.042"/>
      <mass value="3.4821"/>
      <inertia ixx="0.02076" ixy="0" ixz="-0.003626" iyy="0.02179" iyz="0" izz="0.00779"/>
    </inertial>
    <visual>
      <origin rpy="0 0 0" xyz="0 0 0"/>
      <geometry>
        <mesh filename="meshes/iiwa7/visual/link_2.stl"/>
      </geometry>
      <material name="Orange"/>
    </visual>
    <collision>
      <origin rpy="0 0 0" xyz="0 0 0"/>
      <geometry>
        <mesh filename="meshes/iiwa7/collision/link_2.stl"/>
      </geometry>
      <material name="Orange"/>
    </collision>
  </link>
  <joint name="victor_left_arm_joint_3" type="revolute">
    <parent link="victor_left_arm_link_2"/>
    <child link="victor_left_arm_link_3"/>
    <origin rpy="1.5707963267948966 0 3.141592653589793" xyz="0 0.21 0"/>
    <axis xyz="0 0 1"/>
    <limit effort="300" lower="-2.9670597283903604" upper="2.9670597283903604" velocity="1.7453292519943295"/>
    <dynamics damping="0.5"/>
  </joint>
  <link name="victor_left_arm_link_3">
    <inertial>
      <origin rpy="0 0 0" xyz="0 0.03 0.13"/>
      <mass value="4.05623"/>
      <inertia ixx="0.03204" ixy="0" ixz="0" iyy="0.00972" iyz="0.006227" izz="0.03042"/>
    </inertial>
    <visual>
      <origin rpy="0 0 0" xyz="0 0 -0.026"/>
      <geometry>
        <mesh filename="meshes/iiwa7/visual/link_3.stl"/>
      </geometry>
      <material name="Orange"/>
    </visual>
    <collision>
      <origin rpy="0 0 0" xyz="0 0 -0.026"/>
      <geometry>
        <mesh filename="meshes/iiwa7/collision/link_3.stl"/>
      </geometry>
      <material name="Orange"/>
    </collision>
  </link>
  <joint name="victor_left_arm_joint_4" type="revolute">
    <parent link="victor_left_arm_link_3"/>
    <child link="victor_left_arm_link_4"/>
    <origin rpy="1.5707963267948966 0 0" xyz="0 0 0.19"/>
    <axis xyz="0 0 1"/>
    <limit effort="300" lower="-2.0943951023931953" upper="2.0943951023931953" velocity="2.2689280275926285"/>
    <dynamics damping="0.5"/>
  </joint>
  <link name="victor_left_arm_link_4">
    <inertial>
      <origin rpy="0 0 0" xyz="0 0.067 0.034"/>
      <mass value="3.4822"/>
      <inertia ixx="0.02178" ixy="0" ixz="0" iyy="0.02075" iyz="-0.003625" izz="0.007785"/>
    </inertial>
    <visual>
      <origin rpy="0 0 0" xyz="0 0 0"/>
      <geometry>
        <mesh filename="meshes/iiwa7/visual/link_4.stl"/>
      </geometry>
      <material name="Orange"/>
    </visual>
    <collision>
      <origin rpy="0 0 0" xyz="0 0 0"/>
      <geometry>
        <mesh filename="meshes/iiwa7/collision/link_4.stl"/>
      </geometry>
      <material name="Orange"/>
    </collision>
  </link>
  <joint name="victor_left_arm_joint_5" type="revolute">
    <parent link="victor_left_arm_link_4"/>
    <child link="victor_left_arm_link_5"/>
    <origin rpy="-1.5707963267948966 3.141592653589793 0" xyz="0 0.21 0"/>
    <axis xyz="0 0 1"/>
    <limit effort="300" lower="-2.9670597283903604" upper="2.9670597283903604" velocity="2.443460952792061"/>
    <dynamics damping="0.5"/>
  </joint>
  <link name="victor_left_arm_link_5">
    <inertial>
      <origin rpy="0 0 0" xyz="0.0001 0.021 0.076"/>
      <mass value="2.1633"/>
      <inertia ixx="0.01287" ixy="0" ixz="0" iyy="0.005708" iyz="-0.003946" izz="0.01112"/>
    </inertial>
    <visual>
      <origin rpy="0 0 0" xyz="0 0 -0.026"/>
      <geometry>
        <mesh filename="meshes/iiwa7/visual/link_5.stl"/>
      </geometry>
      <material name="Orange"/>
    </visual>
    <collision>
      <origin rpy="0 0 0" xyz="0 0 -0.026"/>
      <geometry>
        <mesh filename="meshes/iiwa7/collision/link_5.stl"/>
      </geometry>
      <material name="Orange"/>
    </collision>
  </link>
  <joint name="victor_left_arm_joint_6" type="revolute">
    <parent link="victor_left_arm_link_5"/>
    <child link="victor_left_arm_link_6"/>
    <origin rpy="1.5707963267948966 0 0" xyz="0 0.06070 0.19"/>
    <axis xyz="0 0 1"/>
    <limit effort="300" lower="-2.0943951023931953" upper="2.0943951023931953" velocity="3.141592653589793"/>
    <dynamics damping="0.5"/>
  </joint>
  <link name="victor_left_arm_link_6">
    <inertial>
      <origin rpy="0 0 0" xyz="0 0.0006 0.0004"/>
      <mass value="2.3466"/>
      <inertia ixx="0.006509" ixy="0" ixz="0" iyy="0.006259" iyz="0.00031891" izz="0.004527"/>
    </inertial>
    <visual>
      <origin rpy="0 0 0" xyz="0 0 0"/>
      <geometry>
        <mesh filename="meshes/iiwa7/visual/link_6.stl"/>
      </geometry>
      <material name="Orange"/>
    </visual>
    <collision>
      <origin rpy="0 0 0" xyz="0 0 0"/>
      <geometry>
        <mesh filename="meshes/iiwa7/collision/link_6.stl"/>
      </geometry>
      <material name="Orange"/>
    </collision>
  </link>
  <joint name="victor_left_arm_joint_7" type="revolute">
    <parent link="victor_left_arm_link_6"/>
    <child link="victor_left_arm_link_7"/>
    <origin rpy="-1.5707963267948966 3.141592653589793 0" xyz="0 0.081 0.06070"/>
    <axis xyz="0 0 1"/>
    <limit effort="300" lower="-3.0543261909900763" upper="3.0543261909900763" velocity="3.141592653589793"/>
    <dynamics damping="0.5"/>
  </joint>
  <link name="victor_left_arm_link_7">
    <inertial>
      <origin rpy="0 0 0" xyz="0 0 0.02"/>
      <mass value="3.129"/>
      <inertia ixx="0.01464" ixy="0.0005912" ixz="0" iyy="0.01465" iyz="0" izz="0.002872"/>
    </inertial>
    <visual>
      <origin rpy="0 0 0" xyz="0 0 -0.0005"/>
      <geometry>
        <mesh filename="meshes/iiwa7/visual/link_7_electric.stl"/>
      </geometry>
      <material name="Grey"/>
    </visual>
    <collision>
      <origin rpy="0 0 0" xyz="0 0 -0.0005"/>
      <geometry>
        <mesh filename="meshes/iiwa7/collision/link_7_electric.stl"/>
      </geometry>
      <material name="Grey"/>
    </collision>
  </link>
  <joint name="victor_left_arm_joint_flange" type="fixed">
    <parent link="victor_left_arm_link_7"/>
    <child link="victor_left_arm_flange"/>
    <origin rpy="0 0 0" xyz="0 0 0.045"/>
  </joint>
  <link name="victor_left_arm_flange">
        </link>
  <!-- Our usage above has been tweaked to match Kuka's internal usage, so identity transform -->
  <joint name="victor_left_arm_flange_kuka_joint" type="fixed">
    <parent link="victor_left_arm_flange"/>
    <child link="victor_left_arm_flange_kuka"/>
    <origin rpy="0 0 0" xyz="0 0 0"/>
  </joint>
  <link name="victor_left_arm_flange_kuka">
        </link>
  <!-- Link0 -->
  <gazebo reference="victor_left_arm_link_0">
    <kinematic>0</kinematic>
    <mu1>0.2</mu1>
    <mu2>0.2</mu2>
  </gazebo>
  <!-- Link1 -->
  <gazebo reference="victor_left_arm_link_1">
    <kinematic>0</kinematic>
    <mu1>0.2</mu1>
    <mu2>0.2</mu2>
  </gazebo>
  <!-- Link2 -->
  <gazebo reference="victor_left_arm_link_2">
    <kinematic>0</kinematic>
    <mu1>0.2</mu1>
    <mu2>0.2</mu2>
  </gazebo>
  <!-- Link3 -->
  <gazebo reference="victor_left_arm_link_3">
    <kinematic>0</kinematic>
    <mu1>0.2</mu1>
    <mu2>0.2</mu2>
  </gazebo>
  <!-- Link4 -->
  <gazebo reference="victor_left_arm_link_4">
    <kinematic>0</kinematic>
    <mu1>0.2</mu1>
    <mu2>0.2</mu2>
  </gazebo>
  <!-- Link5 -->
  <gazebo reference="victor_left_arm_link_5">
    <kinematic>0</kinematic>
    <mu1>0.2</mu1>
    <mu2>0.2</mu2>
  </gazebo>
  <!-- Link6 -->
  <gazebo reference="victor_left_arm_link_6">
    <kinematic>0</kinematic>
    <mu1>0.2</mu1>
    <mu2>0.2</mu2>
  </gazebo>
  <!-- Link7 -->
  <gazebo reference="victor_left_arm_link_7">
    <kinematic>0</kinematic>
    <mu1>0.2</mu1>
    <mu2>0.2</mu2>
  </gazebo>
  <transmission name="victor_left_arm_tran_1">
    <type>transmission_interface/SimpleTransmission</type>
    <joint name="victor_left_arm_joint_1">
      <hardwareInterface>hardware_interface/PositionJointInterface</hardwareInterface>
    </joint>
    <actuator name="victor_left_arm_motor_1">
      <mechanicalReduction>1</mechanicalReduction>
    </actuator>
  </transmission>
  <transmission name="victor_left_arm_tran_2">
    <type>transmission_interface/SimpleTransmission</type>
    <joint name="victor_left_arm_joint_2">
      <hardwareInterface>hardware_interface/PositionJointInterface</hardwareInterface>
    </joint>
    <actuator name="victor_left_arm_motor_2">
      <mechanicalReduction>1</mechanicalReduction>
    </actuator>
  </transmission>
  <transmission name="victor_left_arm_tran_3">
    <type>transmission_interface/SimpleTransmission</type>
    <joint name="victor_left_arm_joint_3">
      <hardwareInterface>hardware_interface/PositionJointInterface</hardwareInterface>
    </joint>
    <actuator name="victor_left_arm_motor_3">
      <mechanicalReduction>1</mechanicalReduction>
    </actuator>
  </transmission>
  <transmission name="victor_left_arm_tran_4">
    <type>transmission_interface/SimpleTransmission</type>
    <joint name="victor_left_arm_joint_4">
      <hardwareInterface>hardware_interface/PositionJointInterface</hardwareInterface>
    </joint>
    <actuator name="victor_left_arm_motor_4">
      <mechanicalReduction>1</mechanicalReduction>
    </actuator>
  </transmission>
  <transmission name="victor_left_arm_tran_5">
    <type>transmission_interface/SimpleTransmission</type>
    <joint name="victor_left_arm_joint_5">
      <hardwareInterface>hardware_interface/PositionJointInterface</hardwareInterface>
    </joint>
    <actuator name="victor_left_arm_motor_5">
      <mechanicalReduction>1</mechanicalReduction>
    </actuator>
  </transmission>
  <transmission name="victor_left_arm_tran_6">
    <type>transmission_interface/SimpleTransmission</type>
    <joint name="victor_left_arm_joint_6">
      <hardwareInterface>hardware_interface/PositionJointInterface</hardwareInterface>
    </joint>
    <actuator name="victor_left_arm_motor_6">
      <mechanicalReduction>1</mechanicalReduction>
    </actuator>
  </transmission>
  <transmission name="victor_left_arm_tran_7">
    <type>transmission_interface/SimpleTransmission</type>
    <joint name="victor_left_arm_joint_7">
      <hardwareInterface>hardware_interface/PositionJointInterface</hardwareInterface>
    </joint>
    <actuator name="victor_left_arm_motor_7">
      <mechanicalReduction>1</mechanicalReduction>
    </actuator>
  </transmission>
  <joint name="victor_joint_left_arm_world_frame_kuka" type="fixed">
    <parent link="victor_left_arm_mount"/>
    <child link="victor_left_arm_world_frame_kuka"/>
    <origin rpy="1.57079632679 0 0" xyz="0 0 0"/>
  </joint>
  <link name="victor_left_arm_world_frame_kuka">
    </link>
  <!--joint between {parent} and link_0-->
  <joint name="victor_right_arm_mount_victor_right_arm_joint" type="fixed">
    <origin rpy="0 0 0" xyz="0 0 0"/>
    <parent link="victor_right_arm_mount"/>
    <child link="victor_right_arm_link_0"/>
  </joint>
  <link name="victor_right_arm_link_0">
    <inertial>
      <origin rpy="0 0 0" xyz="-0.1 0 0.07"/>
      <mass value="5"/>
      <inertia ixx="0.05" ixy="0" ixz="0" iyy="0.06" iyz="0" izz="0.03"/>
    </inertial>
    <visual>
      <origin rpy="0 0 0" xyz="0 0 0"/>
      <geometry>
        <mesh filename="meshes/iiwa7/visual/link_0.stl"/>
      </geometry>
      <material name="Grey"/>
    </visual>
    <collision>
      <origin rpy="0 0 0" xyz="0 0 0"/>
      <geometry>
        <mesh filename="meshes/iiwa7/collision/link_0.stl"/>
      </geometry>
      <material name="Grey"/>
    </collision>
    <self_collision_checking>
      <origin rpy="0 0 0" xyz="0 0 0"/>
      <geometry>
        <capsule length="0.25" radius="0.15"/>
      </geometry>
    </self_collision_checking>
  </link>
  <!-- joint between link_0 and link_1 -->
  <joint name="victor_right_arm_joint_1" type="revolute">
    <parent link="victor_right_arm_link_0"/>
    <child link="victor_right_arm_link_1"/>
    <origin rpy="0 0 0" xyz="0 0 0.15"/>
    <axis xyz="0 0 1"/>
    <limit effort="300" lower="-2.9670597283903604" upper="2.9670597283903604" velocity="1.7453292519943295"/>
    <dynamics damping="0.5"/>
  </joint>
  <link name="victor_right_arm_link_1">
    <inertial>
      <origin rpy="0 0 0" xyz="0 -0.03 0.12"/>
      <mass value="3.4525"/>
      <inertia ixx="0.02183" ixy="0" ixz="0" iyy="0.007703" iyz="-0.003887" izz="0.02083"/>
    </inertial>
    <visual>
      <origin rpy="0 0 0" xyz="0 0 0.0075"/>
      <geometry>
        <mesh filename="meshes/iiwa7/visual/link_1.stl"/>
      </geometry>
      <material name="Orange"/>
    </visual>
    <collision>
      <origin rpy="0 0 0" xyz="0 0 0.0075"/>
      <geometry>
        <mesh filename="meshes/iiwa7/collision/link_1.stl"/>
      </geometry>
      <material name="Orange"/>
    </collision>
  </link>
  <joint name="victor_right_arm_joint_2" type="revolute">
    <parent link="victor_right_arm_link_1"/>
    <child link="victor_right_arm_link_2"/>
    <origin rpy="1.5707963267948966   0 3.141592653589793" xyz="0 0 0.19"/>
    <axis xyz="0 0 1"/>
    <limit effort="300" lower="-2.0943951023931953" upper="2.0943951023931953" velocity="1.7453292519943295"/>
    <dynamics damping="0.5"/>
  </joint>
  <link name="victor_right_arm_link_2">
    <inertial>
      <origin rpy="0 0 0" xyz="0.0003 0.059 0.042"/>
      <mass value="3.4821"/>
      <inertia ixx="0.02076" ixy="0" ixz="-0.003626" iyy="0.02179" iyz="0" izz="0.00779"/>
    </inertial>
    <visual>
      <origin rpy="0 0 0" xyz="0 0 0"/>
      <geometry>
        <mesh filename="meshes/iiwa7/visual/link_2.stl"/>
      </geometry>
      <material name="Orange"/>
    </visual>
    <collision>
      <origin rpy="0 0 0" xyz="0 0 0"/>
      <geometry>
        <mesh filename="meshes/iiwa7/collision/link_2.stl"/>
      </geometry>
      <material name="Orange"/>
    </collision>
  </link>
  <joint name="victor_right_arm_joint_3" type="revolute">
    <parent link="victor_right_arm_link_2"/>
    <child link="victor_right_arm_link_3"/>
    <origin rpy="1.5707963267948966 0 3.141592653589793" xyz="0 0.21 0"/>
    <axis xyz="0 0 1"/>
    <limit effort="300" lower="-2.9670597283903604" upper="2.9670597283903604" velocity="1.7453292519943295"/>
    <dynamics damping="0.5"/>
  </joint>
  <link name="victor_right_arm_link_3">
    <inertial>
      <origin rpy="0 0 0" xyz="0 0.03 0.13"/>
      <mass value="4.05623"/>
      <inertia ixx="0.03204" ixy="0" ixz="0" iyy="0.00972" iyz="0.006227" izz="0.03042"/>
    </inertial>
    <visual>
      <origin rpy="0 0 0" xyz="0 0 -0.026"/>
      <geometry>
        <mesh filename="meshes/iiwa7/visual/link_3.stl"/>
      </geometry>
      <material name="Orange"/>
    </visual>
    <collision>
      <origin rpy="0 0 0" xyz="0 0 -0.026"/>
      <geometry>
        <mesh filename="meshes/iiwa7/collision/link_3.stl"/>
      </geometry>
      <material name="Orange"/>
    </collision>
  </link>
  <joint name="victor_right_arm_joint_4" type="revolute">
    <parent link="victor_right_arm_link_3"/>
    <child link="victor_right_arm_link_4"/>
    <origin rpy="1.5707963267948966 0 0" xyz="0 0 0.19"/>
    <axis xyz="0 0 1"/>
    <limit effort="300" lower="-2.0943951023931953" upper="2.0943951023931953" velocity="2.2689280275926285"/>
    <dynamics damping="0.5"/>
  </joint>
  <link name="victor_right_arm_link_4">
    <inertial>
      <origin rpy="0 0 0" xyz="0 0.067 0.034"/>
      <mass value="3.4822"/>
      <inertia ixx="0.02178" ixy="0" ixz="0" iyy="0.02075" iyz="-0.003625" izz="0.007785"/>
    </inertial>
    <visual>
      <origin rpy="0 0 0" xyz="0 0 0"/>
      <geometry>
        <mesh filename="meshes/iiwa7/visual/link_4.stl"/>
      </geometry>
      <material name="Orange"/>
    </visual>
    <collision>
      <origin rpy="0 0 0" xyz="0 0 0"/>
      <geometry>
        <mesh filename="meshes/iiwa7/collision/link_4.stl"/>
      </geometry>
      <material name="Orange"/>
    </collision>
  </link>
  <joint name="victor_right_arm_joint_5" type="revolute">
    <parent link="victor_right_arm_link_4"/>
    <child link="victor_right_arm_link_5"/>
    <origin rpy="-1.5707963267948966 3.141592653589793 0" xyz="0 0.21 0"/>
    <axis xyz="0 0 1"/>
    <limit effort="300" lower="-2.9670597283903604" upper="2.9670597283903604" velocity="2.443460952792061"/>
    <dynamics damping="0.5"/>
  </joint>
  <link name="victor_right_arm_link_5">
    <inertial>
      <origin rpy="0 0 0" xyz="0.0001 0.021 0.076"/>
      <mass value="2.1633"/>
      <inertia ixx="0.01287" ixy="0" ixz="0" iyy="0.005708" iyz="-0.003946" izz="0.01112"/>
    </inertial>
    <visual>
      <origin rpy="0 0 0" xyz="0 0 -0.026"/>
      <geometry>
        <mesh filename="meshes/iiwa7/visual/link_5.stl"/>
      </geometry>
      <material name="Orange"/>
    </visual>
    <collision>
      <origin rpy="0 0 0" xyz="0 0 -0.026"/>
      <geometry>
        <mesh filename="meshes/iiwa7/collision/link_5.stl"/>
      </geometry>
      <material name="Orange"/>
    </collision>
  </link>
  <joint name="victor_right_arm_joint_6" type="revolute">
    <parent link="victor_right_arm_link_5"/>
    <child link="victor_right_arm_link_6"/>
    <origin rpy="1.5707963267948966 0 0" xyz="0 0.06070 0.19"/>
    <axis xyz="0 0 1"/>
    <limit effort="300" lower="-2.0943951023931953" upper="2.0943951023931953" velocity="3.141592653589793"/>
    <dynamics damping="0.5"/>
  </joint>
  <link name="victor_right_arm_link_6">
    <inertial>
      <origin rpy="0 0 0" xyz="0 0.0006 0.0004"/>
      <mass value="2.3466"/>
      <inertia ixx="0.006509" ixy="0" ixz="0" iyy="0.006259" iyz="0.00031891" izz="0.004527"/>
    </inertial>
    <visual>
      <origin rpy="0 0 0" xyz="0 0 0"/>
      <geometry>
        <mesh filename="meshes/iiwa7/visual/link_6.stl"/>
      </geometry>
      <material name="Orange"/>
    </visual>
    <collision>
      <origin rpy="0 0 0" xyz="0 0 0"/>
      <geometry>
        <mesh filename="meshes/iiwa7/collision/link_6.stl"/>
      </geometry>
      <material name="Orange"/>
    </collision>
  </link>
  <joint name="victor_right_arm_joint_7" type="revolute">
    <parent link="victor_right_arm_link_6"/>
    <child link="victor_right_arm_link_7"/>
    <origin rpy="-1.5707963267948966 3.141592653589793 0" xyz="0 0.081 0.06070"/>
    <axis xyz="0 0 1"/>
    <limit effort="300" lower="-3.0543261909900763" upper="3.0543261909900763" velocity="3.141592653589793"/>
    <dynamics damping="0.5"/>
  </joint>
  <link name="victor_right_arm_link_7">
    <inertial>
      <origin rpy="0 0 0" xyz="0 0 0.02"/>
      <mass value="3.129"/>
      <inertia ixx="0.01464" ixy="0.0005912" ixz="0" iyy="0.01465" iyz="0" izz="0.002872"/>
    </inertial>
    <visual>
      <origin rpy="0 0 0" xyz="0 0 -0.0005"/>
      <geometry>
        <mesh filename="meshes/iiwa7/visual/link_7_electric.stl"/>
      </geometry>
      <material name="Grey"/>
    </visual>
    <collision>
      <origin rpy="0 0 0" xyz="0 0 -0.0005"/>
      <geometry>
        <mesh filename="meshes/iiwa7/collision/link_7_electric.stl"/>
      </geometry>
      <material name="Grey"/>
    </collision>
  </link>
  <joint name="victor_right_arm_joint_flange" type="fixed">
    <parent link="victor_right_arm_link_7"/>
    <child link="victor_right_arm_flange"/>
    <origin rpy="0 0 0" xyz="0 0 0.045"/>
  </joint>
  <link name="victor_right_arm_flange">
        </link>
  <!-- Our usage above has been tweaked to match Kuka's internal usage, so identity transform -->
  <joint name="victor_right_arm_flange_kuka_joint" type="fixed">
    <parent link="victor_right_arm_flange"/>
    <child link="victor_right_arm_flange_kuka"/>
    <origin rpy="0 0 0" xyz="0 0 0"/>
  </joint>
  <link name="victor_right_arm_flange_kuka">
        </link>
  <!-- Link0 -->
  <gazebo reference="victor_right_arm_link_0">
    <kinematic>0</kinematic>
    <mu1>0.2</mu1>
    <mu2>0.2</mu2>
  </gazebo>
  <!-- Link1 -->
  <gazebo reference="victor_right_arm_link_1">
    <kinematic>0</kinematic>
    <mu1>0.2</mu1>
    <mu2>0.2</mu2>
  </gazebo>
  <!-- Link2 -->
  <gazebo reference="victor_right_arm_link_2">
    <kinematic>0</kinematic>
    <mu1>0.2</mu1>
    <mu2>0.2</mu2>
  </gazebo>
  <!-- Link3 -->
  <gazebo reference="victor_right_arm_link_3">
    <kinematic>0</kinematic>
    <mu1>0.2</mu1>
    <mu2>0.2</mu2>
  </gazebo>
  <!-- Link4 -->
  <gazebo reference="victor_right_arm_link_4">
    <kinematic>0</kinematic>
    <mu1>0.2</mu1>
    <mu2>0.2</mu2>
  </gazebo>
  <!-- Link5 -->
  <gazebo reference="victor_right_arm_link_5">
    <kinematic>0</kinematic>
    <mu1>0.2</mu1>
    <mu2>0.2</mu2>
  </gazebo>
  <!-- Link6 -->
  <gazebo reference="victor_right_arm_link_6">
    <kinematic>0</kinematic>
    <mu1>0.2</mu1>
    <mu2>0.2</mu2>
  </gazebo>
  <!-- Link7 -->
  <gazebo reference="victor_right_arm_link_7">
    <kinematic>0</kinematic>
    <mu1>0.2</mu1>
    <mu2>0.2</mu2>
  </gazebo>
  <transmission name="victor_right_arm_tran_1">
    <type>transmission_interface/SimpleTransmission</type>
    <joint name="victor_right_arm_joint_1">
      <hardwareInterface>hardware_interface/PositionJointInterface</hardwareInterface>
    </joint>
    <actuator name="victor_right_arm_motor_1">
      <mechanicalReduction>1</mechanicalReduction>
    </actuator>
  </transmission>
  <transmission name="victor_right_arm_tran_2">
    <type>transmission_interface/SimpleTransmission</type>
    <joint name="victor_right_arm_joint_2">
      <hardwareInterface>hardware_interface/PositionJointInterface</hardwareInterface>
    </joint>
    <actuator name="victor_right_arm_motor_2">
      <mechanicalReduction>1</mechanicalReduction>
    </actuator>
  </transmission>
  <transmission name="victor_right_arm_tran_3">
    <type>transmission_interface/SimpleTransmission</type>
    <joint name="victor_right_arm_joint_3">
      <hardwareInterface>hardware_interface/PositionJointInterface</hardwareInterface>
    </joint>
    <actuator name="victor_right_arm_motor_3">
      <mechanicalReduction>1</mechanicalReduction>
    </actuator>
  </transmission>
  <transmission name="victor_right_arm_tran_4">
    <type>transmission_interface/SimpleTransmission</type>
    <joint name="victor_right_arm_joint_4">
      <hardwareInterface>hardware_interface/PositionJointInterface</hardwareInterface>
    </joint>
    <actuator name="victor_right_arm_motor_4">
      <mechanicalReduction>1</mechanicalReduction>
    </actuator>
  </transmission>
  <transmission name="victor_right_arm_tran_5">
    <type>transmission_interface/SimpleTransmission</type>
    <joint name="victor_right_arm_joint_5">
      <hardwareInterface>hardware_interface/PositionJointInterface</hardwareInterface>
    </joint>
    <actuator name="victor_right_arm_motor_5">
      <mechanicalReduction>1</mechanicalReduction>
    </actuator>
  </transmission>
  <transmission name="victor_right_arm_tran_6">
    <type>transmission_interface/SimpleTransmission</type>
    <joint name="victor_right_arm_joint_6">
      <hardwareInterface>hardware_interface/PositionJointInterface</hardwareInterface>
    </joint>
    <actuator name="victor_right_arm_motor_6">
      <mechanicalReduction>1</mechanicalReduction>
    </actuator>
  </transmission>
  <transmission name="victor_right_arm_tran_7">
    <type>transmission_interface/SimpleTransmission</type>
    <joint name="victor_right_arm_joint_7">
      <hardwareInterface>hardware_interface/PositionJointInterface</hardwareInterface>
    </joint>
    <actuator name="victor_right_arm_motor_7">
      <mechanicalReduction>1</mechanicalReduction>
    </actuator>
  </transmission>
  <joint name="victor_joint_right_arm_world_frame_kuka" type="fixed">
    <parent link="victor_right_arm_mount"/>
    <child link="victor_right_arm_world_frame_kuka"/>
    <origin rpy="-1.57079632679 0 0" xyz="0 0 0"/>
  </joint>
  <link name="victor_right_arm_world_frame_kuka">
    </link>
  <!--joint between {parent} and link_0-->
  <joint name="victor_left_arm_flange_victor_left_joint" type="fixed">
    <origin rpy="0 0 0" xyz="0 0 -0.01"/>
    <parent link="victor_left_arm_flange"/>
    <child link="victor_left_gripper_mounting_bracket"/>
  </joint>
  <link name="victor_left_gripper_mounting_bracket">
    <visual>
      <origin rpy="0 0 0" xyz="0 0 0"/>
      <geometry>
        <mesh filename="meshes/robotiq_3finger/kuka_to_palm_connectors_visual.stl"/>
      </geometry>
      <material name="LightGrey"/>
    </visual>
    <collision>
      <origin rpy="0 0 0" xyz="0 0 0"/>
      <geometry>
        <mesh filename="meshes/robotiq_3finger/kuka_to_palm_connectors_collision.stl"/>
      </geometry>
      <material name="LightGrey"/>
    </collision>
  </link>
  <!--joint between {parent} and link_0-->
  <joint name="victor_right_arm_flange_victor_right_joint" type="fixed">
    <origin rpy="0 0 0" xyz="0 0 -0.01"/>
    <parent link="victor_right_arm_flange"/>
    <child link="victor_right_gripper_mounting_bracket"/>
  </joint>
  <link name="victor_right_gripper_mounting_bracket">
    <visual>
      <origin rpy="0 0 0" xyz="0 0 0"/>
      <geometry>
        <mesh filename="meshes/robotiq_3finger/kuka_to_palm_connectors_visual.stl"/>
      </geometry>
      <material name="LightGrey"/>
    </visual>
    <collision>
      <origin rpy="0 0 0" xyz="0 0 0"/>
      <geometry>
        <mesh filename="meshes/robotiq_3finger/kuka_to_palm_connectors_collision.stl"/>
      </geometry>
      <material name="LightGrey"/>
    </collision>
  </link>
  <joint name="l_robotiq_hand_joint" type="fixed">
    <origin rpy="1.5707963267948966 0 0.7853981633974483" xyz="0 0 0.07"/>
    <parent link="victor_left_gripper_mounting_bracket"/>
    <child link="l_palm"/>
  </joint>
  <link name="l_finger_1_link_0">
    <visual>
      <origin rpy="0 0 0" xyz="0.020 0 0"/>
      <geometry>
        <mesh filename="meshes/robotiq/visual/link_0.obj"/>
      </geometry>
      <material name="green">
        <color rgba="0 1 0 1"/>
      </material>
    </visual>
    <inertial>
      <origin rpy="0 0 0" xyz="0 0 0"/>
      <mass value="0.02133"/>
      <inertia ixx="4.598e-06" ixy="2.211e-07" ixz="0.0" iyy="4.441e-06" iyz="0.0" izz="5.906e-06"/>
    </inertial>
  </link>
  <link name="l_finger_1_link_1">
    <visual>
      <origin rpy="0 0 -0.52" xyz="0.050 -.028 0"/>
      <geometry>
        <mesh filename="meshes/robotiq/visual/link_1.obj"/>
      </geometry>
      <material name="green"/>
    </visual>
    <collision>
      <origin rpy="0 0 -0.61" xyz="0.028 -0.016 0.0"/>
      <geometry>
        <box size="0.048 0.018 0.0308"/>
      </geometry>
      <material name="red">
        <color rgba="1 0 0 1"/>
      </material>
      <surface>
        <friction>
          <ode>
            <mu>1.5</mu>
            <mu2>1.0</mu2>
          </ode>
        </friction>
      </surface>
    </collision>
    <inertial>
      <origin rpy="0 0 0" xyz="0 0 0"/>
      <mass value="0.10489"/>
      <inertia ixx="1.655e-05" ixy="-5.844e-07" ixz="0.0" iyy="7.334e-05" iyz="0.0" izz="8.054e-05"/>
    </inertial>
  </link>
  <link name="l_finger_1_link_2">
    <!--
				NOTE: This link has an offset in the z-direction based on the models that were
				used to generate grap-it poses.  With the offset below the model appears visually
				correct, but it is suspect.
				-->
    <visual>
      <origin rpy="0 0 0" xyz="0.039 0 0.0075"/>
      <geometry>
        <mesh filename="meshes/robotiq/visual/link_2.obj"/>
      </geometry>
      <material name="green"/>
    </visual>
    <collision>
      <origin rpy="0 0 0.0" xyz="0.023 0.002 0.0"/>
      <geometry>
        <box size="0.0285 0.01 0.0308"/>
      </geometry>
      <material name="red">
        <color rgba="1 0 0 1"/>
      </material>
      <surface>
        <friction>
          <ode>
            <mu>1.5</mu>
            <mu2>1.0</mu2>
          </ode>
        </friction>
      </surface>
    </collision>
    <inertial>
      <origin rpy="0 0 0" xyz="0 0 0"/>
      <mass value="0.0601"/>
      <inertia ixx="7.304e-06" ixy="-2.645e-06" ixz="3.537e-07" iyy="1.918e-05" iyz="6.920e-07" izz="2.214e-05"/>
    </inertial>
  </link>
  <link name="l_finger_1_link_3">
    <visual>
      <origin rpy="0 0 0.52" xyz="0 0 0"/>
      <geometry>
        <mesh filename="meshes/robotiq/visual/link_3.obj"/>
      </geometry>
      <material name="green"/>
    </visual>
    <collision>
      <origin rpy="0 0 0.58" xyz="0.015 0.0135 0.0"/>
      <geometry>
        <box size="0.03 0.007 0.0308"/>
      </geometry>
      <material name="red">
        <color rgba="1 0 0 1"/>
      </material>
      <surface>
        <friction>
          <ode>
            <mu>1.5</mu>
            <mu2>1.0</mu2>
          </ode>
        </friction>
      </surface>
    </collision>
    <inertial>
      <origin rpy="0 0 0" xyz="0 0 0"/>
      <mass value="0.024"/>
      <inertia ixx="2.021e-06" ixy="-7.733e-07" ixz="-1.031e-08" iyy="4.908e-06" iyz="0.0" izz="4.578e-06"/>
    </inertial>
  </link>
  <joint name="l_finger_1_joint_1" type="revolute">
    <parent link="l_finger_1_link_0"/>
    <child link="l_finger_1_link_1"/>
    <axis xyz="0 0 1"/>
    <origin rpy="0 0 0" xyz="0.020 0 0"/>
    <limit effort="100" lower="0" upper="1.2217304764" velocity="100"/>
  </joint>
  <joint name="l_finger_1_joint_2" type="revolute">
    <parent link="l_finger_1_link_1"/>
    <child link="l_finger_1_link_2"/>
    <axis xyz="0 0 1"/>
    <origin rpy="0 0 -0.52" xyz="0.050 -.028 0"/>
    <limit effort="100" lower="0" upper="1.57079632679" velocity="100"/>
  </joint>
  <joint name="l_finger_1_joint_3" type="revolute">
    <parent link="l_finger_1_link_2"/>
    <child link="l_finger_1_link_3"/>
    <axis xyz="0 0 1"/>
    <origin rpy="0 0 0" xyz="0.039 0 0"/>
    <!-- upper limit -0.0523598775598 -->
    <limit effort="100" lower="-1.2217304764" upper="1.0" velocity="100"/>
  </joint>
  <link name="l_finger_2_link_0">
    <visual>
      <origin rpy="0 0 0" xyz="0.020 0 0"/>
      <geometry>
        <mesh filename="meshes/robotiq/visual/link_0.obj"/>
      </geometry>
      <material name="green">
        <color rgba="0 1 0 1"/>
      </material>
    </visual>
    <inertial>
      <origin rpy="0 0 0" xyz="0 0 0"/>
      <mass value="0.02133"/>
      <inertia ixx="4.598e-06" ixy="2.211e-07" ixz="0.0" iyy="4.441e-06" iyz="0.0" izz="5.906e-06"/>
    </inertial>
  </link>
  <link name="l_finger_2_link_1">
    <visual>
      <origin rpy="0 0 -0.52" xyz="0.050 -.028 0"/>
      <geometry>
        <mesh filename="meshes/robotiq/visual/link_1.obj"/>
      </geometry>
      <material name="green"/>
    </visual>
    <collision>
      <origin rpy="0 0 -0.61" xyz="0.028 -0.016 0.0"/>
      <geometry>
        <box size="0.048 0.018 0.0308"/>
      </geometry>
      <material name="red">
        <color rgba="1 0 0 1"/>
      </material>
      <surface>
        <friction>
          <ode>
            <mu>1.5</mu>
            <mu2>1.0</mu2>
          </ode>
        </friction>
      </surface>
    </collision>
    <inertial>
      <origin rpy="0 0 0" xyz="0 0 0"/>
      <mass value="0.10489"/>
      <inertia ixx="1.655e-05" ixy="-5.844e-07" ixz="0.0" iyy="7.334e-05" iyz="0.0" izz="8.054e-05"/>
    </inertial>
  </link>
  <link name="l_finger_2_link_2">
    <!--
				NOTE: This link has an offset in the z-direction based on the models that were
				used to generate grap-it poses.  With the offset below the model appears visually
				correct, but it is suspect.
				-->
    <visual>
      <origin rpy="0 0 0" xyz="0.039 0 0.0075"/>
      <geometry>
        <mesh filename="meshes/robotiq/visual/link_2.obj"/>
      </geometry>
      <material name="green"/>
    </visual>
    <collision>
      <origin rpy="0 0 0.0" xyz="0.023 0.002 0.0"/>
      <geometry>
        <box size="0.0285 0.01 0.0308"/>
      </geometry>
      <material name="red">
        <color rgba="1 0 0 1"/>
      </material>
      <surface>
        <friction>
          <ode>
            <mu>1.5</mu>
            <mu2>1.0</mu2>
          </ode>
        </friction>
      </surface>
    </collision>
    <inertial>
      <origin rpy="0 0 0" xyz="0 0 0"/>
      <mass value="0.0601"/>
      <inertia ixx="7.304e-06" ixy="-2.645e-06" ixz="3.537e-07" iyy="1.918e-05" iyz="6.920e-07" izz="2.214e-05"/>
    </inertial>
  </link>
  <link name="l_finger_2_link_3">
    <visual>
      <origin rpy="0 0 0.52" xyz="0 0 0"/>
      <geometry>
        <mesh filename="meshes/robotiq/visual/link_3.obj"/>
      </geometry>
      <material name="green"/>
    </visual>
    <collision>
      <origin rpy="0 0 0.58" xyz="0.015 0.0135 0.0"/>
      <geometry>
        <box size="0.03 0.007 0.0308"/>
      </geometry>
      <material name="red">
        <color rgba="1 0 0 1"/>
      </material>
      <surface>
        <friction>
          <ode>
            <mu>1.5</mu>
            <mu2>1.0</mu2>
          </ode>
        </friction>
      </surface>
    </collision>
    <inertial>
      <origin rpy="0 0 0" xyz="0 0 0"/>
      <mass value="0.024"/>
      <inertia ixx="2.021e-06" ixy="-7.733e-07" ixz="-1.031e-08" iyy="4.908e-06" iyz="0.0" izz="4.578e-06"/>
    </inertial>
  </link>
  <joint name="l_finger_2_joint_1" type="revolute">
    <parent link="l_finger_2_link_0"/>
    <child link="l_finger_2_link_1"/>
    <axis xyz="0 0 1"/>
    <origin rpy="0 0 0" xyz="0.020 0 0"/>
    <limit effort="100" lower="0" upper="1.2217304764" velocity="100"/>
  </joint>
  <joint name="l_finger_2_joint_2" type="revolute">
    <parent link="l_finger_2_link_1"/>
    <child link="l_finger_2_link_2"/>
    <axis xyz="0 0 1"/>
    <origin rpy="0 0 -0.52" xyz="0.050 -.028 0"/>
    <limit effort="100" lower="0" upper="1.57079632679" velocity="100"/>
  </joint>
  <joint name="l_finger_2_joint_3" type="revolute">
    <parent link="l_finger_2_link_2"/>
    <child link="l_finger_2_link_3"/>
    <axis xyz="0 0 1"/>
    <origin rpy="0 0 0" xyz="0.039 0 0"/>
    <!-- upper limit -0.0523598775598 -->
    <limit effort="100" lower="-1.2217304764" upper="1.0" velocity="100"/>
  </joint>
  <link name="l_finger_middle_link_0">
    <visual>
      <origin rpy="0 0 0" xyz="0.020 0 0"/>
      <geometry>
        <mesh filename="meshes/robotiq/visual/link_0.obj"/>
      </geometry>
      <material name="green">
        <color rgba="0 1 0 1"/>
      </material>
    </visual>
    <inertial>
      <origin rpy="0 0 0" xyz="0 0 0"/>
      <mass value="0.02133"/>
      <inertia ixx="4.598e-06" ixy="2.211e-07" ixz="0.0" iyy="4.441e-06" iyz="0.0" izz="5.906e-06"/>
    </inertial>
  </link>
  <link name="l_finger_middle_link_1">
    <visual>
      <origin rpy="0 0 -0.52" xyz="0.050 -.028 0"/>
      <geometry>
        <mesh filename="meshes/robotiq/visual/link_1.obj"/>
      </geometry>
      <material name="green"/>
    </visual>
    <collision>
      <origin rpy="0 0 -0.61" xyz="0.028 -0.016 0.0"/>
      <geometry>
        <box size="0.048 0.018 0.0308"/>
      </geometry>
      <material name="red">
        <color rgba="1 0 0 1"/>
      </material>
      <surface>
        <friction>
          <ode>
            <mu>1.5</mu>
            <mu2>1.0</mu2>
          </ode>
        </friction>
      </surface>
    </collision>
    <inertial>
      <origin rpy="0 0 0" xyz="0 0 0"/>
      <mass value="0.10489"/>
      <inertia ixx="1.655e-05" ixy="-5.844e-07" ixz="0.0" iyy="7.334e-05" iyz="0.0" izz="8.054e-05"/>
    </inertial>
  </link>
  <link name="l_finger_middle_link_2">
    <!--
				NOTE: This link has an offset in the z-direction based on the models that were
				used to generate grap-it poses.  With the offset below the model appears visually
				correct, but it is suspect.
				-->
    <visual>
      <origin rpy="0 0 0" xyz="0.039 0 0.0075"/>
      <geometry>
        <mesh filename="meshes/robotiq/visual/link_2.obj"/>
      </geometry>
      <material name="green"/>
    </visual>
    <collision>
      <origin rpy="0 0 0.0" xyz="0.023 0.002 0.0"/>
      <geometry>
        <box size="0.0285 0.01 0.0308"/>
      </geometry>
      <material name="red">
        <color rgba="1 0 0 1"/>
      </material>
      <surface>
        <friction>
          <ode>
            <mu>1.5</mu>
            <mu2>1.0</mu2>
          </ode>
        </friction>
      </surface>
    </collision>
    <inertial>
      <origin rpy="0 0 0" xyz="0 0 0"/>
      <mass value="0.0601"/>
      <inertia ixx="7.304e-06" ixy="-2.645e-06" ixz="3.537e-07" iyy="1.918e-05" iyz="6.920e-07" izz="2.214e-05"/>
    </inertial>
  </link>
  <link name="l_finger_middle_link_3">
    <visual>
      <origin rpy="0 0 0.52" xyz="0 0 0"/>
      <geometry>
        <mesh filename="meshes/robotiq/visual/link_3.obj"/>
      </geometry>
      <material name="green"/>
    </visual>
    <collision>
      <origin rpy="0 0 0.58" xyz="0.015 0.0135 0.0"/>
      <geometry>
        <box size="0.03 0.007 0.0308"/>
      </geometry>
      <material name="red">
        <color rgba="1 0 0 1"/>
      </material>
      <surface>
        <friction>
          <ode>
            <mu>1.5</mu>
            <mu2>1.0</mu2>
          </ode>
        </friction>
      </surface>
    </collision>
    <inertial>
      <origin rpy="0 0 0" xyz="0 0 0"/>
      <mass value="0.024"/>
      <inertia ixx="2.021e-06" ixy="-7.733e-07" ixz="-1.031e-08" iyy="4.908e-06" iyz="0.0" izz="4.578e-06"/>
    </inertial>
  </link>
  <joint name="l_finger_middle_joint_1" type="revolute">
    <parent link="l_finger_middle_link_0"/>
    <child link="l_finger_middle_link_1"/>
    <axis xyz="0 0 1"/>
    <origin rpy="0 0 0" xyz="0.020 0 0"/>
    <limit effort="100" lower="0" upper="1.2217304764" velocity="100"/>
  </joint>
  <joint name="l_finger_middle_joint_2" type="revolute">
    <parent link="l_finger_middle_link_1"/>
    <child link="l_finger_middle_link_2"/>
    <axis xyz="0 0 1"/>
    <origin rpy="0 0 -0.52" xyz="0.050 -.028 0"/>
    <limit effort="100" lower="0" upper="1.57079632679" velocity="100"/>
  </joint>
  <joint name="l_finger_middle_joint_3" type="revolute">
    <parent link="l_finger_middle_link_2"/>
    <child link="l_finger_middle_link_3"/>
    <hardwareInterface>EffortJointInterface</hardwareInterface>
    <axis xyz="0 0 1"/>
    <origin rpy="0 0 0" xyz="0.039 0 0"/>
    <!-- upper limit -0.0523598775598 -->
    <limit effort="100" lower="-1.2217304764" upper="1.0" velocity="100"/>
  </joint>
  <link name="l_palm">
    <visual>
      <geometry>
        <mesh filename="meshes/robotiq/visual/palm.obj"/>
      </geometry>
      <material name="green">
        <color rgba="0 1 0 1"/>
      </material>
    </visual>
    <collision>
      <origin rpy="0 0 0" xyz="0.0 -0.001 0.0"/>
      <geometry>
        <box size="0.0425 0.1048 0.1302"/>
      </geometry>
      <material name="red">
        <color rgba="1 0 0 1"/>
      </material>
      <surface>
        <friction>
          <ode>
            <mu>1.5</mu>
            <mu2>1.0</mu2>
          </ode>
        </friction>
      </surface>
    </collision>
    <inertial>
      <origin rpy="0 0 0" xyz="0 0 0"/>
      <mass value="1.72568"/>
      <inertia ixx="2.983e-03" ixy="1.075e-04" ixz="4.738e-08" iyy="3.607e-03" iyz="0.0" izz="2.840e-03"/>
    </inertial>
  </link>
  <joint name="l_palm_finger_1_joint" type="revolute">
    <parent link="l_palm"/>
    <child link="l_finger_1_link_0"/>
    <axis xyz="0 1 0"/>
    <origin rpy="0 3.1416 -1.57" xyz="-0.0455 0.0214 0.036"/>
    <limit effort="100" lower="-0.16" upper="0.25" velocity="100"/>
  </joint>

  <joint name="l_palm_finger_2_joint" type="revolute">
    <parent link="l_palm"/>
    <child link="l_finger_2_link_0"/>
    <axis xyz="0 1 0"/>
    <origin rpy="0 3.1416 -1.57" xyz="-0.0455 0.0214 -0.036"/>
    <limit effort="100" lower="-0.25" upper="0.16" velocity="100"/>
  </joint>

  <joint name="l_palm_finger_middle_joint" type="fixed">
    <parent link="l_palm"/>
    <child link="l_finger_middle_link_0"/>
    <axis xyz="0 0 1"/>
    <origin rpy="0 0 1.57" xyz="0.0455 0.0214 0"/>
  </joint>
  <!--
		<include filename="${prefix}$(find robotiq_3f_gripper_visualization)/cfg/robotiq-3f-gripper_finger_articulated_macro.xacro" />
		<xacro:robotiq-3f-gripper_finger_articulated prefix=""/>
	-->


  <joint name="r_robotiq_hand_joint" type="fixed">
    <origin rpy="1.5707963267948966 0 0.7853981633974483" xyz="0 0 0.07"/>
    <parent link="victor_right_gripper_mounting_bracket"/>
    <child link="r_palm"/>
  </joint>
  <link name="r_finger_1_link_0">
    <visual>
      <origin rpy="0 0 0" xyz="0.020 0 0"/>
      <geometry>
        <mesh filename="meshes/robotiq/visual/link_0.obj"/>
      </geometry>
      <material name="green">
        <color rgba="0 1 0 1"/>
      </material>
    </visual>
    <inertial>
      <origin rpy="0 0 0" xyz="0 0 0"/>
      <mass value="0.02133"/>
      <inertia ixx="4.598e-06" ixy="2.211e-07" ixz="0.0" iyy="4.441e-06" iyz="0.0" izz="5.906e-06"/>
    </inertial>
  </link>
  <link name="r_finger_1_link_1">
    <visual>
      <origin rpy="0 0 -0.52" xyz="0.050 -.028 0"/>
      <geometry>
        <mesh filename="meshes/robotiq/visual/link_1.obj"/>
      </geometry>
      <material name="green"/>
    </visual>
    <collision>
      <origin rpy="0 0 -0.61" xyz="0.028 -0.016 0.0"/>
      <geometry>
        <box size="0.048 0.018 0.0308"/>
      </geometry>
      <material name="red">
        <color rgba="1 0 0 1"/>
      </material>
      <surface>
        <friction>
          <ode>
            <mu>1.5</mu>
            <mu2>1.0</mu2>
          </ode>
        </friction>
      </surface>
    </collision>
    <inertial>
      <origin rpy="0 0 0" xyz="0 0 0"/>
      <mass value="0.10489"/>
      <inertia ixx="1.655e-05" ixy="-5.844e-07" ixz="0.0" iyy="7.334e-05" iyz="0.0" izz="8.054e-05"/>
    </inertial>
  </link>
  <link name="r_finger_1_link_2">
    <!--
				NOTE: This link has an offset in the z-direction based on the models that were
				used to generate grap-it poses.  With the offset below the model appears visually
				correct, but it is suspect.
				-->
    <visual>
      <origin rpy="0 0 0" xyz="0.039 0 0.0075"/>
      <geometry>
        <mesh filename="meshes/robotiq/visual/link_2.obj"/>
      </geometry>
      <material name="green"/>
    </visual>
    <collision>
      <origin rpy="0 0 0.0" xyz="0.023 0.002 0.0"/>
      <geometry>
        <box size="0.0285 0.01 0.0308"/>
      </geometry>
      <material name="red">
        <color rgba="1 0 0 1"/>
      </material>
      <surface>
        <friction>
          <ode>
            <mu>1.5</mu>
            <mu2>1.0</mu2>
          </ode>
        </friction>
      </surface>
    </collision>
    <inertial>
      <origin rpy="0 0 0" xyz="0 0 0"/>
      <mass value="0.0601"/>
      <inertia ixx="7.304e-06" ixy="-2.645e-06" ixz="3.537e-07" iyy="1.918e-05" iyz="6.920e-07" izz="2.214e-05"/>
    </inertial>
  </link>
  <link name="r_finger_1_link_3">
    <visual>
      <origin rpy="0 0 0.52" xyz="0 0 0"/>
      <geometry>
        <mesh filename="meshes/robotiq/visual/link_3.obj"/>
      </geometry>
      <material name="green"/>
    </visual>
    <collision>
      <origin rpy="0 0 0.58" xyz="0.015 0.0135 0.0"/>
      <geometry>
        <box size="0.03 0.007 0.0308"/>
      </geometry>
      <material name="red">
        <color rgba="1 0 0 1"/>
      </material>
      <surface>
        <friction>
          <ode>
            <mu>1.5</mu>
            <mu2>1.0</mu2>
          </ode>
        </friction>
      </surface>
    </collision>
    <inertial>
      <origin rpy="0 0 0" xyz="0 0 0"/>
      <mass value="0.024"/>
      <inertia ixx="2.021e-06" ixy="-7.733e-07" ixz="-1.031e-08" iyy="4.908e-06" iyz="0.0" izz="4.578e-06"/>
    </inertial>
  </link>
  <joint name="r_finger_1_joint_1" type="revolute">
    <parent link="r_finger_1_link_0"/>
    <child link="r_finger_1_link_1"/>
    <axis xyz="0 0 1"/>
    <origin rpy="0 0 0" xyz="0.020 0 0"/>
    <limit effort="100" lower="0" upper="1.2217304764" velocity="100"/>
  </joint>
  <joint name="r_finger_1_joint_2" type="revolute">
    <parent link="r_finger_1_link_1"/>
    <child link="r_finger_1_link_2"/>
    <axis xyz="0 0 1"/>
    <origin rpy="0 0 -0.52" xyz="0.050 -.028 0"/>
    <limit effort="100" lower="0" upper="1.57079632679" velocity="100"/>
  </joint>

  <joint name="r_finger_1_joint_3" type="revolute">
    <parent link="r_finger_1_link_2"/>
    <child link="r_finger_1_link_3"/>
    <axis xyz="0 0 1"/>
    <origin rpy="0 0 0" xyz="0.039 0 0"/>
    <!-- upper limit -0.0523598775598 -->
    <limit effort="100" lower="-1.2217304764" upper="1.0" velocity="100"/>
  </joint>
  <link name="r_finger_2_link_0">
    <visual>
      <origin rpy="0 0 0" xyz="0.020 0 0"/>
      <geometry>
        <mesh filename="meshes/robotiq/visual/link_0.obj"/>
      </geometry>
      <material name="green">
        <color rgba="0 1 0 1"/>
      </material>
    </visual>
    <inertial>
      <origin rpy="0 0 0" xyz="0 0 0"/>
      <mass value="0.02133"/>
      <inertia ixx="4.598e-06" ixy="2.211e-07" ixz="0.0" iyy="4.441e-06" iyz="0.0" izz="5.906e-06"/>
    </inertial>
  </link>
  <link name="r_finger_2_link_1">
    <visual>
      <origin rpy="0 0 -0.52" xyz="0.050 -.028 0"/>
      <geometry>
        <mesh filename="meshes/robotiq/visual/link_1.obj"/>
      </geometry>
      <material name="green"/>
    </visual>
    <collision>
      <origin rpy="0 0 -0.61" xyz="0.028 -0.016 0.0"/>
      <geometry>
        <box size="0.048 0.018 0.0308"/>
      </geometry>
      <material name="red">
        <color rgba="1 0 0 1"/>
      </material>
      <surface>
        <friction>
          <ode>
            <mu>1.5</mu>
            <mu2>1.0</mu2>
          </ode>
        </friction>
      </surface>
    </collision>
    <inertial>
      <origin rpy="0 0 0" xyz="0 0 0"/>
      <mass value="0.10489"/>
      <inertia ixx="1.655e-05" ixy="-5.844e-07" ixz="0.0" iyy="7.334e-05" iyz="0.0" izz="8.054e-05"/>
    </inertial>
  </link>
  <link name="r_finger_2_link_2">
    <!--
				NOTE: This link has an offset in the z-direction based on the models that were
				used to generate grap-it poses.  With the offset below the model appears visually
				correct, but it is suspect.
				-->
    <visual>
      <origin rpy="0 0 0" xyz="0.039 0 0.0075"/>
      <geometry>
        <mesh filename="meshes/robotiq/visual/link_2.obj"/>
      </geometry>
      <material name="green"/>
    </visual>
    <collision>
      <origin rpy="0 0 0.0" xyz="0.023 0.002 0.0"/>
      <geometry>
        <box size="0.0285 0.01 0.0308"/>
      </geometry>
      <material name="red">
        <color rgba="1 0 0 1"/>
      </material>
      <surface>
        <friction>
          <ode>
            <mu>1.5</mu>
            <mu2>1.0</mu2>
          </ode>
        </friction>
      </surface>
    </collision>
    <inertial>
      <origin rpy="0 0 0" xyz="0 0 0"/>
      <mass value="0.0601"/>
      <inertia ixx="7.304e-06" ixy="-2.645e-06" ixz="3.537e-07" iyy="1.918e-05" iyz="6.920e-07" izz="2.214e-05"/>
    </inertial>
  </link>
  <link name="r_finger_2_link_3">
    <visual>
      <origin rpy="0 0 0.52" xyz="0 0 0"/>
      <geometry>
        <mesh filename="meshes/robotiq/visual/link_3.obj"/>
      </geometry>
      <material name="green"/>
    </visual>
    <collision>
      <origin rpy="0 0 0.58" xyz="0.015 0.0135 0.0"/>
      <geometry>
        <box size="0.03 0.007 0.0308"/>
      </geometry>
      <material name="red">
        <color rgba="1 0 0 1"/>
      </material>
      <surface>
        <friction>
          <ode>
            <mu>1.5</mu>
            <mu2>1.0</mu2>
          </ode>
        </friction>
      </surface>
    </collision>
    <inertial>
      <origin rpy="0 0 0" xyz="0 0 0"/>
      <mass value="0.024"/>
      <inertia ixx="2.021e-06" ixy="-7.733e-07" ixz="-1.031e-08" iyy="4.908e-06" iyz="0.0" izz="4.578e-06"/>
    </inertial>
  </link>
  <joint name="r_finger_2_joint_1" type="revolute">
    <parent link="r_finger_2_link_0"/>
    <child link="r_finger_2_link_1"/>
    <axis xyz="0 0 1"/>
    <origin rpy="0 0 0" xyz="0.020 0 0"/>
    <limit effort="100" lower="0" upper="1.2217304764" velocity="100"/>
  </joint>
  <joint name="r_finger_2_joint_2" type="revolute">
    <parent link="r_finger_2_link_1"/>
    <child link="r_finger_2_link_2"/>
    <axis xyz="0 0 1"/>
    <origin rpy="0 0 -0.52" xyz="0.050 -.028 0"/>
    <limit effort="100" lower="0" upper="1.57079632679" velocity="100"/>
  </joint>
  <joint name="r_finger_2_joint_3" type="revolute">
    <parent link="r_finger_2_link_2"/>
    <child link="r_finger_2_link_3"/>
    <axis xyz="0 0 1"/>
    <origin rpy="0 0 0" xyz="0.039 0 0"/>
    <!-- upper limit -0.0523598775598 -->
    <limit effort="100" lower="-1.2217304764" upper="1.0" velocity="100"/>
  </joint>
  <link name="r_finger_middle_link_0">
    <visual>
      <origin rpy="0 0 0" xyz="0.020 0 0"/>
      <geometry>
        <mesh filename="meshes/robotiq/visual/link_0.obj"/>
      </geometry>
      <material name="green">
        <color rgba="0 1 0 1"/>
      </material>
    </visual>
    <inertial>
      <origin rpy="0 0 0" xyz="0 0 0"/>
      <mass value="0.02133"/>
      <inertia ixx="4.598e-06" ixy="2.211e-07" ixz="0.0" iyy="4.441e-06" iyz="0.0" izz="5.906e-06"/>
    </inertial>
  </link>
  <link name="r_finger_middle_link_1">
    <visual>
      <origin rpy="0 0 -0.52" xyz="0.050 -.028 0"/>
      <geometry>
        <mesh filename="meshes/robotiq/visual/link_1.obj"/>
      </geometry>
      <material name="green"/>
    </visual>
    <collision>
      <origin rpy="0 0 -0.61" xyz="0.028 -0.016 0.0"/>
      <geometry>
        <box size="0.048 0.018 0.0308"/>
      </geometry>
      <material name="red">
        <color rgba="1 0 0 1"/>
      </material>
      <surface>
        <friction>
          <ode>
            <mu>1.5</mu>
            <mu2>1.0</mu2>
          </ode>
        </friction>
      </surface>
    </collision>
    <inertial>
      <origin rpy="0 0 0" xyz="0 0 0"/>
      <mass value="0.10489"/>
      <inertia ixx="1.655e-05" ixy="-5.844e-07" ixz="0.0" iyy="7.334e-05" iyz="0.0" izz="8.054e-05"/>
    </inertial>
  </link>
  <link name="r_finger_middle_link_2">
    <!--
				NOTE: This link has an offset in the z-direction based on the models that were
				used to generate grap-it poses.  With the offset below the model appears visually
				correct, but it is suspect.
				-->
    <visual>
      <origin rpy="0 0 0" xyz="0.039 0 0.0075"/>
      <geometry>
        <mesh filename="meshes/robotiq/visual/link_2.obj"/>
      </geometry>
      <material name="green"/>
    </visual>
    <collision>
      <origin rpy="0 0 0.0" xyz="0.023 0.002 0.0"/>
      <geometry>
        <box size="0.0285 0.01 0.0308"/>
      </geometry>
      <material name="red">
        <color rgba="1 0 0 1"/>
      </material>
      <surface>
        <friction>
          <ode>
            <mu>1.5</mu>
            <mu2>1.0</mu2>
          </ode>
        </friction>
      </surface>
    </collision>
    <inertial>
      <origin rpy="0 0 0" xyz="0 0 0"/>
      <mass value="0.0601"/>
      <inertia ixx="7.304e-06" ixy="-2.645e-06" ixz="3.537e-07" iyy="1.918e-05" iyz="6.920e-07" izz="2.214e-05"/>
    </inertial>
  </link>
  <link name="r_finger_middle_link_3">
    <visual>
      <origin rpy="0 0 0.52" xyz="0 0 0"/>
      <geometry>
        <mesh filename="meshes/robotiq/visual/link_3.obj"/>
      </geometry>
      <material name="green"/>
    </visual>
    <collision>
      <origin rpy="0 0 0.58" xyz="0.015 0.0135 0.0"/>
      <geometry>
        <box size="0.03 0.007 0.0308"/>
      </geometry>
      <material name="red">
        <color rgba="1 0 0 1"/>
      </material>
      <surface>
        <friction>
          <ode>
            <mu>1.5</mu>
            <mu2>1.0</mu2>
          </ode>
        </friction>
      </surface>
    </collision>
    <inertial>
      <origin rpy="0 0 0" xyz="0 0 0"/>
      <mass value="0.024"/>
      <inertia ixx="2.021e-06" ixy="-7.733e-07" ixz="-1.031e-08" iyy="4.908e-06" iyz="0.0" izz="4.578e-06"/>
    </inertial>
  </link>
  <joint name="r_finger_middle_joint_1" type="revolute">
    <parent link="r_finger_middle_link_0"/>
    <child link="r_finger_middle_link_1"/>
    <axis xyz="0 0 1"/>
    <origin rpy="0 0 0" xyz="0.020 0 0"/>
    <limit effort="100" lower="0" upper="1.2217304764" velocity="100"/>
  </joint>
  <joint name="r_finger_middle_joint_2" type="revolute">
    <parent link="r_finger_middle_link_1"/>
    <child link="r_finger_middle_link_2"/>
    <axis xyz="0 0 1"/>
    <origin rpy="0 0 -0.52" xyz="0.050 -.028 0"/>
    <limit effort="100" lower="0" upper="1.57079632679" velocity="100"/>
  </joint>
  <joint name="r_finger_middle_joint_3" type="revolute">
    <parent link="r_finger_middle_link_2"/>
    <child link="r_finger_middle_link_3"/>
    <hardwareInterface>EffortJointInterface</hardwareInterface>
    <axis xyz="0 0 1"/>
    <origin rpy="0 0 0" xyz="0.039 0 0"/>
    <!-- upper limit -0.0523598775598 -->
    <limit effort="100" lower="-1.2217304764" upper="1.0" velocity="100"/>
  </joint>
  <link name="r_palm">
    <visual>
      <geometry>
        <mesh filename="meshes/robotiq/visual/palm.obj"/>
      </geometry>
      <material name="green">
        <color rgba="0 1 0 1"/>
      </material>
    </visual>
    <collision>
      <origin rpy="0 0 0" xyz="0.0 -0.001 0.0"/>
      <geometry>
        <box size="0.0425 0.1048 0.1302"/>
      </geometry>
      <material name="red">
        <color rgba="1 0 0 1"/>
      </material>
      <surface>
        <friction>
          <ode>
            <mu>1.5</mu>
            <mu2>1.0</mu2>
          </ode>
        </friction>
      </surface>
    </collision>
    <inertial>
      <origin rpy="0 0 0" xyz="0 0 0"/>
      <mass value="1.72568"/>
      <inertia ixx="2.983e-03" ixy="1.075e-04" ixz="4.738e-08" iyy="3.607e-03" iyz="0.0" izz="2.840e-03"/>
    </inertial>
  </link>
  <joint name="r_palm_finger_1_joint" type="revolute">
    <parent link="r_palm"/>
    <child link="r_finger_1_link_0"/>
    <axis xyz="0 1 0"/> 
    <origin rpy="0 3.1416 -1.57" xyz="-0.0455 0.0214 0.036"/>
    <limit effort="100" lower="-0.16" upper="0.25" velocity="100"/>
  </joint>

  <joint name="r_palm_finger_2_joint" type="revolute">
    <parent link="r_palm"/>
    <child link="r_finger_2_link_0"/>
    <axis xyz="0 1 0"/>
    <origin rpy="0 3.1416 -1.57" xyz="-0.0455 0.0214 -0.036"/>
    <limit effort="100" lower="-0.25" upper="0.16" velocity="100"/>
  </joint>

  <joint name="r_palm_finger_middle_joint" type="fixed">
    <parent link="r_palm"/>
    <child link="r_finger_middle_link_0"/>
    <axis xyz="0 0 1"/>
    <origin rpy="0 0 1.57" xyz="0.0455 0.0214 0"/>
  </joint>


  
  <!--
		<include filename="${prefix}$(find robotiq_3f_gripper_visualization)/cfg/robotiq-3f-gripper_finger_articulated_macro.xacro" />
		<xacro:robotiq-3f-gripper_finger_articulated prefix=""/>
	-->



  <gazebo reference="victor_pedestal">
    <visual>
      <material>
        <diffuse>0.2 0.2 0.2 1.0</diffuse>
        <ambient>0.1 0.1 0.1 1.0</ambient>
      </material>
    </visual>
  </gazebo>
  <gazebo reference="victor_base_plate">
    <visual>
      <material>
        <diffuse>0.7 0.7 0.7 1.0</diffuse>
        <ambient>0.3 0.3 0.3 1.0</ambient>
        <specular>0.9 0.9 0.9 1.0</specular>
      </material>
    </visual>
  </gazebo>
  <gazebo reference="right_tool_joint">
    <preserveFixedJoint>true</preserveFixedJoint>
  </gazebo>
  <gazebo reference="left_tool_joint">
    <preserveFixedJoint>true</preserveFixedJoint>
  </gazebo>
  <link name="world"/>
  <joint name="world_joint" type="fixed">
    <parent link="world"/>
    <child link="victor_root"/>
    <origin rpy="0.0 0.0 0.0" xyz="0.0 0.0 0.0"/>
  </joint>
</robot>

