<?xml version="1.0"?>
<robot name="A2D">
  <link name="base_link">
    <inertial>
      <origin xyz="-0.0134486971267798 0.00152103941353612 -0.0320076754329413" rpy="0 0 0"/>
      <mass value="23.2085382238952"/>  <!-- Base mass approximately 23.2kg -->
      <inertia
        ixx="0.386955641760608" ixy="0.000135417314593726" ixz="0.00669301645720665"
        iyy="0.366800407621218" iyz="0.000105713634260505" izz="0.546852919828475"/>
    </inertial>

    <visual>
      <origin xyz="0 0 0" rpy="0 0 0"/>
      <geometry>
        <mesh filename="package://meshes/base_link.STL"/>
      </geometry>
      <material name="">
        <color rgba="0.752941176470588 0.752941176470588 0.752941176470588 1"/>  <!-- Gray -->
      </material>
    </visual>

    <collision>
      <origin xyz="0 0 0" rpy="0 0 0"/>
      <geometry>
        <mesh filename="package://meshes/base_link.STL"/>
      </geometry>
    </collision>
  </link>

  <!-- Lift mechanism link: Part that controls overall height -->
  <link name="link_up_down_body">
    <inertial>
      <origin xyz="0.0338351537064605 -0.00248044044451858 0.000838431095422365" rpy="0 0 0"/>
      <mass value="3.26275452360108"/>
      <inertia
        ixx="0.0128301877197417" ixy="8.24967996575627E-06" ixz="1.38254543337324E-05"
        iyy="0.006104110250297" iyz="-7.99392548994692E-06" izz="0.0111721084996867"/>
    </inertial>

    <visual>
      <origin xyz="0 0 0" rpy="0 0 0"/>
      <geometry>
        <mesh filename="package://meshes/link_up_down_body.STL"/>
      </geometry>
      <material name="">
        <color rgba="0.752941176470588 0.752941176470588 0.752941176470588 1"/>
      </material>
    </visual>

    <collision>
      <origin xyz="0 0 0" rpy="0 0 0"/>
      <geometry>
        <mesh filename="package://meshes/link_up_down_body.STL"/>
      </geometry>
    </collision>
  </link>

  <!-- Lift joint: Controls robot overall height, can rise 30cm -->
  <joint name="joint_lift_body" type="prismatic">
    <origin xyz="0 0 0.6485" rpy="0 0 0"/>  <!-- Starting from 34.85cm above base -->
    <parent link="base_link"/>
    <child link="link_up_down_body"/>
    <axis xyz="0 0 1"/>                      <!-- Movement along Z-axis -->
    <limit lower="0" upper="0.5" effort="1000" velocity="2.6100"/>  <!-- Lift range 0-30cm -->
  </joint>

  <!-- Body pitch link: Torso part that can tilt forward/backward -->
  <link name="link_pitch_body">
    <inertial>
      <origin xyz="0.193733558855111 -0.000484180179482319 -0.00124011422952511" rpy="0 0 0"/>
      <mass value="7.53199207979272"/>
      <inertia
        ixx="0.016546682835947" ixy="0.000274441382484697" ixz="0.00102757387076422"
        iyy="0.0445441227006132" iyz="-0.000236858278708531" izz="0.0402036337794082"/>
    </inertial>

    <visual>
      <origin xyz="0 0 0" rpy="3.14159 0 0"/>
      <geometry>
        <mesh filename="package://meshes/link_pitch_body.STL"/>
      </geometry>
      <material name="">
        <color rgba="0.752941176470588 0.752941176470588 0.752941176470588 1"/>
      </material>
    </visual>

    <collision>
      <origin xyz="0 0 0" rpy="3.14159 0 0"/>
      <geometry>
        <mesh filename="package://meshes/link_pitch_body.STL"/>
      </geometry>
    </collision>
  </link>

  <!-- Body pitch joint: Controls robot pitch, can pitch 45 degrees -->
  <joint name="joint_body_pitch" type="revolute">
    <origin xyz="0.131 0 0" rpy="1.5708 -1.5708 0"/>  <!-- From 13.1cm in front of lift mechanism -->
    <parent link="link_up_down_body"/>
    <child link="link_pitch_body"/>
    <axis xyz="0 0 -1"/>                              <!-- Rotation around negative Z-axis -->
    <limit lower="0" upper="1.047197551" effort="1000" velocity="2.6100"/>  <!-- 0-45 degree pitch -->
  </joint>

  <!-- Head yaw link: Head that can turn left/right -->
  <link name="link_yaw_head">
    <inertial>
      <origin xyz="0.0446068140025754 0.00241753143645124 0.0528373754603559" rpy="0 0 0"/>
      <mass value="0.414342871921048"/>
      <inertia
        ixx="0.000158695728344024" ixy="-1.04590928109554E-06" ixz="-6.58530903139189E-06"
        iyy="0.000117742864399469" iyz="-2.65011299996072E-06" izz="0.000170947040827065"/>
    </inertial>

    <visual>
      <origin xyz="0 0 0" rpy="0 0 3.14159"/>
      <geometry>
        <mesh filename="package://meshes/link_yaw_head.STL"/>
      </geometry>
      <material name="">
        <color rgba="0.752941176470588 0.752941176470588 0.752941176470588 1"/>
      </material>
    </visual>

    <collision>
      <origin xyz="0 0 0" rpy="0 0 3.14159"/>
      <geometry>
        <mesh filename="package://meshes/link_yaw_head.STL"/>
      </geometry>
    </collision>
  </link>

  <!-- Head yaw joint: Controls head left/right rotation, 90 degrees each side -->
  <joint name="joint_head_yaw" type="revolute">
    <origin xyz="0.441 0 0" rpy="1.5708 0 1.5708"/>  <!-- From 44.1cm in front of torso -->
    <parent link="link_pitch_body"/>
    <child link="link_yaw_head"/>
    <axis xyz="0 0 1"/>                              <!-- Rotation around Z-axis -->
    <limit lower="-1.5708" upper="1.5708" effort="50" velocity="1.0"/>  <!-- 90 degrees left and right -->
  </joint>

  <!-- Head pitch link: Part that can nod up/down -->
  <link name="link_pitch_head">
    <inertial>
      <origin xyz="0.0257009265816389 0.0316254080188787 -3.77390122592164E-05" rpy="0 0 0"/>
      <mass value="0.707063977171202"/>
      <inertia
        ixx="0.00205409595373573" ixy="0.000347730118005016" ixz="-2.13857752451204E-06"
        iyy="0.00200357281313449" iyz="5.16150600423908E-08" izz="0.00184999028444405"/>
    </inertial>

    <visual>
      <origin xyz="0 0 0" rpy="0 3.14159 0"/>
      <geometry>
        <mesh filename="package://meshes/link_pitch_head.STL"/>
      </geometry>
      <material name="">
        <color rgba="0.752941176470588 0.752941176470588 0.752941176470588 1"/>
      </material>
    </visual>

    <collision>
      <origin xyz="0 0 0" rpy="0 3.14159 0"/>
      <geometry>
        <mesh filename="package://meshes/link_pitch_head.STL"/>
      </geometry>
    </collision>
  </link>

  <!-- Head pitch joint: Controls head up/down nodding, 45 degrees each side -->
  <joint name="joint_head_pitch" type="revolute">
    <origin xyz="-0.050238 0 0.060065" rpy="1.5708 0 0"/>
    <parent link="link_yaw_head"/>
    <child link="link_pitch_head"/>
    <axis xyz="0 0 1"/>
    <limit lower="-0.785398" upper="0.785398" effort="50" velocity="1.0"/>  <!-- 45 degrees up and down -->
  </joint>

  <!-- Robot arm link: Robot arm fixed on torso -->
  <link name="link_arm"/>

  <!-- Robot arm mounting joint: Fixes robot arm to torso -->
  <joint name="joint_arm_mount" type="fixed">
    <origin xyz="0.305 0 0" rpy="-1.5708 0 -1.5708"/>  <!-- Fixed 30.5cm in front of torso -->
    <parent link="link_pitch_body"/>
    <child link="link_arm"/>
    <axis xyz="0 0 1"/>
  </joint>

  <!-- Left arm mounting joint: Fixes left arm to robot torso -->
  <joint name="joint_left_arm_mount" type="fixed">
    <origin xyz="0 0.025 0" rpy="-1.5708 0 0"/>  <!-- Offset 2.5cm to the left from link_arm -->
    <parent link="link_arm"/>
    <child link="base_link_l"/>
  </joint>

  <!-- Right arm mounting joint: Fixes right arm to robot torso -->
  <joint name="joint_right_arm_mount" type="fixed">
    <origin xyz="0 -0.025 0" rpy="1.5708 -3.14159 0"/>  <!-- Offset 2.5cm to the right from link_arm -->
    <parent link="link_arm"/>
    <child link="base_link_r"/>
  </joint>

  <!-- Left arm的所有link和joint定义 -->
  <link
    name="base_link_l">
    <inertial>
      <origin
        xyz="0.00020641 -0.00057488 0.034396"
        rpy="0 0 0" />
      <mass
        value="0.37595" />
      <inertia
        ixx="0.00024335"
        ixy="1.2188E-06"
        ixz="2.4281E-06"
        iyy="0.00024039"
        iyz="-6.6932E-06"
        izz="0.00032195" />
    </inertial>
    <visual>
      <origin
        xyz="0 0 0"
        rpy="0 0 0" />
      <geometry>
        <mesh
          filename="package://meshes/base_link_l.STL" />
      </geometry>
      <material
        name="">
        <color
          rgba="0.75294 0.75294 0.75294 1" />
      </material>
    </visual>
    <collision>
      <origin
        xyz="0 0 0"
        rpy="0 0 0" />
      <geometry>
        <mesh
          filename="package://meshes/base_link_l.STL" />
      </geometry>
    </collision>
  </link>
  <link
    name="Link1_l">
    <inertial>
      <origin
        xyz="-0.0014596 0.00049476 0.017089"
        rpy="0 0 0" />
      <mass
        value="0.43694" />
      <inertia
        ixx="0.00061894"
        ixy="-6.6923E-06"
        ixz="3.492E-06"
        iyy="0.00054909"
        iyz="1.2223E-06"
        izz="0.00026663" />
    </inertial>
    <visual>
      <origin
        xyz="0 0 0"
        rpy="0 0 0" />
      <geometry>
        <mesh
          filename="package://meshes/Link1_l.STL" />
      </geometry>
      <material
        name="">
        <color
          rgba="0.75294 0.75294 0.75294 1" />
      </material>
    </visual>
    <collision>
      <origin
        xyz="0 0 0"
        rpy="0 0 0" />
      <geometry>
        <mesh
          filename="package://meshes/Link1_l.STL" />
      </geometry>
    </collision>
  </link>
  <joint
    name="left_arm_joint1"
    type="revolute">
    <origin
      xyz="0 0 0.188"
      rpy="3.1416 0 0" />
    <parent
      link="base_link_l" />
    <child
      link="Link1_l" />
    <axis
      xyz="0 0 -1" />
    <limit
      lower="-3.14"
      upper="3.14"
      effort="60"
      velocity="3.14" />
  </joint>
  <link
    name="Link2_l">
    <inertial>
      <origin
        xyz="-0.00043013 0.088101 -0.0065021"
        rpy="0 0 0" />
      <mass
        value="0.31992" />
      <inertia
        ixx="0.00033101"
        ixy="-4.1377E-06"
        ixz="9.5154E-07"
        iyy="0.00022098"
        iyz="-4.8041E-05"
        izz="0.00031472" />
    </inertial>
    <visual>
      <origin
        xyz="0 0 0"
        rpy="0 0 0" />
      <geometry>
        <mesh
          filename="package://meshes/Link2_l.STL" />
      </geometry>
      <material
        name="">
        <color
          rgba="0.75294 0.75294 0.75294 1" />
      </material>
    </visual>
    <collision>
      <origin
        xyz="0 0 0"
        rpy="0 0 0" />
      <geometry>
        <mesh
          filename="package://meshes/Link2_l.STL" />
      </geometry>
    </collision>
  </link>
  <joint
    name="left_arm_joint2"
    type="revolute">
    <origin
      xyz="0 0 0"
      rpy="-1.5708 0 -1.5708" />
    <parent
      link="Link1_l" />
    <child
      link="Link2_l" />
    <axis
      xyz="0 0 -1" />
    <limit
      lower="-2.35619449"
      upper="2.35619449"
      effort="60"
      velocity="3.14" />
  </joint>
  <link
    name="Link3_l">
    <inertial>
      <origin
        xyz="0.00022593 0.0010417 0.034985"
        rpy="0 0 0" />
      <mass
        value="0.35545" />
      <inertia
        ixx="0.00081056"
        ixy="-2.4265E-06"
        ixz="9.353E-07"
        iyy="0.00083336"
        iyz="3.8681E-06"
        izz="0.00017128" />
    </inertial>
    <visual>
      <origin
        xyz="0 0 0"
        rpy="0 0 0" />
      <geometry>
        <mesh
          filename="package://meshes/Link3_l.STL" />
      </geometry>
      <material
        name="">
        <color
          rgba="0.75294 0.75294 0.75294 1" />
      </material>
    </visual>
    <collision>
      <origin
        xyz="0 0 0"
        rpy="0 0 0" />
      <geometry>
        <mesh
          filename="package://meshes/Link3_l.STL" />
      </geometry>
    </collision>
  </link>
  <joint
    name="left_arm_joint3"
    type="revolute">
    <origin
      xyz="0 0.305 0"
      rpy="1.5708 1.5708 0" />
    <parent
      link="Link2_l" />
    <child
      link="Link3_l" />
    <axis
      xyz="0 0 -1" />
    <limit
      lower="-3.14"
      upper="3.14"
      effort="60"
      velocity="3.14" />
  </joint>
  <link
    name="Link4_l">
    <inertial>
      <origin
        xyz="2.1713E-06 0.071943 -0.0054645"
        rpy="0 0 0" />
      <mass
        value="0.1848" />
      <inertia
        ixx="0.00014344"
        ixy="-1.7659E-08"
        ixz="-4.6234E-09"
        iyy="9.0443E-05"
        iyz="-2.1918E-05"
        izz="0.00013811" />
    </inertial>
    <visual>
      <origin
        xyz="0 0 0"
        rpy="0 0 0" />
      <geometry>
        <mesh
          filename="package://meshes/Link4_l.STL" />
      </geometry>
      <material
        name="">
        <color
          rgba="0.75294 0.75294 0.75294 1" />
      </material>
    </visual>
    <collision>
      <origin
        xyz="0 0 0"
        rpy="0 0 0" />
      <geometry>
        <mesh
          filename="package://meshes/Link4_l.STL" />
      </geometry>
    </collision>
  </link>
  <joint
    name="left_arm_joint4"
    type="revolute">
    <origin
      xyz="0 0 0"
      rpy="-1.5708 0 0" />
    <parent
      link="Link3_l" />
    <child
      link="Link4_l" />
    <axis
      xyz="0 0 -1" />
    <limit
      lower="-2.35619449"
      upper="2.35619449"
      effort="60"
      velocity="3.14" />
  </joint>
  <link
    name="Link5_l">
    <inertial>
      <origin
        xyz="-7.6715E-07 -6.7798E-05 -0.012879"
        rpy="0 0 0" />
      <mass
        value="0.1775" />
      <inertia
        ixx="0.00012838"
        ixy="1.6718E-09"
        ixz="6.959E-09"
        iyy="0.00013741"
        iyz="3.1692E-07"
        izz="6.2102E-05" />
    </inertial>
    <visual>
      <origin
        xyz="0 0 0"
        rpy="0 0 0" />
      <geometry>
        <mesh
          filename="package://meshes/Link5_l.STL" />
      </geometry>
      <material
        name="">
        <color
          rgba="0.75294 0.75294 0.75294 1" />
      </material>
    </visual>
    <collision>
      <origin
        xyz="0 0 0"
        rpy="0 0 0" />
      <geometry>
        <mesh
          filename="package://meshes/Link5_l.STL" />
      </geometry>
    </collision>
  </link>
  <joint
    name="left_arm_joint5"
    type="revolute">
    <origin
      xyz="0 0.1975 0"
      rpy="1.5708 0 -3.1416" />
    <parent
      link="Link4_l" />
    <child
      link="Link5_l" />
    <axis
      xyz="0 0 1" />
    <limit
      lower="-3.14"
      upper="3.14"
      effort="30"
      velocity="3.14" />
  </joint>
  <link
    name="Link6_l">
    <inertial>
      <origin
        xyz="2.2696E-06 -0.10227 -0.0029117"
        rpy="0 0 0" />
      <mass
        value="0.17825" />
      <inertia
        ixx="0.00013761"
        ixy="5.1473E-09"
        ixz="6.9927E-09"
        iyy="8.0777E-05"
        iyz="2.0192E-05"
        izz="0.00012814" />
    </inertial>
    <visual>
      <origin
        xyz="0 0 0"
        rpy="0 0 0" />
      <geometry>
        <mesh
          filename="package://meshes/Link6_l.STL" />
      </geometry>
      <material
        name="">
        <color
          rgba="0.75294 0.75294 0.75294 1" />
      </material>
    </visual>
    <collision>
      <origin
        xyz="0 0 0"
        rpy="0 0 0" />
      <geometry>
        <mesh
          filename="package://meshes/Link6_l.STL" />
      </geometry>
    </collision>
  </link>
  <joint
    name="left_arm_joint6"
    type="revolute">
    <origin
      xyz="0 0 0"
      rpy="-1.5708 0 3.1416" />
    <parent
      link="Link5_l" />
    <child
      link="Link6_l" />
    <axis
      xyz="0 0 -1" />
    <limit
      lower="-2.35619449"
      upper="2.35619449"
      effort="30"
      velocity="3.14" />
  </joint>
  <link
    name="Link7_l">
    <inertial>
      <origin
        xyz="-0.00025629 9.064E-06 -0.017205"
        rpy="0 0 0" />
      <mass
        value="0.06158" />
      <inertia
        ixx="1.8213E-05"
        ixy="-8.6954E-08"
        ixz="1.0858E-07"
        iyy="1.8374E-05"
        iyz="3.2442E-08"
        izz="2.8547E-05" />
    </inertial>
    <visual>
      <origin
        xyz="0 0 0"
        rpy="0 0 0" />
      <geometry>
        <mesh
          filename="package://meshes/Link7_l.STL" />
      </geometry>
      <material
        name="">
        <color
          rgba="0.75294 0.75294 0.75294 1" />
      </material>
    </visual>
    <collision>
      <origin
        xyz="0 0 0"
        rpy="0 0 0" />
      <geometry>
        <mesh
          filename="package://meshes/Link7_l.STL" />
      </geometry>
    </collision>
  </link>
  <joint
    name="left_arm_joint7"
    type="revolute">
    <origin
      xyz="0 -0.181 0"
      rpy="-1.5708 0 -3.1416" />
    <parent
      link="Link6_l" />
    <child
      link="Link7_l" />
    <axis
      xyz="0 0 1" />
    <limit
      lower="-6.28"
      upper="6.28"
      effort="30"
      velocity="3.14" />
  </joint>

  <joint
    name="Joint_hand_l"
    type="fixed">
    <origin
      xyz="0 0 0"
      rpy="0 0 0" />
    <parent
      link="Link7_l" />
    <child
      link="left_base_link" />
    <axis
      xyz="0 0 0" />
  </joint>

  <!-- 右臂的所有link和joint定义 -->
  <link
    name="base_link_r">
    <inertial>
      <origin
        xyz="0.00020641 -0.00057488 0.034396"
        rpy="0 0 0" />
      <mass
        value="0.37595" />
      <inertia
        ixx="0.00024335"
        ixy="1.2188E-06"
        ixz="2.4281E-06"
        iyy="0.00024039"
        iyz="-6.6932E-06"
        izz="0.00032195" />
    </inertial>
    <visual>
      <origin
        xyz="0 0 0"
        rpy="0 0 0" />
      <geometry>
        <mesh
          filename="package://meshes/base_link_r.STL" />
      </geometry>
      <material
        name="">
        <color
          rgba="0.75294 0.75294 0.75294 1" />
      </material>
    </visual>
    <collision>
      <origin
        xyz="0 0 0"
        rpy="0 0 0" />
      <geometry>
        <mesh
          filename="package://meshes/base_link_r.STL" />
      </geometry>
    </collision>
  </link>
  <link
    name="Link1_r">
    <inertial>
      <origin
        xyz="0.0013193 0.00016098 0.018211"
        rpy="0 0 0" />
      <mass
        value="0.48414" />
      <inertia
        ixx="0.000726"
        ixy="2.4165E-06"
        ixz="-7.7713E-06"
        iyy="0.00066689"
        iyz="1.2143E-06"
        izz="0.00028434" />
    </inertial>
    <visual>
      <origin
        xyz="0 0 0"
        rpy="0 0 0" />
      <geometry>
        <mesh
          filename="package://meshes/Link1_r.STL" />
      </geometry>
      <material
        name="">
        <color
          rgba="0.75294 0.75294 0.75294 1" />
      </material>
    </visual>
    <collision>
      <origin
        xyz="0 0 0"
        rpy="0 0 0" />
      <geometry>
        <mesh
          filename="package://meshes/Link1_r.STL" />
      </geometry>
    </collision>
  </link>
  <joint
    name="right_arm_joint1"
    type="revolute">
    <origin
      xyz="0 0 0.188"
      rpy="-3.1416 0 0" />
    <parent
      link="base_link_r" />
    <child
      link="Link1_r" />
    <axis
      xyz="0 0 -1" />
    <limit
      lower="-3.14"
      upper="3.14"
      effort="60"
      velocity="3.14" />
  </joint>
  <link
    name="Link2_r">
    <inertial>
      <origin
        xyz="0.00012037 -0.088102 -0.0062668"
        rpy="0 0 0" />
      <mass
        value="0.31993" />
      <inertia
        ixx="0.00033251"
        ixy="-1.2043E-06"
        ixz="-5.3938E-07"
        iyy="0.00022098"
        iyz="4.5816E-05"
        izz="0.00031325" />
    </inertial>
    <visual>
      <origin
        xyz="0 0 0"
        rpy="0 0 0" />
      <geometry>
        <mesh
          filename="package://meshes/Link2_r.STL" />
      </geometry>
      <material
        name="">
        <color
          rgba="0.75294 0.75294 0.75294 1" />
      </material>
    </visual>
    <collision>
      <origin
        xyz="0 0 0"
        rpy="0 0 0" />
      <geometry>
        <mesh
          filename="package://meshes/Link2_r.STL" />
      </geometry>
    </collision>
  </link>
  <joint
    name="right_arm_joint2"
    type="revolute">
    <origin
      xyz="0 0 0"
      rpy="1.5708 0 -1.5708" />
    <parent
      link="Link1_r" />
    <child
      link="Link2_r" />
    <axis
      xyz="0 0 -1" />
    <limit
      lower="-2.35619449"
      upper="2.35619449"
      effort="60"
      velocity="3.14" />
  </joint>
  <link
    name="Link3_r">
    <inertial>
      <origin
        xyz="-3.7545E-06 -0.00012549 -0.035846"
        rpy="0 0 0" />
      <mass
        value="0.34932" />
      <inertia
        ixx="0.00084957"
        ixy="-6.2047E-11"
        ixz="1.3496E-08"
        iyy="0.00082652"
        iyz="2.8949E-07"
        izz="0.00021145" />
    </inertial>
    <visual>
      <origin
        xyz="0 0 0"
        rpy="0 0 0" />
      <geometry>
        <mesh
          filename="package://meshes/Link3_r.STL" />
      </geometry>
      <material
        name="">
        <color
          rgba="0.75294 0.75294 0.75294 1" />
      </material>
    </visual>
    <collision>
      <origin
        xyz="0 0 0"
        rpy="0 0 0" />
      <geometry>
        <mesh
          filename="package://meshes/Link3_r.STL" />
      </geometry>
    </collision>
  </link>
  <joint
    name="right_arm_joint3"
    type="revolute">
    <origin
      xyz="0 -0.305 0"
      rpy="1.5708 1.5708 0" />
    <parent
      link="Link2_r" />
    <child
      link="Link3_r" />
    <axis
      xyz="0 0 1" />
    <limit
      lower="-3.14"
      upper="3.14"
      effort="60"
      velocity="3.14" />
  </joint>
  <link
    name="Link4_r">
    <inertial>
      <origin
        xyz="1.9102E-06 0.071943 -0.0054646"
        rpy="0 0 0" />
      <mass
        value="0.1848" />
      <inertia
        ixx="0.00014343"
        ixy="-1.7316E-08"
        ixz="-3.4456E-09"
        iyy="9.0442E-05"
        iyz="-2.1917E-05"
        izz="0.0001381" />
    </inertial>
    <visual>
      <origin
        xyz="0 0 0"
        rpy="0 0 0" />
      <geometry>
        <mesh
          filename="package://meshes/Link4_r.STL" />
      </geometry>
      <material
        name="">
        <color
          rgba="0.75294 0.75294 0.75294 1" />
      </material>
    </visual>
    <collision>
      <origin
        xyz="0 0 0"
        rpy="0 0 0" />
      <geometry>
        <mesh
          filename="package://meshes/Link4_r.STL" />
      </geometry>
    </collision>
  </link>
  <joint
    name="right_arm_joint4"
    type="revolute">
    <origin
      xyz="0 0 0"
      rpy="1.5708 0 -3.1416" />
    <parent
      link="Link3_r" />
    <child
      link="Link4_r" />
    <axis
      xyz="0 0 -1" />
    <limit
      lower="-2.35619449"
      upper="2.35619449"
      effort="60"
      velocity="3.14" />
  </joint>
  <link
    name="Link5_r">
    <inertial>
      <origin
        xyz="4.0146E-06 -6.7798E-05 -0.012877"
        rpy="0 0 0" />
      <mass
        value="0.1775" />
      <inertia
        ixx="0.00012838"
        ixy="-3.4874E-09"
        ixz="6.9591E-09"
        iyy="0.00013741"
        iyz="3.1477E-07"
        izz="6.2102E-05" />
    </inertial>
    <visual>
      <origin
        xyz="0 0 0"
        rpy="0 0 0" />
      <geometry>
        <mesh
          filename="package://meshes/Link5_r.STL" />
      </geometry>
      <material
        name="">
        <color
          rgba="0.75294 0.75294 0.75294 1" />
      </material>
    </visual>
    <collision>
      <origin
        xyz="0 0 0"
        rpy="0 0 0" />
      <geometry>
        <mesh
          filename="package://meshes/Link5_r.STL" />
      </geometry>
    </collision>
  </link>
  <joint
    name="right_arm_joint5"
    type="revolute">
    <origin
      xyz="0 0.1975 0"
      rpy="1.5708 0 -3.1416" />
    <parent
      link="Link4_r" />
    <child
      link="Link5_r" />
    <axis
      xyz="0 0 1" />
    <limit
      lower="-3.14"
      upper="3.14"
      effort="30"
      velocity="3.14" />
  </joint>
  <link
    name="Link6_r">
    <inertial>
      <origin
        xyz="-2.4946E-06 -0.10227 -0.0029098"
        rpy="0 0 0" />
      <mass
        value="0.17825" />
      <inertia
        ixx="0.00013761"
        ixy="-2.7933E-11"
        ixz="6.9889E-09"
        iyy="8.0777E-05"
        iyz="2.0194E-05"
        izz="0.00012814" />
    </inertial>
    <visual>
      <origin
        xyz="0 0 0"
        rpy="0 0 0" />
      <geometry>
        <mesh
          filename="package://meshes/Link6_r.STL" />
      </geometry>
      <material
        name="">
        <color
          rgba="0.75294 0.75294 0.75294 1" />
      </material>
    </visual>
    <collision>
      <origin
        xyz="0 0 0"
        rpy="0 0 0" />
      <geometry>
        <mesh
          filename="package://meshes/Link6_r.STL" />
      </geometry>
    </collision>
  </link>
  <joint
    name="right_arm_joint6"
    type="revolute">
    <origin
      xyz="0 0 0"
      rpy="-1.5708 0 3.1416" />
    <parent
      link="Link5_r" />
    <child
      link="Link6_r" />
    <axis
      xyz="0 0 -1" />
    <limit
      lower="-2.35619449"
      upper="2.35619449"
      effort="30"
      velocity="3.14" />
  </joint>
  <link
    name="Link7_r">
    <inertial>
      <origin
        xyz="0.0002265 0.00012031 -0.017205"
        rpy="0 0 0" />
      <mass
        value="0.06158" />
      <inertia
        ixx="1.8328E-05"
        ixy="-1.1354E-07"
        ixz="-7.7825E-08"
        iyy="1.8259E-05"
        iyz="-8.2338E-08"
        izz="2.8547E-05" />
    </inertial>
    <visual>
      <origin
        xyz="0 0 0"
        rpy="0 0 0" />
      <geometry>
        <mesh
          filename="package://meshes/Link7_r.STL" />
      </geometry>
      <material
        name="">
        <color
          rgba="0.75294 0.75294 0.75294 1" />
      </material>
    </visual>
    <collision>
      <origin
        xyz="0 0 0"
        rpy="0 0 0" />
      <geometry>
        <mesh
          filename="package://meshes/Link7_r.STL" />
      </geometry>
    </collision>
  </link>


  <joint
    name="right_arm_joint7"
    type="revolute">
    <origin
      xyz="0 -0.181 0"
      rpy="-1.5708 0 3.1416" />
    <parent
      link="Link6_r" />
    <child
      link="Link7_r" />
    <axis
      xyz="0 0 1" />
    <limit
      lower="-3.14"
      upper="3.14"
      effort="30"
      velocity="3.14" />
  </joint>

  <joint
    name="Joint_hand_r"
    type="fixed">
    <origin
      xyz="0 0 0"
      rpy="0 0 0" />
    <parent
      link="Link7_r" />
    <child
      link="right_base_link" />
    <axis
      xyz="0 0 0" />
  </joint>
  <link
    name="right_base_link">
    <inertial>
      <origin
        xyz="1.23989288637867E-06 3.27564415436087E-07 0.0536186975993762"
        rpy="0 0 0" />
      <mass
        value="0.443105756928829" />
      <inertia
        ixx="0.00064200574020552"
        ixy="-1.51180224931458E-07"
        ixz="7.24174172220287E-09"
        iyy="0.00066998312004943"
        iyz="2.73584170951165E-09"
        izz="0.000278949393571484" />
    </inertial>
    <visual>
      <origin
        xyz="0 0 0"
        rpy="0 0 0" />
      <geometry>
        <mesh
          filename="package://meshes/crt_120s/base_link.STL" />
      </geometry>
      <material
        name="">
        <color
          rgba="0.792156862745098 0.819607843137255 0.933333333333333 1" />
      </material>
    </visual>
    <collision>
      <origin
        xyz="0 0 0"
        rpy="0 0 0" />
      <geometry>
        <mesh
          filename="package://meshes/crt_120s/base_link.STL" />
      </geometry>
    </collision>
  </link>

  <link
    name="left_base_link">
    <inertial>
      <origin
        xyz="1.23989288637867E-06 3.27564415436087E-07 0.0536186975993762"
        rpy="0 0 0" />
      <mass
        value="0.443105756928829" />
      <inertia
        ixx="0.00064200574020552"
        ixy="-1.51180224931458E-07"
        ixz="7.24174172220287E-09"
        iyy="0.00066998312004943"
        iyz="2.73584170951165E-09"
        izz="0.000278949393571484" />
    </inertial>
    <visual>
      <origin
        xyz="0 0 0"
        rpy="0 0 0" />
      <geometry>
        <mesh
          filename="package://meshes/crt_120s/base_link.STL" />
      </geometry>
      <material
        name="">
        <color
          rgba="0.792156862745098 0.819607843137255 0.933333333333333 1" />
      </material>
    </visual>
    <collision>
      <origin
        xyz="0 0 0"
        rpy="0 0 0" />
      <geometry>
        <mesh
          filename="package://meshes/crt_120s/base_link.STL" />
      </geometry>
    </collision>
  </link>



  <link
      name="gripper_center">
  </link>
  <joint name="gripper_center_joint" type="fixed">
      <!-- add pitch=90, to make the gripper direction from +Z to +X -->
      <origin rpy="0 -1.57079632679 -1.57079632679" xyz="0.0 0.0 0.23"/>
      <parent link="left_base_link"/>
      <child link="gripper_center"/>
  </joint>

  <link
      name="right_gripper_center">
  </link>

  <joint name="right_gripper_center_joint" type="fixed">
      <origin rpy="0 0 -1.57079632679" xyz="0.0 0.0 0.227"/>
      <parent link="right_base_link"/>
      <child link="right_gripper_center"/>
  </joint>


</robot>
