<?xml version="1.0" ?>
<!-- =================================================================================== -->
<!-- |    This document was autogenerated by xacro from galbot_one_charlie.xacro       | -->
<!-- |    EDITING THIS FILE BY HAND IS NOT RECOMMENDED                                 | -->
<!-- =================================================================================== -->
<!--
#####################################################################################
#
# Copyright (c) 2023-2024 Galbot, Inc. All rights Reserved.
#
# This software contains confidential and proprietary information of Galbot, Inc.
# ("Confidential Information"). You shall not disclose such Confidential Information
# and shall use it only in accordance with the terms of the license agreement you
# entered into with Galbot, Inc.
#
# UNAUTHORIZED COPYING, USE, OR DISTRIBUTION OF THIS SOFTWARE, OR ANY PORTION OR
# DERIVATIVE THEREOF, IS STRICTLY PROHIBITED. IF YOU HAVE RECEIVED THIS SOFTWARE IN
# ERROR, PLEASE NOTIFY GALBOT, INC. IMMEDIATELY AND DELETE IT FROM YOUR SYSTEM.
#
#####################################################################################
#
# Description: URDF file for Galbot One Charlie.
# Author: Herman Ye@Galbot, Yuhao Zeng@Galbot
#
#####################################################################################
-->
<robot name="galbot_one_charlie">
  <!-- ROBOT -->
  <!-- Robot Base Link -->
  <link name="base_link">
    </link>
  <joint name="omni_chassis_joint" type="fixed">
    <origin rpy="0 0 0" xyz="0 0 0"/>
    <parent link="base_link"/>
    <child link="omni_chassis_base_link"/>
  </joint>
  <link name="omni_chassis_base_link">
    <inertial>
      <origin rpy="0 0 0" xyz="0.00310 0.00022 0.09001"/>
      <mass value="25.85"/>
      <inertia ixx="1.12288" ixy="0.00076" ixz="0.02446" iyy="1.15522" iyz="0.00086" izz="1.58321"/>
    </inertial>
    <visual>
      <origin rpy="0 0 0" xyz="0 0 0"/>
      <geometry>
        <mesh filename="package://galbot_one_charlie_description/meshes/chassis/omni_chassis_base_link.obj"/>
      </geometry>
    </visual>
    <collision>
      <origin rpy="0 0 0" xyz="0 0 0"/>
      <geometry>
        <mesh filename="package://galbot_one_charlie_description/meshes/chassis/omni_chassis_base_link.stl"/>
      </geometry>
    </collision>
  </link>
  <link name="omni_chassis_lidar_sim_view_frame">
    <inertial>
      <origin rpy="0 0 0" xyz="0 0 0"/>
      <mass value="0"/>
      <inertia ixx="0" ixy="0" ixz="0" iyy="0" iyz="0" izz="0"/>
    </inertial>
  </link>
  <joint name="omni_chassis_lidar_sim_view_joint" type="fixed">
    <origin rpy="0 0 0" xyz="0.222 0 0.2387"/>
    <parent link="omni_chassis_base_link"/>
    <child link="omni_chassis_lidar_sim_view_frame"/>
    <axis xyz="0 0 0"/>
  </joint>
  <link name="omni_chassis_ultrasonic_sim_view_frame1">
    <inertial>
      <origin rpy="0 0 0" xyz="0 0 0"/>
      <mass value="0"/>
      <inertia ixx="0" ixy="0" ixz="0" iyy="0" iyz="0" izz="0"/>
    </inertial>
  </link>
  <joint name="omni_chassis_ultrasonic_sim_view_joint1" type="fixed">
    <origin rpy="0 0 0.39269908169872414" xyz="0.27537 0.11642 0.145"/>
    <parent link="omni_chassis_base_link"/>
    <child link="omni_chassis_ultrasonic_sim_view_frame1"/>
    <axis xyz="0 0 0"/>
  </joint>
  <link name="omni_chassis_ultrasonic_sim_view_frame2">
    <inertial>
      <origin rpy="0 0 0" xyz="0 0 0"/>
      <mass value="0"/>
      <inertia ixx="0" ixy="0" ixz="0" iyy="0" iyz="0" izz="0"/>
    </inertial>
  </link>
  <joint name="omni_chassis_ultrasonic_sim_view_joint2" type="fixed">
    <origin rpy="0 0 1.1780972450961724" xyz="0.11642 0.27537 0.145"/>
    <parent link="omni_chassis_base_link"/>
    <child link="omni_chassis_ultrasonic_sim_view_frame2"/>
    <axis xyz="0 0 0"/>
  </joint>
  <link name="omni_chassis_ultrasonic_sim_view_frame3">
    <inertial>
      <origin rpy="0 0 0" xyz="0 0 0"/>
      <mass value="0"/>
      <inertia ixx="0" ixy="0" ixz="0" iyy="0" iyz="0" izz="0"/>
    </inertial>
  </link>
  <joint name="omni_chassis_ultrasonic_sim_view_joint3" type="fixed">
    <origin rpy="0 0 1.9634954084936207" xyz="-0.11642 0.27537 0.145"/>
    <parent link="omni_chassis_base_link"/>
    <child link="omni_chassis_ultrasonic_sim_view_frame3"/>
    <axis xyz="0 0 0"/>
  </joint>
  <link name="omni_chassis_ultrasonic_sim_view_frame4">
    <inertial>
      <origin rpy="0 0 0" xyz="0 0 0"/>
      <mass value="0"/>
      <inertia ixx="0" ixy="0" ixz="0" iyy="0" iyz="0" izz="0"/>
    </inertial>
  </link>
  <joint name="omni_chassis_ultrasonic_sim_view_joint4" type="fixed">
    <origin rpy="0 0 2.748893571891069" xyz="-0.27537 0.11642 0.145"/>
    <parent link="omni_chassis_base_link"/>
    <child link="omni_chassis_ultrasonic_sim_view_frame4"/>
    <axis xyz="0 0 0"/>
  </joint>
  <link name="omni_chassis_ultrasonic_sim_view_frame5">
    <inertial>
      <origin rpy="0 0 0" xyz="0 0 0"/>
      <mass value="0"/>
      <inertia ixx="0" ixy="0" ixz="0" iyy="0" iyz="0" izz="0"/>
    </inertial>
  </link>
  <joint name="omni_chassis_ultrasonic_sim_view_joint5" type="fixed">
    <origin rpy="0 0 3.5342917352885173" xyz="-0.27537 -0.11642 0.145"/>
    <parent link="omni_chassis_base_link"/>
    <child link="omni_chassis_ultrasonic_sim_view_frame5"/>
    <axis xyz="0 0 0"/>
  </joint>
  <link name="omni_chassis_ultrasonic_sim_view_frame6">
    <inertial>
      <origin rpy="0 0 0" xyz="0 0 0"/>
      <mass value="0"/>
      <inertia ixx="0" ixy="0" ixz="0" iyy="0" iyz="0" izz="0"/>
    </inertial>
  </link>
  <joint name="omni_chassis_ultrasonic_sim_view_joint6" type="fixed">
    <origin rpy="0 0 4.319689898685965" xyz="-0.11642 -0.27537 0.145"/>
    <parent link="omni_chassis_base_link"/>
    <child link="omni_chassis_ultrasonic_sim_view_frame6"/>
    <axis xyz="0 0 0"/>
  </joint>
  <link name="omni_chassis_ultrasonic_sim_view_frame7">
    <inertial>
      <origin rpy="0 0 0" xyz="0 0 0"/>
      <mass value="0"/>
      <inertia ixx="0" ixy="0" ixz="0" iyy="0" iyz="0" izz="0"/>
    </inertial>
  </link>
  <joint name="omni_chassis_ultrasonic_sim_view_joint7" type="fixed">
    <origin rpy="0 0 5.105088062083414" xyz="0.11642 -0.27537 0.145"/>
    <parent link="omni_chassis_base_link"/>
    <child link="omni_chassis_ultrasonic_sim_view_frame7"/>
    <axis xyz="0 0 0"/>
  </joint>
  <link name="omni_chassis_ultrasonic_sim_view_frame8">
    <inertial>
      <origin rpy="0 0 0" xyz="0 0 0"/>
      <mass value="0"/>
      <inertia ixx="0" ixy="0" ixz="0" iyy="0" iyz="0" izz="0"/>
    </inertial>
  </link>
  <joint name="omni_chassis_ultrasonic_sim_view_joint8" type="fixed">
    <origin rpy="0 0 5.890486225480862" xyz="0.27537 -0.11642 0.145"/>
    <parent link="omni_chassis_base_link"/>
    <child link="omni_chassis_ultrasonic_sim_view_frame8"/>
    <axis xyz="0 0 0"/>
  </joint>
  <link name="omni_chassis_leg_mount_link">
    <inertial>
      <origin rpy="0 0 0" xyz="0 0 0"/>
      <mass value="0"/>
      <inertia ixx="0" ixy="0" ixz="0" iyy="0" iyz="0" izz="0"/>
    </inertial>
  </link>
  <joint name="omni_chassis_leg_mount_joint" type="fixed">
    <origin rpy="0 0 0" xyz="0.134 0 0.13"/>
    <parent link="omni_chassis_base_link"/>
    <child link="omni_chassis_leg_mount_link"/>
    <axis xyz="0 0 0"/>
  </joint>
  <joint name="leg_joint" type="fixed">
    <origin rpy="0 0 0" xyz="0 0 0"/>
    <parent link="omni_chassis_leg_mount_link"/>
    <child link="leg_base_link"/>
  </joint>
  <link name="leg_base_link">
    <inertial>
      <origin rpy="0 0 0" xyz="0.00138 -0.01502 -0.05360"/>
      <mass value="1.98"/>
      <inertia ixx="0.01545" ixy="0.00015" ixz="-0.00028" iyy="0.01172" iyz="-0.00071" izz="0.00904"/>
    </inertial>
  </link>
  <link name="leg_link1">
    <inertial>
      <origin rpy="0 0 0" xyz="0.23126 0.00187 -0.01166"/>
      <mass value="13.38"/>
      <inertia ixx="0.05540" ixy="0.00267" ixz="-0.03511" iyy="1.17040" iyz="-0.00012" izz="1.15967"/>
    </inertial>
    <visual>
      <origin rpy="0 0 0" xyz="0 0 0"/>
      <geometry>
        <mesh filename="package://galbot_one_charlie_description/meshes/leg/leg_link1.obj"/>
      </geometry>
    </visual>
    <collision>
      <origin rpy="0 0 0" xyz="0 0 0"/>
      <geometry>
        <mesh filename="package://galbot_one_charlie_description/meshes/leg/leg_link1.stl"/>
      </geometry>
    </collision>
  </link>
  <joint name="leg_joint1" type="revolute">
    <origin rpy="-1.5707963267948966 -2.756573021 0" xyz="0 0 0"/>
    <parent link="leg_base_link"/>
    <child link="leg_link1"/>
    <axis xyz="0 0 1"/>
    <limit effort="507" lower="0" upper="0.994837674" velocity="1"/>
  </joint>
  <link name="leg_link2">
    <inertial>
      <origin rpy="0 0 0" xyz="0.18340 0.00001 0.01143"/>
      <mass value="4.72"/>
      <inertia ixx="0.04727" ixy="0.00001" ixz="0.01147" iyy="0.29026" iyz="0.00001" izz="0.25782"/>
    </inertial>
    <visual>
      <origin rpy="0 0 0" xyz="0 0 0"/>
      <geometry>
        <mesh filename="package://galbot_one_charlie_description/meshes/leg/leg_link2.obj"/>
      </geometry>
    </visual>
    <collision>
      <origin rpy="0 0 0" xyz="0 0 0"/>
      <geometry>
        <mesh filename="package://galbot_one_charlie_description/meshes/leg/leg_link2.stl"/>
      </geometry>
    </collision>
  </link>
  <joint name="leg_joint2" type="revolute">
    <origin rpy="-3.141592653589793 0 2.756573021" xyz="0.45 0 0"/>
    <parent link="leg_link1"/>
    <child link="leg_link2"/>
    <axis xyz="0 0 1"/>
    <limit effort="507" lower="0" upper="3.05" velocity="1"/>
  </joint>
  <link name="leg_link3">
    <inertial>
      <origin rpy="0 0 0" xyz="0.00004 0.03287 -0.00556"/>
      <mass value="6.04"/>
      <inertia ixx="0.02981" ixy="0.00001" ixz="-0.00000" iyy="0.02294" iyz="-0.00079" izz="0.03182"/>
    </inertial>
    <visual>
      <origin rpy="0 0 0" xyz="0 0 0"/>
      <geometry>
        <mesh filename="package://galbot_one_charlie_description/meshes/leg/leg_link3.obj"/>
      </geometry>
    </visual>
    <collision>
      <origin rpy="0 0 0" xyz="0 0 0"/>
      <geometry>
        <mesh filename="package://galbot_one_charlie_description/meshes/leg/leg_link3.stl"/>
      </geometry>
    </collision>
  </link>
  <joint name="leg_joint3" type="revolute">
    <origin rpy="-3.141592653589793 0 -3.141592653589793" xyz="0.39 0 0"/>
    <parent link="leg_link2"/>
    <child link="leg_link3"/>
    <axis xyz="0 0 1"/>
    <limit effort="252" lower="0" upper="2.35619449" velocity="1"/>
  </joint>
  <link name="leg_link4">
    <inertial>
      <origin rpy="0 0 0" xyz="0.00006 -0.00003 0.14494"/>
      <mass value="0.55"/>
      <inertia ixx="0.01267" ixy="0.00000" ixz="0.00001" iyy="0.01270" iyz="-0.00000" izz="0.00125"/>
    </inertial>
    <visual>
      <origin rpy="0 0 0" xyz="0 0 0"/>
      <geometry>
        <mesh filename="package://galbot_one_charlie_description/meshes/leg/leg_link4.obj"/>
      </geometry>
    </visual>
    <collision>
      <origin rpy="0 0 0" xyz="0 0 0"/>
      <geometry>
        <mesh filename="package://galbot_one_charlie_description/meshes/leg/leg_link4.stl"/>
      </geometry>
    </collision>
  </link>
  <joint name="leg_joint4" type="revolute">
    <origin rpy="1.5707963267948966 0 -3.141592653589793" xyz="0 0 0"/>
    <parent link="leg_link3"/>
    <child link="leg_link4"/>
    <axis xyz="0 0 1"/>
    <limit effort="90" lower="-1.570796327" upper="1.570796327" velocity="1"/>
  </joint>
  <link name="leg_end_effector_mount_link">
    <inertial>
      <origin rpy="0 0 0" xyz="0 0 0"/>
      <mass value="0"/>
      <inertia ixx="0" ixy="0" ixz="0" iyy="0" iyz="0" izz="0"/>
    </inertial>
  </link>
  <joint name="leg_end_effector_mount_joint" type="fixed">
    <origin rpy="0 0 0" xyz="0 0 0"/>
    <parent link="leg_link4"/>
    <child link="leg_end_effector_mount_link"/>
    <axis xyz="0 0 0"/>
  </joint>
  <joint name="torso_joint" type="fixed">
    <origin rpy="0 0 0" xyz="0 0 0"/>
    <parent link="leg_end_effector_mount_link"/>
    <child link="torso_base_link"/>
  </joint>
  <link name="torso_base_link">
    <inertial>
      <origin rpy="0 0 0" xyz="0.00004 0.00011 0.32719"/>
      <mass value="6.68"/>
      <inertia ixx="0.87119" ixy="0.00009" ixz="-0.00496" iyy="0.85457" iyz="0.00295" izz="0.06560"/>
    </inertial>
    <visual>
      <origin rpy="0 0 0" xyz="0 0 0"/>
      <geometry>
        <mesh filename="package://galbot_one_charlie_description/meshes/torso/torso_base_link.obj"/>
      </geometry>
    </visual>
    <collision>
      <origin rpy="0 0 0" xyz="0 0 0"/>
      <geometry>
        <mesh filename="package://galbot_one_charlie_description/meshes/torso/torso_base_link.stl"/>
      </geometry>
    </collision>
  </link>
  <!-- Head Mount -->
  <link name="torso_head_mount_link">
    <inertial>
      <origin rpy="0 0 0" xyz="0 0 0"/>
      <mass value="0"/>
      <inertia ixx="0" ixy="0" ixz="0" iyy="0" iyz="0" izz="0"/>
    </inertial>
  </link>
  <joint name="torso_head_mount_joint" type="fixed">
    <origin rpy="0 0 0" xyz="-0.0081669 5E-05 0.58394"/>
    <parent link="torso_base_link"/>
    <child link="torso_head_mount_link"/>
    <axis xyz="0 0 0"/>
  </joint>
  <!-- Right Arm Mount -->
  <link name="torso_right_arm_mount_link">
    <inertial>
      <origin rpy="0 0 0" xyz="0 0 0"/>
      <mass value="0"/>
      <inertia ixx="0" ixy="0" ixz="0" iyy="0" iyz="0" izz="0"/>
    </inertial>
  </link>
  <joint name="torso_right_arm_mount_joint" type="fixed">
    <origin rpy="-1.5707963267948966 0 3.141592653589793" xyz="0 -0.206 0.39599"/>
    <parent link="torso_base_link"/>
    <child link="torso_right_arm_mount_link"/>
    <axis xyz="0 0 0"/>
  </joint>
  <!-- Left Arm Mount -->
  <link name="torso_left_arm_mount_link">
    <inertial>
      <origin rpy="0 0 0" xyz="0 0 0"/>
      <mass value="0"/>
      <inertia ixx="0" ixy="0" ixz="0" iyy="0" iyz="0" izz="0"/>
    </inertial>
  </link>
  <joint name="torso_left_arm_mount_joint" type="fixed">
    <origin rpy="1.5707963267948966 0 3.141592653589793" xyz="0 0.206 0.39599"/>
    <parent link="torso_base_link"/>
    <child link="torso_left_arm_mount_link"/>
    <axis xyz="0 0 0"/>
  </joint>
  <!-- camera_front_right  -->
  <link name="torso_camera_front_right_sim_view_frame">
    <inertial>
      <origin rpy="0 0 0" xyz="0 0 0"/>
      <mass value="0"/>
      <inertia ixx="0" ixy="0" ixz="0" iyy="0" iyz="0" izz="0"/>
    </inertial>
  </link>
  <joint name="torso_camera_front_right_sim_view_joint" type="fixed">
    <!-- TODO@Herman-->
    <!-- Move x to avoid sim camera block-->
    <!-- <origin rpy="-0.010 0.363 -0.673" xyz="0.08 -0.075 0.21"/> -->
    <origin rpy="-0.010 0.363 -0.673" xyz="0.1 -0.075 0.21"/>
    <parent link="torso_base_link"/>
    <child link="torso_camera_front_right_sim_view_frame"/>
    <axis xyz="0 0 0"/>
  </joint>
  <!-- camera_front_left  -->
  <link name="torso_camera_front_left_sim_view_frame">
    <inertial>
      <origin rpy="0 0 0" xyz="0 0 0"/>
      <mass value="0"/>
      <inertia ixx="0" ixy="0" ixz="0" iyy="0" iyz="0" izz="0"/>
    </inertial>
  </link>
  <joint name="torso_camera_front_left_sim_view_joint" type="fixed">
    <!-- TODO@Herman-->
    <!-- Move x to avoid sim camera block-->
    <!-- <origin rpy="-0.001 0.328 0.705" xyz="0.08 0.075 0.21"/> -->
    <origin rpy="-0.001 0.328 0.705" xyz="0.1 0.075 0.21"/>
    <parent link="torso_base_link"/>
    <child link="torso_camera_front_left_sim_view_frame"/>
    <axis xyz="0 0 0"/>
  </joint>
  <!-- camera_back_left  -->
  <link name="torso_camera_back_left_sim_view_frame">
    <inertial>
      <origin rpy="0 0 0" xyz="0 0 0"/>
      <mass value="0"/>
      <inertia ixx="0" ixy="0" ixz="0" iyy="0" iyz="0" izz="0"/>
    </inertial>
  </link>
  <joint name="torso_camera_back_left_sim_view_joint" type="fixed">
    <!-- TODO@Herman-->
    <!-- Move x to avoid sim camera block-->
    <!-- <origin rpy="-0.003 0.330 2.459" xyz="-0.08 0.075 0.21"/> -->
    <origin rpy="-0.003 0.330 2.459" xyz="-0.1 0.075 0.21"/>
    <parent link="torso_base_link"/>
    <child link="torso_camera_back_left_sim_view_frame"/>
    <axis xyz="0 0 0"/>
  </joint>
  <!-- camera_back_right  -->
  <link name="torso_camera_back_right_sim_view_frame">
    <inertial>
      <origin rpy="0 0 0" xyz="0 0 0"/>
      <mass value="0"/>
      <inertia ixx="0" ixy="0" ixz="0" iyy="0" iyz="0" izz="0"/>
    </inertial>
  </link>
  <joint name="torso_camera_back_right_sim_view_joint" type="fixed">
    <!-- TODO@Herman-->
    <!-- Move x to avoid sim camera block-->
    <!-- <origin rpy="0.010 0.345 -2.436" xyz="-0.08 -0.075 0.21"/> -->
    <origin rpy="0.010 0.345 -2.436" xyz="-0.1 -0.075 0.21"/>
    <parent link="torso_base_link"/>
    <child link="torso_camera_back_right_sim_view_frame"/>
    <axis xyz="0 0 0"/>
  </joint>
  <joint name="head_joint" type="fixed">
    <origin rpy="0 0 0" xyz="0 0 0"/>
    <parent link="torso_head_mount_link"/>
    <child link="head_base_link"/>
  </joint>
  <link name="head_base_link">
    <inertial>
      <origin rpy="0 0 0" xyz="0 0 0"/>
      <mass value="0"/>
      <inertia ixx="0.018397" ixy="-6.5897E-07" ixz="0.00030036" iyy="0.013058" iyz="0.00016843" izz="0.0082332"/>
    </inertial>
  </link>
  <link name="head_link1">
    <inertial>
      <origin rpy="0 0 0" xyz="0.00000 0.00004 -0.04238"/>
      <mass value="0.41"/>
      <inertia ixx="0.00110" ixy="-0.00000" ixz="0.00000" iyy="0.00113" iyz="0.00008" izz="0.00014"/>
    </inertial>
  </link>
  <joint name="head_joint1" type="revolute">
    <origin rpy="0 0 0" xyz="0 0 0"/>
    <parent link="head_base_link"/>
    <child link="head_link1"/>
    <axis xyz="0 0 1"/>
    <limit effort="4" lower="-1.570796327" upper="1.570796327" velocity="1.5"/>
  </joint>
  <link name="head_link2">
    <inertial>
      <origin rpy="0 0 0" xyz="0.03200 -0.03753 0.00162"/>
      <mass value="0.75"/>
      <inertia ixx="0.00380" ixy="-0.00070" ixz="0.00000" iyy="0.00367" iyz="-0.00000" izz="0.00538"/>
    </inertial>
    <visual>
      <origin rpy="0 0 0" xyz="0 0 0"/>
      <geometry>
        <mesh filename="package://galbot_one_charlie_description/meshes/head/head_link2.obj"/>
      </geometry>
    </visual>
    <collision>
      <origin rpy="0 0 0" xyz="0 0 0"/>
      <geometry>
        <mesh filename="package://galbot_one_charlie_description/meshes/head/head_link2.stl"/>
      </geometry>
    </collision>
  </link>
  <joint name="head_joint2" type="revolute">
    <origin rpy="-1.5707963267948966 0 0" xyz="0 0 0"/>
    <parent link="head_link1"/>
    <child link="head_link2"/>
    <axis xyz="0 0 1"/>
    <limit effort="4" lower="-0.366519143" upper="0.366519143" velocity="1.5"/>
  </joint>
  <link name="head_end_effector_mount_link">
    <inertial>
      <origin rpy="0 0 0" xyz="0 0 0"/>
      <mass value="0"/>
      <inertia ixx="0" ixy="0" ixz="0" iyy="0" iyz="0" izz="0"/>
    </inertial>
  </link>
  <joint name="head_end_effector_mount_joint" type="fixed">
    <origin rpy="0 0 0" xyz="0 0 0"/>
    <parent link="head_link2"/>
    <child link="head_end_effector_mount_link"/>
    <axis xyz="0 0 0"/>
  </joint>
  <link name="head_camera_sim_view_frame">
    <inertial>
      <origin rpy="0 0 0" xyz="0 0 0"/>
      <mass value="0"/>
      <inertia ixx="0" ixy="0" ixz="0" iyy="0" iyz="0" izz="0"/>
    </inertial>
  </link>
  <joint name="head_camera_sim_view_joint" type="fixed">
    <!-- <origin rpy="1.5707963267948966 0 0.523598776" xyz="0.09321 -0.06166 0.033"/> -->
    <origin rpy=" -0.23746065  1.54782696  0.26041167" xyz="0.08722521107149132 -0.06810390910368269 0.022462515091698998"/>
    <parent link="head_end_effector_mount_link"/>
    <child link="head_camera_sim_view_frame"/>
    <axis xyz="0 0 0"/>
  </joint>
  <joint name="right_arm_joint" type="fixed">
    <origin rpy="0 0 0" xyz="0 0 0"/>
    <parent link="torso_right_arm_mount_link"/>
    <child link="right_arm_base_link"/>
  </joint>
  <link name="right_arm_base_link">
    <inertial>
      <origin rpy="0 0 0" xyz="0.00037 0.00006 -0.11407"/>
      <mass value="0.9"/>
      <inertia ixx="0.01248" ixy="0.00000" ixz="0.00003" iyy="0.01247" iyz="0.00003" izz="0.00056"/>
    </inertial>
  </link>
  <link name="right_arm_link1">
    <inertial>
      <origin rpy="0 0 0" xyz="0.00000 0.00650 -0.01459"/>
      <mass value="1.48"/>
      <inertia ixx="0.00378" ixy="0.00000" ixz="0.00000" iyy="0.00460" iyz="0.00008" izz="0.00217"/>
    </inertial>
    <visual>
      <origin rpy="0 0 0" xyz="0 0 0"/>
      <geometry>
        <mesh filename="package://galbot_one_charlie_description/meshes/arm/right_arm_link1.obj"/>
      </geometry>
    </visual>
    <collision>
      <origin rpy="0 0 0" xyz="0 0 0"/>
      <geometry>
        <mesh filename="package://galbot_one_charlie_description/meshes/arm/right_arm_link1.stl"/>
      </geometry>
    </collision>
  </link>
  <joint name="right_arm_joint1" type="revolute">
    <origin rpy="0 0 0" xyz="0 0 0"/>
    <parent link="right_arm_base_link"/>
    <child link="right_arm_link1"/>
    <axis xyz="0 0 1"/>
    <limit acceleration="2" effort="60" jerk="12" lower="-3.05" upper="3.05" velocity="1.5"/>
    <dynamics damping="0" friction="0"/>
  </joint>
  <link name="right_arm_link2">
    <inertial>
      <origin rpy="0 0 0" xyz="-0.00080 -0.09873 0.00815"/>
      <mass value="1.33"/>
      <inertia ixx="0.01827" ixy="0.00003" ixz="0.00001" iyy="0.00232" iyz="0.00080" izz="0.01769"/>
    </inertial>
    <visual>
      <origin rpy="0 0 0" xyz="0 0 0"/>
      <geometry>
        <mesh filename="package://galbot_one_charlie_description/meshes/arm/right_arm_link2.obj"/>
      </geometry>
    </visual>
    <collision>
      <origin rpy="0 0 0" xyz="0 0 0"/>
      <geometry>
        <mesh filename="package://galbot_one_charlie_description/meshes/arm/right_arm_link2.stl"/>
      </geometry>
    </collision>
  </link>
  <joint name="right_arm_joint2" type="revolute">
    <origin rpy="-1.5707963267948966 0 3.141592653589793" xyz="0 0 0"/>
    <parent link="right_arm_link1"/>
    <child link="right_arm_link2"/>
    <axis xyz="0 0 1"/>
    <limit acceleration="2" effort="60" jerk="12" lower="-1.5707963267948966" upper="1.7" velocity="1.5"/>
    <dynamics damping="0" friction="0"/>
  </joint>
  <link name="right_arm_link3">
    <inertial>
      <origin rpy="0 0 0" xyz="-0.00019 -0.00330 -0.04824"/>
      <mass value="1.25"/>
      <inertia ixx="0.00955" ixy="0.00000" ixz="0.00001" iyy="0.00983" iyz="0.00007" izz="0.00151"/>
    </inertial>
    <visual>
      <origin rpy="0 0 0" xyz="0 0 0"/>
      <geometry>
        <mesh filename="package://galbot_one_charlie_description/meshes/arm/right_arm_link3.obj"/>
      </geometry>
    </visual>
    <collision>
      <origin rpy="0 0 0" xyz="0 0 0"/>
      <geometry>
        <mesh filename="package://galbot_one_charlie_description/meshes/arm/right_arm_link3.stl"/>
      </geometry>
    </collision>
  </link>
  <joint name="right_arm_joint3" type="revolute">
    <origin rpy="1.5707963267948966 -1.5707963267948966 0" xyz="0 -0.35 0"/>
    <parent link="right_arm_link2"/>
    <child link="right_arm_link3"/>
    <axis xyz="0 0 1"/>
    <limit acceleration="2" effort="30" jerk="12" lower="-2.9" upper="2.9" velocity="1.5"/>
    <dynamics damping="0" friction="0"/>
  </joint>
  <link name="right_arm_link4">
    <inertial>
      <origin rpy="0 0 0" xyz="0.00000 -0.06457 0.00899"/>
      <mass value="0.8"/>
      <inertia ixx="0.00529" ixy="0.00000" ixz="0.00000" iyy="0.00120" iyz="0.00030" izz="0.00488"/>
    </inertial>
    <visual>
      <origin rpy="0 0 0" xyz="0 0 0"/>
      <geometry>
        <mesh filename="package://galbot_one_charlie_description/meshes/arm/right_arm_link4.obj"/>
      </geometry>
    </visual>
    <collision>
      <origin rpy="0 0 0" xyz="0 0 0"/>
      <geometry>
        <mesh filename="package://galbot_one_charlie_description/meshes/arm/right_arm_link4.stl"/>
      </geometry>
    </collision>
  </link>
  <joint name="right_arm_joint4" type="revolute">
    <origin rpy="-1.5707963267948966 0 3.141592653589793" xyz="0 0 0"/>
    <parent link="right_arm_link3"/>
    <child link="right_arm_link4"/>
    <axis xyz="0 0 1"/>
    <limit acceleration="2" effort="30" jerk="12" lower="-2.1" upper="2.1" velocity="1.5"/>
    <dynamics damping="0" friction="0"/>
  </joint>
  <link name="right_arm_link5">
    <inertial>
      <origin rpy="0 0 0" xyz="0.00201 -0.00042 -0.14589"/>
      <mass value="1.22"/>
      <inertia ixx="0.03428" ixy="0.00001" ixz="0.00032" iyy="0.03366" iyz="0.00005" izz="0.00222"/>
    </inertial>
    <visual>
      <origin rpy="0 0 0" xyz="0 0 0"/>
      <geometry>
        <mesh filename="package://galbot_one_charlie_description/meshes/arm/right_arm_link5.obj"/>
      </geometry>
    </visual>
    <collision>
      <origin rpy="0 0 0" xyz="0 0 0"/>
      <geometry>
        <mesh filename="package://galbot_one_charlie_description/meshes/arm/right_arm_link5.stl"/>
      </geometry>
    </collision>
  </link>
  <joint name="right_arm_joint5" type="revolute">
    <origin rpy="1.5707963267948966 0 0" xyz="0 -0.36 0"/>
    <parent link="right_arm_link4"/>
    <child link="right_arm_link5"/>
    <axis xyz="0 0 1"/>
    <limit acceleration="2" effort="10" jerk="12" lower="-2.9" upper="2.9" velocity="1.5"/>
    <dynamics damping="0" friction="0"/>
  </joint>
  <link name="right_arm_link6">
    <inertial>
      <origin rpy="0 0 0" xyz="0.00000 0.01031 0.00000"/>
      <mass value="0.43"/>
      <inertia ixx="0.00051" ixy="0.00000" ixz="0.00000" iyy="0.00070" iyz="0.00000" izz="0.00091"/>
    </inertial>
    <visual>
      <origin rpy="0 0 0" xyz="0 0 0"/>
      <geometry>
        <mesh filename="package://galbot_one_charlie_description/meshes/arm/right_arm_link6.obj"/>
      </geometry>
    </visual>
    <collision>
      <origin rpy="0 0 0" xyz="0 0 0"/>
      <geometry>
        <mesh filename="package://galbot_one_charlie_description/meshes/arm/right_arm_link6.stl"/>
      </geometry>
    </collision>
  </link>
  <joint name="right_arm_joint6" type="revolute">
    <origin rpy="-1.5707963267948966 1.5707963267948966 3.141592653589793" xyz="0 0 0"/>
    <parent link="right_arm_link5"/>
    <child link="right_arm_link6"/>
    <axis xyz="0 0 1"/>
    <limit acceleration="2" effort="10" jerk="12" lower="-0.785398163" upper="0.785398163" velocity="1.5"/>
    <dynamics damping="0" friction="0"/>
  </joint>
  <link name="right_arm_link7">
    <inertial>
      <origin rpy="0 0 0" xyz="-0.03291 0.00799 -0.00131"/>
      <mass value="0.6"/>
      <inertia ixx="0.00124" ixy="0.00030" ixz="0.00013" iyy="0.00198" iyz="0.00007" izz="0.00164"/>
    </inertial>
    <visual>
      <origin rpy="0 0 0" xyz="0 0 0"/>
      <geometry>
        <mesh filename="package://galbot_one_charlie_description/meshes/arm/right_arm_link7.obj"/>
      </geometry>
    </visual>
    <collision>
      <origin rpy="0 0 0" xyz="0 0 0"/>
      <geometry>
        <mesh filename="package://galbot_one_charlie_description/meshes/arm/right_arm_link7.stl"/>
      </geometry>
    </collision>
  </link>
  <joint name="right_arm_joint7" type="revolute">
    <origin rpy="-1.5707963267948966 0 0" xyz="0 0 0"/>
    <parent link="right_arm_link6"/>
    <child link="right_arm_link7"/>
    <axis xyz="0 0 1"/>
    <limit acceleration="2" effort="10" jerk="12" lower="-1.4" upper="1.4" velocity="1.5"/>
    <dynamics damping="0" friction="0"/>
  </joint>
  <link name="right_arm_end_effector_mount_link">
    <inertial>
      <origin rpy="0 0 0" xyz="0 0 0"/>
      <mass value="0"/>
      <inertia ixx="0" ixy="0" ixz="0" iyy="0" iyz="0" izz="0"/>
    </inertial>
  </link>
  <joint name="right_arm_end_effector_mount_joint" type="fixed">
    <origin rpy="1.5707963267948966 0 3.141592653589793" xyz="-0.083 0 0"/>
    <parent link="right_arm_link7"/>
    <child link="right_arm_end_effector_mount_link"/>
    <axis xyz="0 0 0"/>
  </joint>
  <link name="right_arm_camera_sim_view_frame">
    <inertial>
      <origin rpy="0 0 0" xyz="0 0 0"/>
      <mass value="0"/>
      <inertia ixx="0" ixy="0" ixz="0" iyy="0" iyz="0" izz="0"/>
    </inertial>
  </link>
  <joint name="right_arm_camera_sim_view_joint" type="fixed">
    <origin rpy="0 -0.261799388 0 " xyz="-0.02255 0.035 0.05178"/>
    <parent link="right_arm_end_effector_mount_link"/>
    <child link="right_arm_camera_sim_view_frame"/>
    <axis xyz="0 0 0"/>
  </joint>
  <link name="right_arm_force_sensor_sim_view_frame">
    <inertial>
      <origin rpy="0 0 0" xyz="0 0 0"/>
      <mass value="0"/>
      <inertia ixx="0" ixy="0" ixz="0" iyy="0" iyz="0" izz="0"/>
    </inertial>
  </link>
  <joint name="right_arm_force_sensor_sim_view_joint" type="fixed">
    <origin rpy="0 1.5707963267948966 0" xyz="-0.013 0 0"/>
    <parent link="right_arm_end_effector_mount_link"/>
    <child link="right_arm_force_sensor_sim_view_frame"/>
    <axis xyz="0 0 0"/>
  </joint>
  <joint name="right_suction_cup_joint" type="fixed">
    <origin rpy="-1.5707963267948966 3.141592653589793 0" xyz="0 0 0"/>
    <parent link="right_arm_end_effector_mount_link"/>
    <child link="right_suction_cup_base_link"/>
  </joint>
  <link name="right_suction_cup_base_link">
    <inertial>
      <origin rpy="0 0 0" xyz="-4.0035E-05 -0.00015919 0.065665"/>
      <mass value="0.36941"/>
      <inertia ixx="0.00014564" ixy="3.5459E-07" ixz="-1.2386E-07" iyy="0.00016918" iyz="-4.0084E-07" izz="0.000219"/>
    </inertial>
    <visual>
      <origin rpy="0 0 0" xyz="0 0 0"/>
      <geometry>
        <mesh filename="package://galbot_one_charlie_description/meshes/suction_cup/suction_cup_base_link.obj"/>
      </geometry>
    </visual>
    <collision>
      <origin rpy="0 0 0" xyz="0 0 0"/>
      <geometry>
        <mesh filename="package://galbot_one_charlie_description/meshes/suction_cup/suction_cup_base_link.stl"/>
      </geometry>
    </collision>
  </link>
  <link name="right_suction_cup_link1">
    <inertial>
      <origin rpy="0 0 0" xyz="0.037966 -3.0191E-05 -4.2414E-08"/>
      <mass value="0.063856"/>
      <inertia ixx="7.1717E-06" ixy="1.7711E-08" ixz="-3.6994E-11" iyy="8.0256E-06" iyz="4.7383E-09" izz="7.78E-06"/>
    </inertial>
    <visual>
      <origin rpy="0 0 0" xyz="0 0 0"/>
      <geometry>
        <mesh filename="package://galbot_one_charlie_description/meshes/suction_cup/suction_cup_link1.obj"/>
      </geometry>
    </visual>
    <collision>
      <origin rpy="0 0 0" xyz="0 0 0"/>
      <geometry>
        <mesh filename="package://galbot_one_charlie_description/meshes/suction_cup/suction_cup_link1.stl"/>
      </geometry>
    </collision>
  </link>
  <joint name="right_suction_cup_joint1" type="revolute">
    <origin rpy="0 0 -1.5707963267948966" xyz="-0.1428 0 0"/>
    <parent link="right_suction_cup_base_link"/>
    <child link="right_suction_cup_link1"/>
    <axis xyz="0 0 1"/>
    <limit effort="1" lower="0" upper="1.570796327" velocity="1.570796327"/>
  </joint>
  <link name="right_suction_cup_tcp_link"/>
  <joint name="right_suction_cup_tcp_joint" type="fixed">
    <origin rpy="1.5707963267948966 0 -1.5707963267948966" xyz="0 -0.079807 0"/>
    <parent link="right_suction_cup_link1"/>
    <child link="right_suction_cup_tcp_link"/>
    <axis xyz="0 0 0"/>
  </joint>
  <joint name="left_arm_joint" type="fixed">
    <origin rpy="0 0 0" xyz="0 0 0"/>
    <parent link="torso_left_arm_mount_link"/>
    <child link="left_arm_base_link"/>
  </joint>
  <link name="left_arm_base_link">
    <inertial>
      <origin rpy="0 0 0" xyz="-0.00037 -0.00006 -0.11407"/>
      <mass value="0.9"/>
      <inertia ixx="0.01248" ixy="0.00000" ixz="0.00003" iyy="0.01247" iyz="0.00003" izz="0.00056"/>
    </inertial>
  </link>
  <link name="left_arm_link1">
    <inertial>
      <origin rpy="0 0 0" xyz="0.00000 0.00650 -0.01459"/>
      <mass value="1.48"/>
      <inertia ixx="0.00378" ixy="0.00000" ixz="0.00000" iyy="0.00460" iyz="0.00020" izz="0.00217"/>
    </inertial>
    <visual>
      <origin rpy="0 0 0" xyz="0 0 0"/>
      <geometry>
        <mesh filename="package://galbot_one_charlie_description/meshes/arm/left_arm_link1.obj"/>
      </geometry>
    </visual>
    <collision>
      <origin rpy="0 0 0" xyz="0 0 0"/>
      <geometry>
        <mesh filename="package://galbot_one_charlie_description/meshes/arm/left_arm_link1.stl"/>
      </geometry>
    </collision>
  </link>
  <joint name="left_arm_joint1" type="revolute">
    <origin rpy="0 0 0" xyz="0 0 0"/>
    <parent link="left_arm_base_link"/>
    <child link="left_arm_link1"/>
    <axis xyz="0 0 1"/>
    <limit acceleration="2" effort="60" jerk="12" lower="-3.05" upper="3.05" velocity="1.5"/>
    <dynamics damping="0" friction="0"/>
  </joint>
  <link name="left_arm_link2">
    <inertial>
      <origin rpy="0 0 0" xyz="-0.00080 0.09873 0.00815"/>
      <mass value="1.33"/>
      <inertia ixx="0.01827" ixy="0.00003" ixz="0.00003" iyy="0.00232" iyz="0.00134" izz="0.01769"/>
    </inertial>
    <visual>
      <origin rpy="0 0 0" xyz="0 0 0"/>
      <geometry>
        <mesh filename="package://galbot_one_charlie_description/meshes/arm/left_arm_link2.obj"/>
      </geometry>
    </visual>
    <collision>
      <origin rpy="0 0 0" xyz="0 0 0"/>
      <geometry>
        <mesh filename="package://galbot_one_charlie_description/meshes/arm/left_arm_link2.stl"/>
      </geometry>
    </collision>
  </link>
  <joint name="left_arm_joint2" type="revolute">
    <origin rpy="1.5707963267948966 0 3.141592653589793" xyz="0 0 0"/>
    <parent link="left_arm_link1"/>
    <child link="left_arm_link2"/>
    <axis xyz="0 0 1"/>
    <limit acceleration="2" effort="60" jerk="12" lower="-1.95" upper="1.570796327" velocity="1.5"/>
    <dynamics damping="0" friction="0"/>
  </joint>
  <link name="left_arm_link3">
    <inertial>
      <origin rpy="0 0 0" xyz="0.00019 0.00330 -0.04824"/>
      <mass value="1.25"/>
      <inertia ixx="0.00955" ixy="0.00000" ixz="0.00001" iyy="0.00983" iyz="0.00007" izz="0.00151"/>
    </inertial>
    <visual>
      <origin rpy="0 0 0" xyz="0 0 0"/>
      <geometry>
        <mesh filename="package://galbot_one_charlie_description/meshes/arm/left_arm_link3.obj"/>
      </geometry>
    </visual>
    <collision>
      <origin rpy="0 0 0" xyz="0 0 0"/>
      <geometry>
        <mesh filename="package://galbot_one_charlie_description/meshes/arm/left_arm_link3.stl"/>
      </geometry>
    </collision>
  </link>
  <joint name="left_arm_joint3" type="revolute">
    <origin rpy="-1.5707963267948966 -1.5707963267948966 0" xyz="0 0.35 0"/>
    <parent link="left_arm_link2"/>
    <child link="left_arm_link3"/>
    <axis xyz="0 0 1"/>
    <limit acceleration="2" effort="30" jerk="12" lower="-2.9" upper="2.9" velocity="1.5"/>
    <dynamics damping="0" friction="0"/>
  </joint>
  <link name="left_arm_link4">
    <inertial>
      <origin rpy="0 0 0" xyz="0.00000 0.06457 0.00899"/>
      <mass value="0.8"/>
      <inertia ixx="0.00529" ixy="0.00000" ixz="0.00000" iyy="0.00120" iyz="0.00030" izz="0.00488"/>
    </inertial>
    <visual>
      <origin rpy="0 0 0" xyz="0 0 0"/>
      <geometry>
        <mesh filename="package://galbot_one_charlie_description/meshes/arm/left_arm_link4.obj"/>
      </geometry>
    </visual>
    <collision>
      <origin rpy="0 0 0" xyz="0 0 0"/>
      <geometry>
        <mesh filename="package://galbot_one_charlie_description/meshes/arm/left_arm_link4.stl"/>
      </geometry>
    </collision>
  </link>
  <joint name="left_arm_joint4" type="revolute">
    <origin rpy="1.5707963267948966 0 -3.141592653589793" xyz="0 0 0"/>
    <parent link="left_arm_link3"/>
    <child link="left_arm_link4"/>
    <axis xyz="0 0 1"/>
    <limit acceleration="2" effort="30" jerk="12" lower="-2.1" upper="2.1" velocity="1.5"/>
    <dynamics damping="0" friction="0"/>
  </joint>
  <link name="left_arm_link5">
    <inertial>
      <origin rpy="0 0 0" xyz="-0.00201 0.00042 -0.14589"/>
      <mass value="1.22"/>
      <inertia ixx="0.03428" ixy="0.00001" ixz="0.00039" iyy="0.03366" iyz="0.00010" izz="0.00222"/>
    </inertial>
    <visual>
      <origin rpy="0 0 0" xyz="0 0 0"/>
      <geometry>
        <mesh filename="package://galbot_one_charlie_description/meshes/arm/left_arm_link5.obj"/>
      </geometry>
    </visual>
    <collision>
      <origin rpy="0 0 0" xyz="0 0 0"/>
      <geometry>
        <mesh filename="package://galbot_one_charlie_description/meshes/arm/left_arm_link5.stl"/>
      </geometry>
    </collision>
  </link>
  <joint name="left_arm_joint5" type="revolute">
    <origin rpy="-1.5707963267948966 3.141592653589793 0" xyz="0 0.36 0"/>
    <parent link="left_arm_link4"/>
    <child link="left_arm_link5"/>
    <axis xyz="0 0 1"/>
    <limit acceleration="2" effort="10" jerk="12" lower="-2.9" upper="2.9" velocity="1.5"/>
    <dynamics damping="0" friction="0"/>
  </joint>
  <link name="left_arm_link6">
    <inertial>
      <origin rpy="0 0 0" xyz="0.00000 -0.01031 0.00000"/>
      <mass value="0.43"/>
      <inertia ixx="0.00051" ixy="0.00000" ixz="0.00000" iyy="0.00070" iyz="0.00000" izz="0.00091"/>
    </inertial>
    <visual>
      <origin rpy="0 0 0" xyz="0 0 0"/>
      <geometry>
        <mesh filename="package://galbot_one_charlie_description/meshes/arm/left_arm_link6.obj"/>
      </geometry>
    </visual>
    <collision>
      <origin rpy="0 0 0" xyz="0 0 0"/>
      <geometry>
        <mesh filename="package://galbot_one_charlie_description/meshes/arm/left_arm_link6.stl"/>
      </geometry>
    </collision>
  </link>
  <joint name="left_arm_joint6" type="revolute">
    <origin rpy="1.5707963267948966 1.5707963267948966 0" xyz="0 0 0"/>
    <parent link="left_arm_link5"/>
    <child link="left_arm_link6"/>
    <axis xyz="0 0 1"/>
    <limit acceleration="2" effort="10" jerk="12" lower="-0.785398163" upper="0.785398163" velocity="1.5"/>
    <dynamics damping="0" friction="0"/>
  </joint>
  <link name="left_arm_link7">
    <inertial>
      <origin rpy="0 0 0" xyz="-0.03291 0.00799 -0.00131"/>
      <mass value="0.6"/>
      <inertia ixx="0.00124" ixy="0.00000" ixz="0.00012" iyy="0.00197" iyz="0.00004" izz="0.00165"/>
    </inertial>
    <visual>
      <origin rpy="0 0 0" xyz="0 0 0"/>
      <geometry>
        <mesh filename="package://galbot_one_charlie_description/meshes/arm/left_arm_link7.obj"/>
      </geometry>
    </visual>
    <collision>
      <origin rpy="0 0 0" xyz="0 0 0"/>
      <geometry>
        <mesh filename="package://galbot_one_charlie_description/meshes/arm/left_arm_link7.stl"/>
      </geometry>
    </collision>
  </link>
  <joint name="left_arm_joint7" type="revolute">
    <origin rpy="1.5707963267948966 0 0" xyz="0 0 0"/>
    <parent link="left_arm_link6"/>
    <child link="left_arm_link7"/>
    <axis xyz="0 0 1"/>
    <limit acceleration="2" effort="10" jerk="12" lower="-1.4" upper="1.4" velocity="1.5"/>
    <dynamics damping="0" friction="0"/>
  </joint>
  <link name="left_arm_end_effector_mount_link">
    <inertial>
      <origin rpy="0 0 0" xyz="0 0 0"/>
      <mass value="0"/>
      <inertia ixx="0" ixy="0" ixz="0" iyy="0" iyz="0" izz="0"/>
    </inertial>
  </link>
  <joint name="left_arm_end_effector_mount_joint" type="fixed">
    <origin rpy="-1.5707963267948966 0 3.141592653589793" xyz="-0.083 0 0"/>
    <parent link="left_arm_link7"/>
    <child link="left_arm_end_effector_mount_link"/>
    <axis xyz="0 0 0"/>
  </joint>
  <link name="left_arm_camera_sim_view_frame">
    <inertial>
      <origin rpy="0 0 0" xyz="0 0 0"/>
      <mass value="0"/>
      <inertia ixx="0" ixy="0" ixz="0" iyy="0" iyz="0" izz="0"/>
    </inertial>
  </link>
  <joint name="left_arm_camera_sim_view_joint" type="fixed">
    <origin rpy="0 -0.261799388 0 " xyz="-0.02255 -0.035 0.05178"/>
    <parent link="left_arm_end_effector_mount_link"/>
    <child link="left_arm_camera_sim_view_frame"/>
    <axis xyz="0 0 0"/>
  </joint>
  <link name="left_arm_force_sensor_sim_view_frame">
    <inertial>
      <origin rpy="0 0 0" xyz="0 0 0"/>
      <mass value="0"/>
      <inertia ixx="0" ixy="0" ixz="0" iyy="0" iyz="0" izz="0"/>
    </inertial>
  </link>
  <joint name="left_arm_force_sensor_sim_view_joint" type="fixed">
    <origin rpy="0 -1.5707963267948966 3.141592653589793" xyz="-0.013 0 0"/>
    <parent link="left_arm_end_effector_mount_link"/>
    <child link="left_arm_force_sensor_sim_view_frame"/>
    <axis xyz="0 0 0"/>
  </joint>
  <joint name="left_gripper_joint" type="fixed">
    <origin rpy="1.5707963267948966 3.141592653589793 0" xyz="0 0 0"/>
    <parent link="left_arm_end_effector_mount_link"/>
    <child link="left_gripper_base_link"/>
  </joint>
  <link name="left_gripper_base_link">
    <inertial>
      <origin rpy="0 0 0" xyz="0.0875969515032359 -0.000593766922509439 -0.000273353044587243"/>
      <mass value="0.229646651659589"/>
      <inertia ixx="8.60029243295527E-05" ixy="2.00063024143341E-06" ixz="2.85398505671959E-06" iyy="7.73254340691918E-05" iyz="-1.0856442426917E-07" izz="9.78281466602487E-05"/>
    </inertial>
    <visual>
      <origin rpy="0 0 0" xyz="0 0 0"/>
      <geometry>
        <mesh filename="package://galbot_one_charlie_description/meshes/gripper/gripper_hitbot_base_link.obj"/>
      </geometry>
    </visual>
    <collision>
      <origin rpy="0 0 0" xyz="0 0 0"/>
      <geometry>
        <mesh filename="package://galbot_one_charlie_description/meshes/gripper/gripper_hitbot_base_link.stl"/>
      </geometry>
    </collision>
  </link>
  <link name="left_gripper_left_link">
    <inertial>
      <origin rpy="0 0 0" xyz="-0.0231481638496937 -4.90112376816481E-07 -0.000267991935875532"/>
      <mass value="0.00675449578859124"/>
      <inertia ixx="3.19945619554153E-07" ixy="-7.76829664652689E-12" ixz="-3.91342467850705E-07" iyy="1.5976052028241E-06" iyz="2.16781299849398E-11" izz="1.50158040800935E-06"/>
    </inertial>
    <visual>
      <origin rpy="0 0 0" xyz="0 0 0"/>
      <geometry>
        <mesh filename="package://galbot_one_charlie_description/meshes/gripper/gripper_hitbot_finger_link.obj"/>
      </geometry>
    </visual>
    <collision>
      <origin rpy="0 0 0" xyz="0 0 0"/>
      <geometry>
        <mesh filename="package://galbot_one_charlie_description/meshes/gripper/gripper_hitbot_finger_link.stl"/>
      </geometry>
    </collision>
  </link>
  <joint name="left_gripper_left_joint" type="prismatic">
    <origin rpy="3.141592653589793 0 3.141592653589793" xyz="-0.23074 0 0"/>
    <parent link="left_gripper_base_link"/>
    <child link="left_gripper_left_link"/>
    <axis xyz="0 0 1"/>
    <limit effort="2" lower="0" upper="0.045" velocity="0.045"/>
  </joint>
  <link name="left_gripper_right_link">
    <inertial>
      <origin rpy="0 0 0" xyz="-0.0231481638496943 -4.90112376734401E-07 -0.000267991935824489"/>
      <mass value="0.00675449578859123"/>
      <inertia ixx="3.19945619552427E-07" ixy="-7.76829655500751E-12" ixz="-3.91342467848098E-07" iyy="1.5976052028241E-06" iyz="2.16781300075729E-11" izz="1.50158040801108E-06"/>
    </inertial>
    <visual>
      <origin rpy="0 0 0" xyz="0 0 0"/>
      <geometry>
        <mesh filename="package://galbot_one_charlie_description/meshes/gripper/gripper_hitbot_finger_link.obj"/>
      </geometry>
    </visual>
    <collision>
      <origin rpy="0 0 0" xyz="0 0 0"/>
      <geometry>
        <mesh filename="package://galbot_one_charlie_description/meshes/gripper/gripper_hitbot_finger_link.stl"/>
      </geometry>
    </collision>
  </link>
  <joint name="left_gripper_right_joint" type="prismatic">
    <origin rpy="0 0 3.141592653589793" xyz="-0.23074 0 0"/>
    <parent link="left_gripper_base_link"/>
    <child link="left_gripper_right_link"/>
    <axis xyz="0 0 1"/>
    <limit effort="2" lower="0" upper="0.045" velocity="0.045"/>
    <!-- mimic not supported in isaac sim 2023.1.0-hotfix  -->
    <!-- <mimic joint="${name}_left_joint" multiplier="-1" offset="0" /> -->
  </joint>
  <!-- Tool Center Point -->
  <link name="left_gripper_tcp_link"/>
  <joint name="left_gripper_tcp_joint" type="fixed">
    <origin rpy="1.5707963267948966 3.141592653589793 0" xyz="-0.23074 0 0"/>
    <parent link="left_gripper_base_link"/>
    <child link="left_gripper_tcp_link"/>
    <axis xyz="0 0 0"/>
  </joint>
  <link name="world"/>
  <joint name="world_joint" type="fixed">
    <parent link="world"/>
    <child link="base_link"/>
    <origin rpy="0.0 0.0 0.0" xyz="0.0 0.0 0.0"/>
  </joint>
</robot>
